package thaumcraft.common.lib.world;

@Deprecated(forRemoval = true)
public class WorldGenMound /*extends WorldGenerator*/ {
//   protected static Block[] GetValidSpawnBlocks() {
//      return new Block[]{Blocks.stone, Blocks.GRASS.defaultBlockState(), Blocks.DIRT.defaultBlockState()};
//   }
//
//   public static boolean LocationIsValidSpawn(Level world, int i, int j, int k) {
//      int distanceToAir = 0;
//
//      for(Block checkID = world.getBlock(i, j, k); checkID != Blocks.AIR.defaultBlockState(); checkID = world.getBlock(i, j + distanceToAir, k)) {
//         ++distanceToAir;
//      }
//
//       if (distanceToAir <= 2) {
//           j += distanceToAir - 1;
//           Block blockID = world.getBlock(i, j, k);
//           Block blockIDAbove = world.getBlock(i, j + 1, k);
//           Block blockIDBelow = world.getBlock(i, j - 1, k);
//
//           for (Block x : GetValidSpawnBlocks()) {
//               if (blockIDAbove != Blocks.AIR.defaultBlockState()) {
//                   return false;
//               }
//
//               if (blockID == x) {
//                   return true;
//               }
//
//               if ((blockID == Blocks.snow_layer || blockID == Blocks.tallgrass) && blockIDBelow == x) {
//                   return true;
//               }
//           }
//
//       }
//       return false;
//   }
//
//   public boolean generate(Level world, Random rand, int i, int j, int k) {
//      return generateStatic(world, rand, i, j, k);
//   }
//   public static boolean generateStatic(Level world, Random rand, int i, int j, int k) {
//      if (LocationIsValidSpawn(world, i + 9, j + 9, k + 9)
//              && LocationIsValidSpawn(world, i, j + 9, k)
//              && LocationIsValidSpawn(world, i + 18, j + 9, k)
//              && LocationIsValidSpawn(world, i + 18, j + 9, k + 18)
//              && LocationIsValidSpawn(world, i, j + 9, k + 18))
//      {
//         world.setBlock(i, j + 8, k + 4, Blocks.DIRT.defaultBlockState());
//         world.setBlock(i, j + 8, k + 5, Blocks.DIRT.defaultBlockState());
//         world.setBlock(i, j + 8, k + 6, Blocks.DIRT.defaultBlockState());
//         world.setBlock(i, j + 8, k + 7, Blocks.DIRT.defaultBlockState());
//         world.setBlock(i, j + 8, k + 8, Blocks.COBBLESTONE.defaultBlockState());
//         world.setBlock(i, j + 8, k + 9, Blocks.COBBLESTONE.defaultBlockState());
//         world.setBlock(i, j + 8, k + 10, Blocks.COBBLESTONE.defaultBlockState());
//         world.setBlock(i, j + 8, k + 11, Blocks.DIRT.defaultBlockState());
//         world.setBlock(i, j + 8, k + 12, Blocks.DIRT.defaultBlockState());
//         world.setBlock(i, j + 8, k + 13, Blocks.DIRT.defaultBlockState());
//         world.setBlock(i, j + 8, k + 14, Blocks.DIRT.defaultBlockState());
//         world.setBlock(i, j + 9, k + 4, Blocks.GRASS.defaultBlockState());
//         world.setBlock(i, j + 9, k + 5, Blocks.GRASS.defaultBlockState());
//         world.setBlock(i, j + 9, k + 6, Blocks.GRASS.defaultBlockState());
//         world.setBlock(i, j + 9, k + 7, Blocks.GRASS.defaultBlockState());
//         world.setBlock(i, j + 9, k + 8, Blocks.STONE_STAIRS.defaultBlockState());
//         world.setBlock(i, j + 9, k + 9, Blocks.AIR.defaultBlockState());
//         world.setBlock(i, j + 9, k + 10, Blocks.STONE_STAIRS.defaultBlockState());
//         world.setBlock(i, j + 9, k + 11, Blocks.GRASS.defaultBlockState());
//         world.setBlock(i, j + 9, k + 12, Blocks.GRASS.defaultBlockState());
//         world.setBlock(i, j + 9, k + 13, Blocks.GRASS.defaultBlockState());
//         world.setBlock(i, j + 9, k + 14, Blocks.GRASS.defaultBlockState());
//         world.setBlock(i, j + 10, k + 8, Blocks.AIR.defaultBlockState());
//         world.setBlock(i, j + 10, k + 9, Blocks.AIR.defaultBlockState());
//         world.setBlock(i, j + 10, k + 10, Blocks.AIR.defaultBlockState());
//         world.setBlock(i + 1, j + 8, k + 3, Blocks.DIRT.defaultBlockState());
//         world.setBlock(i + 1, j + 8, k + 4, Blocks.DIRT.defaultBlockState());
//         world.setBlock(i + 1, j + 8, k + 5, Blocks.DIRT.defaultBlockState());
//         world.setBlock(i + 1, j + 8, k + 6, Blocks.DIRT.defaultBlockState());
//         world.setBlock(i + 1, j + 8, k + 7, Blocks.DIRT.defaultBlockState());
//         world.setBlock(i + 1, j + 8, k + 8, Blocks.COBBLESTONE.defaultBlockState());
//         world.setBlock(i + 1, j + 8, k + 9, Blocks.COBBLESTONE.defaultBlockState());
//         world.setBlock(i + 1, j + 8, k + 10, Blocks.COBBLESTONE.defaultBlockState());
//         world.setBlock(i + 1, j + 8, k + 11, Blocks.DIRT.defaultBlockState());
//         world.setBlock(i + 1, j + 8, k + 12, Blocks.DIRT.defaultBlockState());
//         world.setBlock(i + 1, j + 8, k + 13, Blocks.DIRT.defaultBlockState());
//         world.setBlock(i + 1, j + 8, k + 14, Blocks.DIRT.defaultBlockState());
//         world.setBlock(i + 1, j + 8, k + 15, Blocks.DIRT.defaultBlockState());
//         world.setBlock(i + 1, j + 9, k + 3, Blocks.GRASS.defaultBlockState());
//         world.setBlock(i + 1, j + 9, k + 4, Blocks.DIRT.defaultBlockState());
//         world.setBlock(i + 1, j + 9, k + 5, Blocks.DIRT.defaultBlockState());
//         world.setBlock(i + 1, j + 9, k + 6, Blocks.DIRT.defaultBlockState());
//         world.setBlock(i + 1, j + 9, k + 7, Blocks.DIRT.defaultBlockState());
//         world.setBlock(i + 1, j + 9, k + 8, Blocks.COBBLESTONE.defaultBlockState());
//         world.setBlock(i + 1, j + 9, k + 9, Blocks.AIR.defaultBlockState());
//         world.setBlock(i + 1, j + 9, k + 10, Blocks.COBBLESTONE.defaultBlockState());
//         world.setBlock(i + 1, j + 9, k + 11, Blocks.DIRT.defaultBlockState());
//         world.setBlock(i + 1, j + 9, k + 12, Blocks.DIRT.defaultBlockState());
//         world.setBlock(i + 1, j + 9, k + 13, Blocks.DIRT.defaultBlockState());
//         world.setBlock(i + 1, j + 9, k + 14, Blocks.DIRT.defaultBlockState());
//         world.setBlock(i + 1, j + 9, k + 15, Blocks.GRASS.defaultBlockState());
//         world.setBlock(i + 1, j + 10, k + 4, Blocks.GRASS.defaultBlockState());
//         world.setBlock(i + 1, j + 10, k + 5, Blocks.GRASS.defaultBlockState());
//         world.setBlock(i + 1, j + 10, k + 6, Blocks.DIRT.defaultBlockState());
//         world.setBlock(i + 1, j + 10, k + 7, Blocks.DIRT.defaultBlockState());
//         world.setBlock(i + 1, j + 10, k + 8, Blocks.STONE_STAIRS.defaultBlockState());
//         world.setBlock(i + 1, j + 10, k + 9, Blocks.AIR.defaultBlockState());
//         world.setBlock(i + 1, j + 10, k + 10, Blocks.STONE_STAIRS.defaultBlockState());
//         world.setBlock(i + 1, j + 10, k + 11, Blocks.GRASS.defaultBlockState());
//         world.setBlock(i + 1, j + 10, k + 12, Blocks.GRASS.defaultBlockState());
//         world.setBlock(i + 1, j + 10, k + 13, Blocks.GRASS.defaultBlockState());
//         world.setBlock(i + 1, j + 10, k + 14, Blocks.GRASS.defaultBlockState());
//         world.setBlock(i + 1, j + 11, k + 6, Blocks.GRASS.defaultBlockState());
//         world.setBlock(i + 1, j + 11, k + 7, Blocks.GRASS.defaultBlockState());
//         world.setBlock(i + 1, j + 11, k + 8, Blocks.AIR.defaultBlockState());
//         world.setBlock(i + 1, j + 11, k + 9, Blocks.AIR.defaultBlockState());
//         world.setBlock(i + 1, j + 11, k + 10, Blocks.AIR.defaultBlockState());
//         world.setBlock(i + 2, j + 8, k + 2, Blocks.DIRT.defaultBlockState());
//         world.setBlock(i + 2, j + 8, k + 3, Blocks.DIRT.defaultBlockState());
//         world.setBlock(i + 2, j + 8, k + 4, Blocks.DIRT.defaultBlockState());
//         world.setBlock(i + 2, j + 8, k + 5, Blocks.DIRT.defaultBlockState());
//         world.setBlock(i + 2, j + 8, k + 6, Blocks.DIRT.defaultBlockState());
//         world.setBlock(i + 2, j + 8, k + 7, Blocks.COBBLESTONE.defaultBlockState());
//         world.setBlock(i + 2, j + 8, k + 8, Blocks.COBBLESTONE.defaultBlockState());
//         world.setBlock(i + 2, j + 8, k + 9, Blocks.MOSSY_COBBLESTONE.defaultBlockState());
//         world.setBlock(i + 2, j + 8, k + 10, Blocks.COBBLESTONE.defaultBlockState());
//         world.setBlock(i + 2, j + 8, k + 11, Blocks.COBBLESTONE.defaultBlockState());
//         world.setBlock(i + 2, j + 8, k + 12, Blocks.DIRT.defaultBlockState());
//         world.setBlock(i + 2, j + 8, k + 13, Blocks.DIRT.defaultBlockState());
//         world.setBlock(i + 2, j + 8, k + 14, Blocks.DIRT.defaultBlockState());
//         world.setBlock(i + 2, j + 8, k + 15, Blocks.DIRT.defaultBlockState());
//         world.setBlock(i + 2, j + 8, k + 16, Blocks.DIRT.defaultBlockState());
//         world.setBlock(i + 2, j + 9, k + 2, Blocks.GRASS.defaultBlockState());
//         world.setBlock(i + 2, j + 9, k + 3, Blocks.DIRT.defaultBlockState());
//         world.setBlock(i + 2, j + 9, k + 4, Blocks.DIRT.defaultBlockState());
//         world.setBlock(i + 2, j + 9, k + 5, Blocks.DIRT.defaultBlockState());
//         world.setBlock(i + 2, j + 9, k + 6, Blocks.DIRT.defaultBlockState());
//         world.setBlock(i + 2, j + 9, k + 7, Blocks.DIRT.defaultBlockState());
//         world.setBlock(i + 2, j + 9, k + 8, Blocks.COBBLESTONE.defaultBlockState());
//         world.setBlock(i + 2, j + 9, k + 9, Blocks.AIR.defaultBlockState());
//         world.setBlock(i + 2, j + 9, k + 10, Blocks.COBBLESTONE.defaultBlockState());
//         world.setBlock(i + 2, j + 9, k + 11, Blocks.DIRT.defaultBlockState());
//         world.setBlock(i + 2, j + 9, k + 12, Blocks.DIRT.defaultBlockState());
//         world.setBlock(i + 2, j + 9, k + 13, Blocks.DIRT.defaultBlockState());
//         world.setBlock(i + 2, j + 9, k + 14, Blocks.DIRT.defaultBlockState());
//         world.setBlock(i + 2, j + 9, k + 15, Blocks.DIRT.defaultBlockState());
//         world.setBlock(i + 2, j + 9, k + 16, Blocks.GRASS.defaultBlockState());
//         world.setBlock(i + 2, j + 10, k + 3, Blocks.GRASS.defaultBlockState());
//         world.setBlock(i + 2, j + 10, k + 4, Blocks.DIRT.defaultBlockState());
//         world.setBlock(i + 2, j + 10, k + 5, Blocks.DIRT.defaultBlockState());
//         world.setBlock(i + 2, j + 10, k + 6, Blocks.DIRT.defaultBlockState());
//         world.setBlock(i + 2, j + 10, k + 7, Blocks.DIRT.defaultBlockState());
//         world.setBlock(i + 2, j + 10, k + 8, Blocks.COBBLESTONE.defaultBlockState());
//         world.setBlock(i + 2, j + 10, k + 9, Blocks.AIR.defaultBlockState());
//         world.setBlock(i + 2, j + 10, k + 10, Blocks.MOSSY_COBBLESTONE.defaultBlockState());
//         world.setBlock(i + 2, j + 10, k + 11, Blocks.DIRT.defaultBlockState());
//         world.setBlock(i + 2, j + 10, k + 12, Blocks.DIRT.defaultBlockState());
//         world.setBlock(i + 2, j + 10, k + 13, Blocks.DIRT.defaultBlockState());
//         world.setBlock(i + 2, j + 10, k + 14, Blocks.DIRT.defaultBlockState());
//         world.setBlock(i + 2, j + 10, k + 15, Blocks.GRASS.defaultBlockState());
//         world.setBlock(i + 2, j + 11, k + 4, Blocks.GRASS.defaultBlockState());
//         world.setBlock(i + 2, j + 11, k + 5, Blocks.GRASS.defaultBlockState());
//         world.setBlock(i + 2, j + 11, k + 6, Blocks.DIRT.defaultBlockState());
//         world.setBlock(i + 2, j + 11, k + 7, Blocks.DIRT.defaultBlockState());
//         world.setBlock(i + 2, j + 11, k + 8, Blocks.COBBLESTONE.defaultBlockState());
//         world.setBlock(i + 2, j + 11, k + 9, Blocks.stonebrick, 3, 3);
//         world.setBlock(i + 2, j + 11, k + 10, Blocks.MOSSY_COBBLESTONE.defaultBlockState());
//         world.setBlock(i + 2, j + 11, k + 11, Blocks.DIRT.defaultBlockState());
//         world.setBlock(i + 2, j + 11, k + 12, Blocks.GRASS.defaultBlockState());
//         world.setBlock(i + 2, j + 11, k + 13, Blocks.GRASS.defaultBlockState());
//         world.setBlock(i + 2, j + 11, k + 14, Blocks.GRASS.defaultBlockState());
//         world.setBlock(i + 2, j + 12, k + 6, Blocks.GRASS.defaultBlockState());
//         world.setBlock(i + 2, j + 12, k + 7, Blocks.GRASS.defaultBlockState());
//         world.setBlock(i + 2, j + 12, k + 8, Blocks.GRASS.defaultBlockState());
//         world.setBlock(i + 2, j + 12, k + 9, Blocks.GRASS.defaultBlockState());
//         world.setBlock(i + 2, j + 12, k + 10, Blocks.GRASS.defaultBlockState());
//         world.setBlock(i + 2, j + 12, k + 11, Blocks.GRASS.defaultBlockState());
//         world.setBlock(i + 3, j + 4, k + 3, Blocks.COBBLESTONE.defaultBlockState());
//         world.setBlock(i + 3, j + 4, k + 4, Blocks.COBBLESTONE.defaultBlockState());
//         world.setBlock(i + 3, j + 4, k + 5, Blocks.COBBLESTONE.defaultBlockState());
//         world.setBlock(i + 3, j + 4, k + 6, Blocks.COBBLESTONE.defaultBlockState());
//         world.setBlock(i + 3, j + 4, k + 7, Blocks.COBBLESTONE.defaultBlockState());
//         world.setBlock(i + 3, j + 4, k + 8, Blocks.COBBLESTONE.defaultBlockState());
//         world.setBlock(i + 3, j + 4, k + 9, Blocks.COBBLESTONE.defaultBlockState());
//         world.setBlock(i + 3, j + 4, k + 10, Blocks.COBBLESTONE.defaultBlockState());
//         world.setBlock(i + 3, j + 4, k + 11, Blocks.COBBLESTONE.defaultBlockState());
//         world.setBlock(i + 3, j + 4, k + 12, Blocks.COBBLESTONE.defaultBlockState());
//         world.setBlock(i + 3, j + 4, k + 13, Blocks.COBBLESTONE.defaultBlockState());
//         world.setBlock(i + 3, j + 4, k + 14, Blocks.COBBLESTONE.defaultBlockState());
//         world.setBlock(i + 3, j + 4, k + 15, Blocks.COBBLESTONE.defaultBlockState());
//         world.setBlock(i + 3, j + 5, k + 3, Blocks.COBBLESTONE.defaultBlockState());
//         world.setBlock(i + 3, j + 5, k + 4, Blocks.COBBLESTONE.defaultBlockState());
//         world.setBlock(i + 3, j + 5, k + 5, Blocks.COBBLESTONE.defaultBlockState());
//         world.setBlock(i + 3, j + 5, k + 6, Blocks.COBBLESTONE.defaultBlockState());
//         world.setBlock(i + 3, j + 5, k + 7, Blocks.MOSSY_COBBLESTONE.defaultBlockState());
//         world.setBlock(i + 3, j + 5, k + 8, Blocks.MOSSY_COBBLESTONE.defaultBlockState());
//         world.setBlock(i + 3, j + 5, k + 9, Blocks.COBBLESTONE.defaultBlockState());
//         world.setBlock(i + 3, j + 5, k + 10, Blocks.COBBLESTONE.defaultBlockState());
//         world.setBlock(i + 3, j + 5, k + 11, Blocks.COBBLESTONE.defaultBlockState());
//         world.setBlock(i + 3, j + 5, k + 12, Blocks.COBBLESTONE.defaultBlockState());
//         world.setBlock(i + 3, j + 5, k + 13, Blocks.COBBLESTONE.defaultBlockState());
//         world.setBlock(i + 3, j + 5, k + 14, Blocks.COBBLESTONE.defaultBlockState());
//         world.setBlock(i + 3, j + 5, k + 15, Blocks.COBBLESTONE.defaultBlockState());
//         world.setBlock(i + 3, j + 6, k + 3, Blocks.COBBLESTONE.defaultBlockState());
//         world.setBlock(i + 3, j + 6, k + 4, Blocks.COBBLESTONE.defaultBlockState());
//         world.setBlock(i + 3, j + 6, k + 5, Blocks.COBBLESTONE.defaultBlockState());
//         world.setBlock(i + 3, j + 6, k + 6, Blocks.COBBLESTONE.defaultBlockState());
//         world.setBlock(i + 3, j + 6, k + 7, Blocks.COBBLESTONE.defaultBlockState());
//         world.setBlock(i + 3, j + 6, k + 8, Blocks.COBBLESTONE.defaultBlockState());
//         world.setBlock(i + 3, j + 6, k + 9, Blocks.COBBLESTONE.defaultBlockState());
//         world.setBlock(i + 3, j + 6, k + 10, Blocks.COBBLESTONE.defaultBlockState());
//         world.setBlock(i + 3, j + 6, k + 11, Blocks.COBBLESTONE.defaultBlockState());
//         world.setBlock(i + 3, j + 6, k + 12, Blocks.COBBLESTONE.defaultBlockState());
//         world.setBlock(i + 3, j + 6, k + 13, Blocks.MOSSY_COBBLESTONE.defaultBlockState());
//         world.setBlock(i + 3, j + 6, k + 14, Blocks.COBBLESTONE.defaultBlockState());
//         world.setBlock(i + 3, j + 6, k + 15, Blocks.COBBLESTONE.defaultBlockState());
//         world.setBlock(i + 3, j + 7, k + 3, Blocks.COBBLESTONE.defaultBlockState());
//         world.setBlock(i + 3, j + 7, k + 4, Blocks.COBBLESTONE.defaultBlockState());
//         world.setBlock(i + 3, j + 7, k + 5, Blocks.COBBLESTONE.defaultBlockState());
//         world.setBlock(i + 3, j + 7, k + 6, Blocks.COBBLESTONE.defaultBlockState());
//         world.setBlock(i + 3, j + 7, k + 7, Blocks.COBBLESTONE.defaultBlockState());
//         world.setBlock(i + 3, j + 7, k + 8, Blocks.COBBLESTONE.defaultBlockState());
//         world.setBlock(i + 3, j + 7, k + 9, Blocks.COBBLESTONE.defaultBlockState());
//         world.setBlock(i + 3, j + 7, k + 10, Blocks.COBBLESTONE.defaultBlockState());
//         world.setBlock(i + 3, j + 7, k + 11, Blocks.MOSSY_COBBLESTONE.defaultBlockState());
//         world.setBlock(i + 3, j + 7, k + 12, Blocks.COBBLESTONE.defaultBlockState());
//         world.setBlock(i + 3, j + 7, k + 13, Blocks.COBBLESTONE.defaultBlockState());
//         world.setBlock(i + 3, j + 7, k + 14, Blocks.COBBLESTONE.defaultBlockState());
//         world.setBlock(i + 3, j + 7, k + 15, Blocks.COBBLESTONE.defaultBlockState());
//         world.setBlock(i + 3, j + 8, k + 1, Blocks.DIRT.defaultBlockState());
//         world.setBlock(i + 3, j + 8, k + 2, Blocks.DIRT.defaultBlockState());
//         world.setBlock(i + 3, j + 8, k + 3, Blocks.COBBLESTONE.defaultBlockState());
//         world.setBlock(i + 3, j + 8, k + 4, Blocks.COBBLESTONE.defaultBlockState());
//         world.setBlock(i + 3, j + 8, k + 5, Blocks.COBBLESTONE.defaultBlockState());
//         world.setBlock(i + 3, j + 8, k + 6, Blocks.COBBLESTONE.defaultBlockState());
//         world.setBlock(i + 3, j + 8, k + 7, Blocks.MOSSY_COBBLESTONE.defaultBlockState());
//         world.setBlock(i + 3, j + 8, k + 8, Blocks.COBBLESTONE.defaultBlockState());
//         world.setBlock(i + 3, j + 8, k + 9, Blocks.COBBLESTONE.defaultBlockState());
//         world.setBlock(i + 3, j + 8, k + 10, Blocks.COBBLESTONE.defaultBlockState());
//         world.setBlock(i + 3, j + 8, k + 11, Blocks.COBBLESTONE.defaultBlockState());
//         world.setBlock(i + 3, j + 8, k + 12, Blocks.COBBLESTONE.defaultBlockState());
//         world.setBlock(i + 3, j + 8, k + 13, Blocks.COBBLESTONE.defaultBlockState());
//         world.setBlock(i + 3, j + 8, k + 14, Blocks.COBBLESTONE.defaultBlockState());
//         world.setBlock(i + 3, j + 8, k + 15, Blocks.COBBLESTONE.defaultBlockState());
//         world.setBlock(i + 3, j + 8, k + 16, Blocks.DIRT.defaultBlockState());
//         world.setBlock(i + 3, j + 8, k + 17, Blocks.DIRT.defaultBlockState());
//         world.setBlock(i + 3, j + 9, k + 1, Blocks.GRASS.defaultBlockState());
//         world.setBlock(i + 3, j + 9, k + 2, Blocks.DIRT.defaultBlockState());
//         world.setBlock(i + 3, j + 9, k + 3, Blocks.COBBLESTONE.defaultBlockState());
//         world.setBlock(i + 3, j + 9, k + 4, Blocks.COBBLESTONE.defaultBlockState());
//         world.setBlock(i + 3, j + 9, k + 5, Blocks.COBBLESTONE.defaultBlockState());
//         world.setBlock(i + 3, j + 9, k + 6, Blocks.COBBLESTONE.defaultBlockState());
//         world.setBlock(i + 3, j + 9, k + 7, Blocks.COBBLESTONE.defaultBlockState());
//         world.setBlock(i + 3, j + 9, k + 8, Blocks.COBBLESTONE.defaultBlockState());
//         world.setBlock(i + 3, j + 9, k + 9, Blocks.iron_bars);
//         world.setBlock(i + 3, j + 9, k + 10, Blocks.COBBLESTONE.defaultBlockState());
//         world.setBlock(i + 3, j + 9, k + 11, Blocks.COBBLESTONE.defaultBlockState());
//         world.setBlock(i + 3, j + 9, k + 12, Blocks.MOSSY_COBBLESTONE.defaultBlockState());
//         world.setBlock(i + 3, j + 9, k + 13, Blocks.COBBLESTONE.defaultBlockState());
//         world.setBlock(i + 3, j + 9, k + 14, Blocks.COBBLESTONE.defaultBlockState());
//         world.setBlock(i + 3, j + 9, k + 15, Blocks.COBBLESTONE.defaultBlockState());
//         world.setBlock(i + 3, j + 9, k + 16, Blocks.DIRT.defaultBlockState());
//         world.setBlock(i + 3, j + 9, k + 17, Blocks.GRASS.defaultBlockState());
//         world.setBlock(i + 3, j + 10, k + 2, Blocks.GRASS.defaultBlockState());
//         world.setBlock(i + 3, j + 10, k + 3, Blocks.COBBLESTONE.defaultBlockState());
//         world.setBlock(i + 3, j + 10, k + 4, Blocks.MOSSY_COBBLESTONE.defaultBlockState());
//         world.setBlock(i + 3, j + 10, k + 5, Blocks.MOSSY_COBBLESTONE.defaultBlockState());
//         world.setBlock(i + 3, j + 10, k + 6, Blocks.COBBLESTONE.defaultBlockState());
//         world.setBlock(i + 3, j + 10, k + 7, Blocks.MOSSY_COBBLESTONE.defaultBlockState());
//         world.setBlock(i + 3, j + 10, k + 8, Blocks.COBBLESTONE.defaultBlockState());
//         world.setBlock(i + 3, j + 10, k + 9, Blocks.iron_bars);
//         world.setBlock(i + 3, j + 10, k + 10, Blocks.COBBLESTONE.defaultBlockState());
//         world.setBlock(i + 3, j + 10, k + 11, Blocks.COBBLESTONE.defaultBlockState());
//         world.setBlock(i + 3, j + 10, k + 12, Blocks.COBBLESTONE.defaultBlockState());
//         world.setBlock(i + 3, j + 10, k + 13, Blocks.COBBLESTONE.defaultBlockState());
//         world.setBlock(i + 3, j + 10, k + 14, Blocks.COBBLESTONE.defaultBlockState());
//         world.setBlock(i + 3, j + 10, k + 15, Blocks.COBBLESTONE.defaultBlockState());
//         world.setBlock(i + 3, j + 10, k + 16, Blocks.GRASS.defaultBlockState());
//         world.setBlock(i + 3, j + 11, k + 3, Blocks.GRASS.defaultBlockState());
//         world.setBlock(i + 3, j + 11, k + 4, Blocks.DIRT.defaultBlockState());
//         world.setBlock(i + 3, j + 11, k + 5, Blocks.COBBLESTONE.defaultBlockState());
//         world.setBlock(i + 3, j + 11, k + 6, Blocks.COBBLESTONE.defaultBlockState());
//         world.setBlock(i + 3, j + 11, k + 7, Blocks.COBBLESTONE.defaultBlockState());
//         world.setBlock(i + 3, j + 11, k + 8, Blocks.COBBLESTONE.defaultBlockState());
//         world.setBlock(i + 3, j + 11, k + 9, Blocks.MOSSY_COBBLESTONE.defaultBlockState());
//         world.setBlock(i + 3, j + 11, k + 10, Blocks.COBBLESTONE.defaultBlockState());
//         world.setBlock(i + 3, j + 11, k + 11, Blocks.COBBLESTONE.defaultBlockState());
//         world.setBlock(i + 3, j + 11, k + 12, Blocks.COBBLESTONE.defaultBlockState());
//         world.setBlock(i + 3, j + 11, k + 13, Blocks.COBBLESTONE.defaultBlockState());
//         world.setBlock(i + 3, j + 11, k + 14, Blocks.DIRT.defaultBlockState());
//         world.setBlock(i + 3, j + 11, k + 15, Blocks.GRASS.defaultBlockState());
//         world.setBlock(i + 3, j + 12, k + 4, Blocks.GRASS.defaultBlockState());
//         world.setBlock(i + 3, j + 12, k + 5, Blocks.GRASS.defaultBlockState());
//         world.setBlock(i + 3, j + 12, k + 6, Blocks.GRASS.defaultBlockState());
//         world.setBlock(i + 3, j + 12, k + 7, Blocks.GRASS.defaultBlockState());
//         world.setBlock(i + 3, j + 12, k + 8, Blocks.GRASS.defaultBlockState());
//         world.setBlock(i + 3, j + 12, k + 9, Blocks.GRASS.defaultBlockState());
//         world.setBlock(i + 3, j + 12, k + 10, Blocks.GRASS.defaultBlockState());
//         world.setBlock(i + 3, j + 12, k + 11, Blocks.GRASS.defaultBlockState());
//         world.setBlock(i + 3, j + 12, k + 12, Blocks.GRASS.defaultBlockState());
//         world.setBlock(i + 3, j + 12, k + 13, Blocks.GRASS.defaultBlockState());
//         world.setBlock(i + 3, j + 12, k + 14, Blocks.GRASS.defaultBlockState());
//         world.setBlock(i + 4, j + 4, k + 3, Blocks.COBBLESTONE.defaultBlockState());
//         world.setBlock(i + 4, j + 4, k + 4, Blocks.COBBLESTONE.defaultBlockState());
//         world.setBlock(i + 4, j + 4, k + 5, Blocks.COBBLESTONE.defaultBlockState());
//         world.setBlock(i + 4, j + 4, k + 6, Blocks.COBBLESTONE.defaultBlockState());
//         world.setBlock(i + 4, j + 4, k + 7, Blocks.COBBLESTONE.defaultBlockState());
//         world.setBlock(i + 4, j + 4, k + 8, Blocks.COBBLESTONE.defaultBlockState());
//         world.setBlock(i + 4, j + 4, k + 9, Blocks.COBBLESTONE.defaultBlockState());
//         world.setBlock(i + 4, j + 4, k + 10, Blocks.COBBLESTONE.defaultBlockState());
//         world.setBlock(i + 4, j + 4, k + 11, Blocks.COBBLESTONE.defaultBlockState());
//         world.setBlock(i + 4, j + 4, k + 12, Blocks.COBBLESTONE.defaultBlockState());
//         world.setBlock(i + 4, j + 4, k + 13, Blocks.COBBLESTONE.defaultBlockState());
//         world.setBlock(i + 4, j + 4, k + 14, Blocks.COBBLESTONE.defaultBlockState());
//         world.setBlock(i + 4, j + 4, k + 15, Blocks.COBBLESTONE.defaultBlockState());
//         world.setBlock(i + 4, j + 5, k + 3, Blocks.COBBLESTONE.defaultBlockState());
//         world.setBlock(i + 4, j + 5, k + 15, Blocks.COBBLESTONE.defaultBlockState());
//         world.setBlock(i + 4, j + 6, k + 3, Blocks.COBBLESTONE.defaultBlockState());
//         world.setBlock(i + 4, j + 6, k + 15, Blocks.COBBLESTONE.defaultBlockState());
//         world.setBlock(i + 4, j + 7, k + 3, Blocks.MOSSY_COBBLESTONE.defaultBlockState());
//         world.setBlock(i + 4, j + 7, k + 15, Blocks.COBBLESTONE.defaultBlockState());
//         world.setBlock(i + 4, j + 8, k, Blocks.DIRT.defaultBlockState());
//         world.setBlock(i + 4, j + 8, k + 1, Blocks.DIRT.defaultBlockState());
//         world.setBlock(i + 4, j + 8, k + 2, Blocks.DIRT.defaultBlockState());
//         world.setBlock(i + 4, j + 8, k + 3, Blocks.COBBLESTONE.defaultBlockState());
//         world.setBlock(i + 4, j + 8, k + 4, Blocks.MOSSY_COBBLESTONE.defaultBlockState());
//         world.setBlock(i + 4, j + 8, k + 5, Blocks.MOSSY_COBBLESTONE.defaultBlockState());
//         world.setBlock(i + 4, j + 8, k + 6, Blocks.COBBLESTONE.defaultBlockState());
//         world.setBlock(i + 4, j + 8, k + 7, Blocks.COBBLESTONE.defaultBlockState());
//         world.setBlock(i + 4, j + 8, k + 8, Blocks.COBBLESTONE.defaultBlockState());
//         world.setBlock(i + 4, j + 8, k + 9, Blocks.MOSSY_COBBLESTONE.defaultBlockState());
//         world.setBlock(i + 4, j + 8, k + 10, Blocks.MOSSY_COBBLESTONE.defaultBlockState());
//         world.setBlock(i + 4, j + 8, k + 11, Blocks.COBBLESTONE.defaultBlockState());
//         world.setBlock(i + 4, j + 8, k + 12, Blocks.COBBLESTONE.defaultBlockState());
//         world.setBlock(i + 4, j + 8, k + 13, Blocks.COBBLESTONE.defaultBlockState());
//         world.setBlock(i + 4, j + 8, k + 14, Blocks.COBBLESTONE.defaultBlockState());
//         world.setBlock(i + 4, j + 8, k + 15, Blocks.COBBLESTONE.defaultBlockState());
//         world.setBlock(i + 4, j + 8, k + 16, Blocks.DIRT.defaultBlockState());
//         world.setBlock(i + 4, j + 8, k + 17, Blocks.DIRT.defaultBlockState());
//         world.setBlock(i + 4, j + 8, k + 18, Blocks.DIRT.defaultBlockState());
//         world.setBlock(i + 4, j + 9, k, Blocks.GRASS.defaultBlockState());
//         world.setBlock(i + 4, j + 9, k + 1, Blocks.DIRT.defaultBlockState());
//         world.setBlock(i + 4, j + 9, k + 2, Blocks.DIRT.defaultBlockState());
//         world.setBlock(i + 4, j + 9, k + 3, Blocks.COBBLESTONE.defaultBlockState());
//         world.setBlock(i + 4, j + 9, k + 15, Blocks.COBBLESTONE.defaultBlockState());
//         world.setBlock(i + 4, j + 9, k + 16, Blocks.DIRT.defaultBlockState());
//         world.setBlock(i + 4, j + 9, k + 17, Blocks.DIRT.defaultBlockState());
//         world.setBlock(i + 4, j + 9, k + 18, Blocks.GRASS.defaultBlockState());
//         world.setBlock(i + 4, j + 10, k + 1, Blocks.GRASS.defaultBlockState());
//         world.setBlock(i + 4, j + 10, k + 2, Blocks.DIRT.defaultBlockState());
//         world.setBlock(i + 4, j + 10, k + 3, Blocks.COBBLESTONE.defaultBlockState());
//         world.setBlock(i + 4, j + 10, k + 15, Blocks.MOSSY_COBBLESTONE.defaultBlockState());
//         world.setBlock(i + 4, j + 10, k + 16, Blocks.DIRT.defaultBlockState());
//         world.setBlock(i + 4, j + 10, k + 17, Blocks.GRASS.defaultBlockState());
//         world.setBlock(i + 4, j + 11, k + 2, Blocks.GRASS.defaultBlockState());
//         world.setBlock(i + 4, j + 11, k + 3, Blocks.DIRT.defaultBlockState());
//         world.setBlock(i + 4, j + 11, k + 4, Blocks.COBBLESTONE.defaultBlockState());
//         world.setBlock(i + 4, j + 11, k + 14, Blocks.MOSSY_COBBLESTONE.defaultBlockState());
//         world.setBlock(i + 4, j + 11, k + 15, Blocks.DIRT.defaultBlockState());
//         world.setBlock(i + 4, j + 11, k + 16, Blocks.GRASS.defaultBlockState());
//         world.setBlock(i + 4, j + 12, k + 3, Blocks.GRASS.defaultBlockState());
//         world.setBlock(i + 4, j + 12, k + 4, Blocks.GRASS.defaultBlockState());
//         world.setBlock(i + 4, j + 12, k + 5, Blocks.COBBLESTONE.defaultBlockState());
//         world.setBlock(i + 4, j + 12, k + 6, Blocks.COBBLESTONE.defaultBlockState());
//         world.setBlock(i + 4, j + 12, k + 7, Blocks.COBBLESTONE.defaultBlockState());
//         world.setBlock(i + 4, j + 12, k + 8, Blocks.COBBLESTONE.defaultBlockState());
//         world.setBlock(i + 4, j + 12, k + 9, Blocks.COBBLESTONE.defaultBlockState());
//         world.setBlock(i + 4, j + 12, k + 10, Blocks.COBBLESTONE.defaultBlockState());
//         world.setBlock(i + 4, j + 12, k + 11, Blocks.COBBLESTONE.defaultBlockState());
//         world.setBlock(i + 4, j + 12, k + 12, Blocks.COBBLESTONE.defaultBlockState());
//         world.setBlock(i + 4, j + 12, k + 13, Blocks.COBBLESTONE.defaultBlockState());
//         world.setBlock(i + 4, j + 12, k + 14, Blocks.DIRT.defaultBlockState());
//         world.setBlock(i + 4, j + 12, k + 15, Blocks.GRASS.defaultBlockState());
//         world.setBlock(i + 4, j + 13, k + 5, Blocks.GRASS.defaultBlockState());
//         world.setBlock(i + 4, j + 13, k + 6, Blocks.GRASS.defaultBlockState());
//         world.setBlock(i + 4, j + 13, k + 7, Blocks.GRASS.defaultBlockState());
//         world.setBlock(i + 4, j + 13, k + 8, Blocks.GRASS.defaultBlockState());
//         world.setBlock(i + 4, j + 13, k + 9, Blocks.GRASS.defaultBlockState());
//         world.setBlock(i + 4, j + 13, k + 10, Blocks.GRASS.defaultBlockState());
//         world.setBlock(i + 4, j + 13, k + 11, Blocks.GRASS.defaultBlockState());
//         world.setBlock(i + 4, j + 13, k + 12, Blocks.GRASS.defaultBlockState());
//         world.setBlock(i + 4, j + 13, k + 13, Blocks.GRASS.defaultBlockState());
//         world.setBlock(i + 4, j + 13, k + 14, Blocks.GRASS.defaultBlockState());
//         world.setBlock(i + 5, j + 4, k + 3, Blocks.COBBLESTONE.defaultBlockState());
//         world.setBlock(i + 5, j + 4, k + 4, Blocks.COBBLESTONE.defaultBlockState());
//         world.setBlock(i + 5, j + 4, k + 5, Blocks.COBBLESTONE.defaultBlockState());
//         world.setBlock(i + 5, j + 4, k + 6, Blocks.COBBLESTONE.defaultBlockState());
//         world.setBlock(i + 5, j + 4, k + 7, Blocks.COBBLESTONE.defaultBlockState());
//         world.setBlock(i + 5, j + 4, k + 8, Blocks.COBBLESTONE.defaultBlockState());
//         world.setBlock(i + 5, j + 4, k + 9, Blocks.COBBLESTONE.defaultBlockState());
//         world.setBlock(i + 5, j + 4, k + 10, Blocks.MOSSY_COBBLESTONE.defaultBlockState());
//         world.setBlock(i + 5, j + 4, k + 11, Blocks.COBBLESTONE.defaultBlockState());
//         world.setBlock(i + 5, j + 4, k + 12, Blocks.COBBLESTONE.defaultBlockState());
//         world.setBlock(i + 5, j + 4, k + 13, Blocks.MOSSY_COBBLESTONE.defaultBlockState());
//         world.setBlock(i + 5, j + 4, k + 14, Blocks.COBBLESTONE.defaultBlockState());
//         world.setBlock(i + 5, j + 4, k + 15, Blocks.COBBLESTONE.defaultBlockState());
//         world.setBlock(i + 5, j + 5, k + 3, Blocks.COBBLESTONE.defaultBlockState());
//         world.setBlock(i + 5, j + 5, k + 15, Blocks.COBBLESTONE.defaultBlockState());
//         world.setBlock(i + 5, j + 6, k + 3, Blocks.MOSSY_COBBLESTONE.defaultBlockState());
//         world.setBlock(i + 5, j + 6, k + 15, Blocks.COBBLESTONE.defaultBlockState());
//         world.setBlock(i + 5, j + 7, k + 3, Blocks.COBBLESTONE.defaultBlockState());
//         world.setBlock(i + 5, j + 7, k + 15, Blocks.COBBLESTONE.defaultBlockState());
//         world.setBlock(i + 5, j + 8, k, Blocks.DIRT.defaultBlockState());
//         world.setBlock(i + 5, j + 8, k + 1, Blocks.DIRT.defaultBlockState());
//         world.setBlock(i + 5, j + 8, k + 2, Blocks.DIRT.defaultBlockState());
//         world.setBlock(i + 5, j + 8, k + 3, Blocks.COBBLESTONE.defaultBlockState());
//         world.setBlock(i + 5, j + 8, k + 4, Blocks.MOSSY_COBBLESTONE.defaultBlockState());
//         world.setBlock(i + 5, j + 8, k + 5, Blocks.COBBLESTONE.defaultBlockState());
//         world.setBlock(i + 5, j + 8, k + 6, Blocks.COBBLESTONE.defaultBlockState());
//         world.setBlock(i + 5, j + 8, k + 7, Blocks.COBBLESTONE.defaultBlockState());
//         world.setBlock(i + 5, j + 8, k + 8, Blocks.COBBLESTONE.defaultBlockState());
//         world.setBlock(i + 5, j + 8, k + 9, Blocks.COBBLESTONE.defaultBlockState());
//         world.setBlock(i + 5, j + 8, k + 10, Blocks.COBBLESTONE.defaultBlockState());
//         world.setBlock(i + 5, j + 8, k + 11, Blocks.COBBLESTONE.defaultBlockState());
//         world.setBlock(i + 5, j + 8, k + 12, Blocks.COBBLESTONE.defaultBlockState());
//         world.setBlock(i + 5, j + 8, k + 13, Blocks.MOSSY_COBBLESTONE.defaultBlockState());
//         world.setBlock(i + 5, j + 8, k + 14, Blocks.COBBLESTONE.defaultBlockState());
//         world.setBlock(i + 5, j + 8, k + 15, Blocks.COBBLESTONE.defaultBlockState());
//         world.setBlock(i + 5, j + 8, k + 16, Blocks.DIRT.defaultBlockState());
//         world.setBlock(i + 5, j + 8, k + 17, Blocks.DIRT.defaultBlockState());
//         world.setBlock(i + 5, j + 8, k + 18, Blocks.DIRT.defaultBlockState());
//         world.setBlock(i + 5, j + 9, k, Blocks.GRASS.defaultBlockState());
//         world.setBlock(i + 5, j + 9, k + 1, Blocks.DIRT.defaultBlockState());
//         world.setBlock(i + 5, j + 9, k + 2, Blocks.DIRT.defaultBlockState());
//         world.setBlock(i + 5, j + 9, k + 3, Blocks.COBBLESTONE.defaultBlockState());
//         world.setBlock(i + 5, j + 9, k + 15, Blocks.COBBLESTONE.defaultBlockState());
//         world.setBlock(i + 5, j + 9, k + 16, Blocks.DIRT.defaultBlockState());
//         world.setBlock(i + 5, j + 9, k + 17, Blocks.DIRT.defaultBlockState());
//         world.setBlock(i + 5, j + 9, k + 18, Blocks.GRASS.defaultBlockState());
//         world.setBlock(i + 5, j + 10, k + 1, Blocks.GRASS.defaultBlockState());
//         world.setBlock(i + 5, j + 10, k + 2, Blocks.DIRT.defaultBlockState());
//         world.setBlock(i + 5, j + 10, k + 3, Blocks.COBBLESTONE.defaultBlockState());
//         world.setBlock(i + 5, j + 10, k + 15, Blocks.COBBLESTONE.defaultBlockState());
//         world.setBlock(i + 5, j + 10, k + 16, Blocks.DIRT.defaultBlockState());
//         world.setBlock(i + 5, j + 10, k + 17, Blocks.GRASS.defaultBlockState());
//         world.setBlock(i + 5, j + 11, k + 2, Blocks.DIRT.defaultBlockState());
//         world.setBlock(i + 5, j + 11, k + 3, Blocks.COBBLESTONE.defaultBlockState());
//         world.setBlock(i + 5, j + 11, k + 6, stoneStair4);
//         world.setBlock(i + 5, j + 11, k + 12, stoneStair4);
//         world.setBlock(i + 5, j + 11, k + 15, Blocks.COBBLESTONE.defaultBlockState());
//         world.setBlock(i + 5, j + 11, k + 16, Blocks.GRASS.defaultBlockState());
//         world.setBlock(i + 5, j + 12, k + 2, Blocks.GRASS.defaultBlockState());
//         world.setBlock(i + 5, j + 12, k + 3, Blocks.GRASS.defaultBlockState());
//         world.setBlock(i + 5, j + 12, k + 4, Blocks.COBBLESTONE.defaultBlockState());
//         world.setBlock(i + 5, j + 12, k + 5, Blocks.COBBLESTONE.defaultBlockState());
//         world.setBlock(i + 5, j + 12, k + 6, Blocks.COBBLESTONE.defaultBlockState());
//         world.setBlock(i + 5, j + 12, k + 7, Blocks.COBBLESTONE.defaultBlockState());
//         world.setBlock(i + 5, j + 12, k + 8, Blocks.COBBLESTONE.defaultBlockState());
//         world.setBlock(i + 5, j + 12, k + 9, Blocks.COBBLESTONE.defaultBlockState());
//         world.setBlock(i + 5, j + 12, k + 10, Blocks.COBBLESTONE.defaultBlockState());
//         world.setBlock(i + 5, j + 12, k + 11, Blocks.COBBLESTONE.defaultBlockState());
//         world.setBlock(i + 5, j + 12, k + 12, Blocks.MOSSY_COBBLESTONE.defaultBlockState());
//         world.setBlock(i + 5, j + 12, k + 13, Blocks.COBBLESTONE.defaultBlockState());
//         world.setBlock(i + 5, j + 12, k + 14, Blocks.COBBLESTONE.defaultBlockState());
//         world.setBlock(i + 5, j + 12, k + 15, Blocks.DIRT.defaultBlockState());
//         world.setBlock(i + 5, j + 13, k + 4, Blocks.GRASS.defaultBlockState());
//         world.setBlock(i + 5, j + 13, k + 5, Blocks.GRASS.defaultBlockState());
//         world.setBlock(i + 5, j + 13, k + 6, Blocks.GRASS.defaultBlockState());
//         world.setBlock(i + 5, j + 13, k + 7, Blocks.GRASS.defaultBlockState());
//         world.setBlock(i + 5, j + 13, k + 8, Blocks.GRASS.defaultBlockState());
//         world.setBlock(i + 5, j + 13, k + 9, Blocks.GRASS.defaultBlockState());
//         world.setBlock(i + 5, j + 13, k + 10, Blocks.GRASS.defaultBlockState());
//         world.setBlock(i + 5, j + 13, k + 11, Blocks.GRASS.defaultBlockState());
//         world.setBlock(i + 5, j + 13, k + 12, Blocks.GRASS.defaultBlockState());
//         world.setBlock(i + 5, j + 13, k + 13, Blocks.GRASS.defaultBlockState());
//         world.setBlock(i + 5, j + 13, k + 14, Blocks.GRASS.defaultBlockState());
//         world.setBlock(i + 5, j + 13, k + 15, Blocks.GRASS.defaultBlockState());
//         world.setBlock(i + 6, j, k + 6, Blocks.COBBLESTONE.defaultBlockState());
//         world.setBlock(i + 6, j, k + 7, Blocks.COBBLESTONE.defaultBlockState());
//         world.setBlock(i + 6, j, k + 8, Blocks.COBBLESTONE.defaultBlockState());
//         world.setBlock(i + 6, j, k + 9, Blocks.COBBLESTONE.defaultBlockState());
//         world.setBlock(i + 6, j, k + 10, Blocks.COBBLESTONE.defaultBlockState());
//         world.setBlock(i + 6, j, k + 11, Blocks.COBBLESTONE.defaultBlockState());
//         world.setBlock(i + 6, j, k + 12, Blocks.COBBLESTONE.defaultBlockState());
//         world.setBlock(i + 6, j + 1, k + 6, Blocks.MOSSY_COBBLESTONE.defaultBlockState());
//         world.setBlock(i + 6, j + 1, k + 7, Blocks.COBBLESTONE.defaultBlockState());
//         world.setBlock(i + 6, j + 1, k + 8, Blocks.COBBLESTONE.defaultBlockState());
//         world.setBlock(i + 6, j + 1, k + 9, Blocks.MOSSY_COBBLESTONE.defaultBlockState());
//         world.setBlock(i + 6, j + 1, k + 10, Blocks.MOSSY_COBBLESTONE.defaultBlockState());
//         world.setBlock(i + 6, j + 1, k + 11, Blocks.COBBLESTONE.defaultBlockState());
//         world.setBlock(i + 6, j + 1, k + 12, Blocks.COBBLESTONE.defaultBlockState());
//         world.setBlock(i + 6, j + 2, k + 6, Blocks.COBBLESTONE.defaultBlockState());
//         world.setBlock(i + 6, j + 2, k + 7, Blocks.COBBLESTONE.defaultBlockState());
//         world.setBlock(i + 6, j + 2, k + 8, Blocks.COBBLESTONE.defaultBlockState());
//         world.setBlock(i + 6, j + 2, k + 9, Blocks.COBBLESTONE.defaultBlockState());
//         world.setBlock(i + 6, j + 2, k + 10, Blocks.COBBLESTONE.defaultBlockState());
//         world.setBlock(i + 6, j + 2, k + 11, Blocks.COBBLESTONE.defaultBlockState());
//         world.setBlock(i + 6, j + 2, k + 12, Blocks.COBBLESTONE.defaultBlockState());
//         world.setBlock(i + 6, j + 3, k + 6, Blocks.COBBLESTONE.defaultBlockState());
//         world.setBlock(i + 6, j + 3, k + 7, Blocks.COBBLESTONE.defaultBlockState());
//         world.setBlock(i + 6, j + 3, k + 8, Blocks.MOSSY_COBBLESTONE.defaultBlockState());
//         world.setBlock(i + 6, j + 3, k + 9, Blocks.COBBLESTONE.defaultBlockState());
//         world.setBlock(i + 6, j + 3, k + 10, Blocks.COBBLESTONE.defaultBlockState());
//         world.setBlock(i + 6, j + 3, k + 11, Blocks.COBBLESTONE.defaultBlockState());
//         world.setBlock(i + 6, j + 3, k + 12, Blocks.COBBLESTONE.defaultBlockState());
//         world.setBlock(i + 6, j + 4, k + 3, Blocks.COBBLESTONE.defaultBlockState());
//         world.setBlock(i + 6, j + 4, k + 4, Blocks.COBBLESTONE.defaultBlockState());
//         world.setBlock(i + 6, j + 4, k + 5, Blocks.COBBLESTONE.defaultBlockState());
//         world.setBlock(i + 6, j + 4, k + 6, Blocks.COBBLESTONE.defaultBlockState());
//         world.setBlock(i + 6, j + 4, k + 7, stoneStair1);
//         world.setBlock(i + 6, j + 4, k + 8, stoneStair1);
//         world.setBlock(i + 6, j + 4, k + 9, Blocks.COBBLESTONE.defaultBlockState());
//         world.setBlock(i + 6, j + 4, k + 10, stoneStair1);
//         world.setBlock(i + 6, j + 4, k + 11, stoneStair1);
//         world.setBlock(i + 6, j + 4, k + 12, Blocks.COBBLESTONE.defaultBlockState());
//         world.setBlock(i + 6, j + 4, k + 13, Blocks.COBBLESTONE.defaultBlockState());
//         world.setBlock(i + 6, j + 4, k + 14, Blocks.COBBLESTONE.defaultBlockState());
//         world.setBlock(i + 6, j + 4, k + 15, Blocks.COBBLESTONE.defaultBlockState());
//         world.setBlock(i + 6, j + 5, k + 3, Blocks.COBBLESTONE.defaultBlockState());
//         world.setBlock(i + 6, j + 5, k + 6, Blocks.MOSSY_COBBLESTONE.defaultBlockState());
//         world.setBlock(i + 6, j + 5, k + 12, Blocks.COBBLESTONE.defaultBlockState());
//         world.setBlock(i + 6, j + 5, k + 15, Blocks.MOSSY_COBBLESTONE.defaultBlockState());
//         world.setBlock(i + 6, j + 6, k + 3, Blocks.COBBLESTONE.defaultBlockState());
//         world.setBlock(i + 6, j + 6, k + 6, Blocks.MOSSY_COBBLESTONE.defaultBlockState());
//         world.setBlock(i + 6, j + 6, k + 12, Blocks.COBBLESTONE.defaultBlockState());
//         world.setBlock(i + 6, j + 6, k + 15, Blocks.COBBLESTONE.defaultBlockState());
//         world.setBlock(i + 6, j + 7, k + 3, Blocks.COBBLESTONE.defaultBlockState());
//         world.setBlock(i + 6, j + 7, k + 6, Blocks.COBBLESTONE.defaultBlockState());
//         world.setBlock(i + 6, j + 7, k + 12, Blocks.COBBLESTONE.defaultBlockState());
//         world.setBlock(i + 6, j + 7, k + 15, Blocks.COBBLESTONE.defaultBlockState());
//         world.setBlock(i + 6, j + 8, k, Blocks.DIRT.defaultBlockState());
//         world.setBlock(i + 6, j + 8, k + 1, Blocks.DIRT.defaultBlockState());
//         world.setBlock(i + 6, j + 8, k + 2, Blocks.DIRT.defaultBlockState());
//         world.setBlock(i + 6, j + 8, k + 3, Blocks.COBBLESTONE.defaultBlockState());
//         world.setBlock(i + 6, j + 8, k + 4, Blocks.COBBLESTONE.defaultBlockState());
//         world.setBlock(i + 6, j + 8, k + 5, Blocks.COBBLESTONE.defaultBlockState());
//         world.setBlock(i + 6, j + 8, k + 6, Blocks.COBBLESTONE.defaultBlockState());
//         world.setBlock(i + 6, j + 8, k + 7, stoneStair5);
//         world.setBlock(i + 6, j + 8, k + 8, stoneStair5);
//         world.setBlock(i + 6, j + 8, k + 9, stoneStair5);
//         world.setBlock(i + 6, j + 8, k + 10, stoneStair5);
//         world.setBlock(i + 6, j + 8, k + 11, stoneStair5);
//         world.setBlock(i + 6, j + 8, k + 12, Blocks.MOSSY_COBBLESTONE.defaultBlockState());
//         world.setBlock(i + 6, j + 8, k + 13, Blocks.COBBLESTONE.defaultBlockState());
//         world.setBlock(i + 6, j + 8, k + 14, Blocks.COBBLESTONE.defaultBlockState());
//         world.setBlock(i + 6, j + 8, k + 15, Blocks.COBBLESTONE.defaultBlockState());
//         world.setBlock(i + 6, j + 8, k + 16, Blocks.DIRT.defaultBlockState());
//         world.setBlock(i + 6, j + 8, k + 17, Blocks.DIRT.defaultBlockState());
//         world.setBlock(i + 6, j + 8, k + 18, Blocks.DIRT.defaultBlockState());
//         world.setBlock(i + 6, j + 9, k, Blocks.GRASS.defaultBlockState());
//         world.setBlock(i + 6, j + 9, k + 1, Blocks.DIRT.defaultBlockState());
//         world.setBlock(i + 6, j + 9, k + 2, Blocks.DIRT.defaultBlockState());
//         world.setBlock(i + 6, j + 9, k + 3, Blocks.COBBLESTONE.defaultBlockState());
//         world.setBlock(i + 6, j + 9, k + 6, Blocks.MOSSY_COBBLESTONE.defaultBlockState());
//         world.setBlock(i + 6, j + 9, k + 12, Blocks.COBBLESTONE.defaultBlockState());
//         world.setBlock(i + 6, j + 9, k + 15, Blocks.COBBLESTONE.defaultBlockState());
//         world.setBlock(i + 6, j + 9, k + 16, Blocks.DIRT.defaultBlockState());
//         world.setBlock(i + 6, j + 9, k + 17, Blocks.DIRT.defaultBlockState());
//         world.setBlock(i + 6, j + 9, k + 18, Blocks.GRASS.defaultBlockState());
//         world.setBlock(i + 6, j + 10, k + 1, Blocks.GRASS.defaultBlockState());
//         world.setBlock(i + 6, j + 10, k + 2, Blocks.DIRT.defaultBlockState());
//         world.setBlock(i + 6, j + 10, k + 3, Blocks.COBBLESTONE.defaultBlockState());
//         world.setBlock(i + 6, j + 10, k + 6, Blocks.COBBLESTONE.defaultBlockState());
//         world.setBlock(i + 6, j + 10, k + 12, Blocks.MOSSY_COBBLESTONE.defaultBlockState());
//         world.setBlock(i + 6, j + 10, k + 15, Blocks.COBBLESTONE.defaultBlockState());
//         world.setBlock(i + 6, j + 10, k + 16, Blocks.DIRT.defaultBlockState());
//         world.setBlock(i + 6, j + 10, k + 17, Blocks.GRASS.defaultBlockState());
//         world.setBlock(i + 6, j + 11, k + 2, Blocks.GRASS.defaultBlockState());
//         world.setBlock(i + 6, j + 11, k + 3, Blocks.COBBLESTONE.defaultBlockState());
//         world.setBlock(i + 6, j + 11, k + 5, stoneStair6);
//         world.setBlock(i + 6, j + 11, k + 6, Blocks.COBBLESTONE.defaultBlockState());
//         world.setBlock(i + 6, j + 11, k + 7, stoneStair7);
//         world.setBlock(i + 6, j + 11, k + 11, stoneStair6);
//         world.setBlock(i + 6, j + 11, k + 12, Blocks.COBBLESTONE.defaultBlockState());
//         world.setBlock(i + 6, j + 11, k + 13, stoneStair7);
//         world.setBlock(i + 6, j + 11, k + 15, Blocks.MOSSY_COBBLESTONE.defaultBlockState());
//         world.setBlock(i + 6, j + 11, k + 16, Blocks.GRASS.defaultBlockState());
//         world.setBlock(i + 6, j + 12, k + 3, Blocks.GRASS.defaultBlockState());
//         world.setBlock(i + 6, j + 12, k + 4, Blocks.COBBLESTONE.defaultBlockState());
//         world.setBlock(i + 6, j + 12, k + 5, Blocks.COBBLESTONE.defaultBlockState());
//         world.setBlock(i + 6, j + 12, k + 6, Blocks.MOSSY_COBBLESTONE.defaultBlockState());
//         world.setBlock(i + 6, j + 12, k + 7, Blocks.COBBLESTONE.defaultBlockState());
//         world.setBlock(i + 6, j + 12, k + 8, Blocks.COBBLESTONE.defaultBlockState());
//         world.setBlock(i + 6, j + 12, k + 9, Blocks.MOSSY_COBBLESTONE.defaultBlockState());
//         world.setBlock(i + 6, j + 12, k + 10, Blocks.COBBLESTONE.defaultBlockState());
//         world.setBlock(i + 6, j + 12, k + 11, Blocks.COBBLESTONE.defaultBlockState());
//         world.setBlock(i + 6, j + 12, k + 12, Blocks.COBBLESTONE.defaultBlockState());
//         world.setBlock(i + 6, j + 12, k + 13, Blocks.COBBLESTONE.defaultBlockState());
//         world.setBlock(i + 6, j + 12, k + 14, Blocks.COBBLESTONE.defaultBlockState());
//         world.setBlock(i + 6, j + 12, k + 15, Blocks.GRASS.defaultBlockState());
//         world.setBlock(i + 6, j + 13, k + 4, Blocks.GRASS.defaultBlockState());
//         world.setBlock(i + 6, j + 13, k + 5, Blocks.GRASS.defaultBlockState());
//         world.setBlock(i + 6, j + 13, k + 6, Blocks.GRASS.defaultBlockState());
//         world.setBlock(i + 6, j + 13, k + 7, Blocks.GRASS.defaultBlockState());
//         world.setBlock(i + 6, j + 13, k + 8, Blocks.GRASS.defaultBlockState());
//         world.setBlock(i + 6, j + 13, k + 9, Blocks.GRASS.defaultBlockState());
//         world.setBlock(i + 6, j + 13, k + 10, Blocks.GRASS.defaultBlockState());
//         world.setBlock(i + 6, j + 13, k + 11, Blocks.GRASS.defaultBlockState());
//         world.setBlock(i + 6, j + 13, k + 12, Blocks.GRASS.defaultBlockState());
//         world.setBlock(i + 6, j + 13, k + 13, Blocks.GRASS.defaultBlockState());
//         world.setBlock(i + 6, j + 13, k + 14, Blocks.GRASS.defaultBlockState());
//         world.setBlock(i + 7, j, k + 6, Blocks.COBBLESTONE.defaultBlockState());
//         world.setBlock(i + 7, j, k + 7, Blocks.MOSSY_COBBLESTONE.defaultBlockState());
//         world.setBlock(i + 7, j, k + 8, Blocks.COBBLESTONE.defaultBlockState());
//         world.setBlock(i + 7, j, k + 9, Blocks.COBBLESTONE.defaultBlockState());
//         world.setBlock(i + 7, j, k + 10, Blocks.MOSSY_COBBLESTONE.defaultBlockState());
//         world.setBlock(i + 7, j, k + 11, Blocks.MOSSY_COBBLESTONE.defaultBlockState());
//         world.setBlock(i + 7, j, k + 12, Blocks.COBBLESTONE.defaultBlockState());
//         world.setBlock(i + 7, j + 1, k + 6, Blocks.MOSSY_COBBLESTONE.defaultBlockState());
//         world.setBlock(i + 7, j + 1, k + 12, Blocks.COBBLESTONE.defaultBlockState());
//         world.setBlock(i + 7, j + 2, k + 6, Blocks.COBBLESTONE.defaultBlockState());
//         world.setBlock(i + 7, j + 2, k + 12, Blocks.COBBLESTONE.defaultBlockState());
//         world.setBlock(i + 7, j + 3, k + 6, Blocks.COBBLESTONE.defaultBlockState());
//         world.setBlock(i + 7, j + 3, k + 12, Blocks.COBBLESTONE.defaultBlockState());
//         world.setBlock(i + 7, j + 4, k + 3, Blocks.COBBLESTONE.defaultBlockState());
//         world.setBlock(i + 7, j + 4, k + 4, Blocks.COBBLESTONE.defaultBlockState());
//         world.setBlock(i + 7, j + 4, k + 5, Blocks.COBBLESTONE.defaultBlockState());
//         world.setBlock(i + 7, j + 4, k + 6, stoneStair3);
//         world.setBlock(i + 7, j + 4, k + 12, stoneStair2);
//         world.setBlock(i + 7, j + 4, k + 13, Blocks.COBBLESTONE.defaultBlockState());
//         world.setBlock(i + 7, j + 4, k + 14, Blocks.COBBLESTONE.defaultBlockState());
//         world.setBlock(i + 7, j + 4, k + 15, Blocks.COBBLESTONE.defaultBlockState());
//         world.setBlock(i + 7, j + 5, k + 3, Blocks.COBBLESTONE.defaultBlockState());
//         world.setBlock(i + 7, j + 5, k + 15, Blocks.COBBLESTONE.defaultBlockState());
//         world.setBlock(i + 7, j + 6, k + 3, Blocks.COBBLESTONE.defaultBlockState());
//         world.setBlock(i + 7, j + 6, k + 15, Blocks.MOSSY_COBBLESTONE.defaultBlockState());
//         world.setBlock(i + 7, j + 7, k + 3, Blocks.COBBLESTONE.defaultBlockState());
//         world.setBlock(i + 7, j + 7, k + 15, Blocks.COBBLESTONE.defaultBlockState());
//         world.setBlock(i + 7, j + 8, k, Blocks.DIRT.defaultBlockState());
//         world.setBlock(i + 7, j + 8, k + 1, Blocks.DIRT.defaultBlockState());
//         world.setBlock(i + 7, j + 8, k + 2, Blocks.DIRT.defaultBlockState());
//         world.setBlock(i + 7, j + 8, k + 3, Blocks.COBBLESTONE.defaultBlockState());
//         world.setBlock(i + 7, j + 8, k + 4, Blocks.COBBLESTONE.defaultBlockState());
//         world.setBlock(i + 7, j + 8, k + 5, Blocks.COBBLESTONE.defaultBlockState());
//         world.setBlock(i + 7, j + 8, k + 6, stoneStair7);
//         world.setBlock(i + 7, j + 8, k + 12, stoneStair6);
//         world.setBlock(i + 7, j + 8, k + 13, Blocks.COBBLESTONE.defaultBlockState());
//         world.setBlock(i + 7, j + 8, k + 14, Blocks.MOSSY_COBBLESTONE.defaultBlockState());
//         world.setBlock(i + 7, j + 8, k + 15, Blocks.COBBLESTONE.defaultBlockState());
//         world.setBlock(i + 7, j + 8, k + 16, Blocks.DIRT.defaultBlockState());
//         world.setBlock(i + 7, j + 8, k + 17, Blocks.DIRT.defaultBlockState());
//         world.setBlock(i + 7, j + 8, k + 18, Blocks.DIRT.defaultBlockState());
//         world.setBlock(i + 7, j + 9, k, Blocks.GRASS.defaultBlockState());
//         world.setBlock(i + 7, j + 9, k + 1, Blocks.DIRT.defaultBlockState());
//         world.setBlock(i + 7, j + 9, k + 2, Blocks.DIRT.defaultBlockState());
//         world.setBlock(i + 7, j + 9, k + 3, Blocks.COBBLESTONE.defaultBlockState());
//         world.setBlock(i + 7, j + 9, k + 15, Blocks.COBBLESTONE.defaultBlockState());
//         world.setBlock(i + 7, j + 9, k + 16, Blocks.DIRT.defaultBlockState());
//         world.setBlock(i + 7, j + 9, k + 17, Blocks.DIRT.defaultBlockState());
//         world.setBlock(i + 7, j + 9, k + 18, Blocks.GRASS.defaultBlockState());
//         world.setBlock(i + 7, j + 10, k + 1, Blocks.DIRT.defaultBlockState());
//         world.setBlock(i + 7, j + 10, k + 2, Blocks.DIRT.defaultBlockState());
//         world.setBlock(i + 7, j + 10, k + 3, Blocks.COBBLESTONE.defaultBlockState());
//         world.setBlock(i + 7, j + 10, k + 15, Blocks.COBBLESTONE.defaultBlockState());
//         world.setBlock(i + 7, j + 10, k + 16, Blocks.DIRT.defaultBlockState());
//         world.setBlock(i + 7, j + 10, k + 17, Blocks.DIRT.defaultBlockState());
//         world.setBlock(i + 7, j + 11, k + 1, Blocks.GRASS.defaultBlockState());
//         world.setBlock(i + 7, j + 11, k + 2, Blocks.GRASS.defaultBlockState());
//         world.setBlock(i + 7, j + 11, k + 3, Blocks.MOSSY_COBBLESTONE.defaultBlockState());
//         world.setBlock(i + 7, j + 11, k + 6, stoneStair5);
//         world.setBlock(i + 7, j + 11, k + 12, stoneStair5);
//         world.setBlock(i + 7, j + 11, k + 15, Blocks.COBBLESTONE.defaultBlockState());
//         world.setBlock(i + 7, j + 11, k + 16, Blocks.GRASS.defaultBlockState());
//         world.setBlock(i + 7, j + 11, k + 17, Blocks.GRASS.defaultBlockState());
//         world.setBlock(i + 7, j + 12, k + 3, Blocks.GRASS.defaultBlockState());
//         world.setBlock(i + 7, j + 12, k + 4, Blocks.COBBLESTONE.defaultBlockState());
//         world.setBlock(i + 7, j + 12, k + 5, Blocks.COBBLESTONE.defaultBlockState());
//         world.setBlock(i + 7, j + 12, k + 6, Blocks.COBBLESTONE.defaultBlockState());
//         world.setBlock(i + 7, j + 12, k + 7, Blocks.COBBLESTONE.defaultBlockState());
//         world.setBlock(i + 7, j + 12, k + 8, Blocks.COBBLESTONE.defaultBlockState());
//         world.setBlock(i + 7, j + 12, k + 9, Blocks.MOSSY_COBBLESTONE.defaultBlockState());
//         world.setBlock(i + 7, j + 12, k + 10, Blocks.COBBLESTONE.defaultBlockState());
//         world.setBlock(i + 7, j + 12, k + 11, Blocks.COBBLESTONE.defaultBlockState());
//         world.setBlock(i + 7, j + 12, k + 12, Blocks.COBBLESTONE.defaultBlockState());
//         world.setBlock(i + 7, j + 12, k + 13, Blocks.COBBLESTONE.defaultBlockState());
//         world.setBlock(i + 7, j + 12, k + 14, Blocks.COBBLESTONE.defaultBlockState());
//         world.setBlock(i + 7, j + 12, k + 15, Blocks.GRASS.defaultBlockState());
//         world.setBlock(i + 7, j + 13, k + 4, Blocks.GRASS.defaultBlockState());
//         world.setBlock(i + 7, j + 13, k + 5, Blocks.GRASS.defaultBlockState());
//         world.setBlock(i + 7, j + 13, k + 6, Blocks.GRASS.defaultBlockState());
//         world.setBlock(i + 7, j + 13, k + 7, Blocks.DIRT.defaultBlockState());
//         world.setBlock(i + 7, j + 13, k + 8, Blocks.DIRT.defaultBlockState());
//         world.setBlock(i + 7, j + 13, k + 9, Blocks.DIRT.defaultBlockState());
//         world.setBlock(i + 7, j + 13, k + 10, Blocks.GRASS.defaultBlockState());
//         world.setBlock(i + 7, j + 13, k + 11, Blocks.GRASS.defaultBlockState());
//         world.setBlock(i + 7, j + 13, k + 12, Blocks.GRASS.defaultBlockState());
//         world.setBlock(i + 7, j + 13, k + 13, Blocks.GRASS.defaultBlockState());
//         world.setBlock(i + 7, j + 13, k + 14, Blocks.GRASS.defaultBlockState());
//         world.setBlock(i + 7, j + 14, k + 7, Blocks.GRASS.defaultBlockState());
//         world.setBlock(i + 7, j + 14, k + 8, Blocks.GRASS.defaultBlockState());
//         world.setBlock(i + 7, j + 14, k + 9, Blocks.GRASS.defaultBlockState());
//         world.setBlock(i + 8, j, k + 6, Blocks.COBBLESTONE.defaultBlockState());
//         world.setBlock(i + 8, j, k + 7, Blocks.COBBLESTONE.defaultBlockState());
//         world.setBlock(i + 8, j, k + 8, Blocks.COBBLESTONE.defaultBlockState());
//         world.setBlock(i + 8, j, k + 9, Blocks.COBBLESTONE.defaultBlockState());
//         world.setBlock(i + 8, j, k + 10, Blocks.COBBLESTONE.defaultBlockState());
//         world.setBlock(i + 8, j, k + 11, Blocks.COBBLESTONE.defaultBlockState());
//         world.setBlock(i + 8, j, k + 12, Blocks.COBBLESTONE.defaultBlockState());
//         world.setBlock(i + 8, j + 1, k + 6, Blocks.COBBLESTONE.defaultBlockState());
//         world.setBlock(i + 8, j + 1, k + 12, Blocks.MOSSY_COBBLESTONE.defaultBlockState());
//         world.setBlock(i + 8, j + 2, k + 6, Blocks.COBBLESTONE.defaultBlockState());
//         world.setBlock(i + 8, j + 2, k + 12, Blocks.COBBLESTONE.defaultBlockState());
//         world.setBlock(i + 8, j + 3, k + 6, Blocks.COBBLESTONE.defaultBlockState());
//         world.setBlock(i + 8, j + 3, k + 12, Blocks.COBBLESTONE.defaultBlockState());
//         world.setBlock(i + 8, j + 4, k + 3, Blocks.COBBLESTONE.defaultBlockState());
//         world.setBlock(i + 8, j + 4, k + 4, Blocks.COBBLESTONE.defaultBlockState());
//         world.setBlock(i + 8, j + 4, k + 5, Blocks.MOSSY_COBBLESTONE.defaultBlockState());
//         world.setBlock(i + 8, j + 4, k + 6, stoneStair3);
//         world.setBlock(i + 8, j + 4, k + 12, stoneStair2);
//         world.setBlock(i + 8, j + 4, k + 13, Blocks.COBBLESTONE.defaultBlockState());
//         world.setBlock(i + 8, j + 4, k + 14, Blocks.COBBLESTONE.defaultBlockState());
//         world.setBlock(i + 8, j + 4, k + 15, Blocks.COBBLESTONE.defaultBlockState());
//         world.setBlock(i + 8, j + 5, k + 3, Blocks.COBBLESTONE.defaultBlockState());
//         world.setBlock(i + 8, j + 5, k + 15, Blocks.COBBLESTONE.defaultBlockState());
//         world.setBlock(i + 8, j + 6, k + 3, Blocks.MOSSY_COBBLESTONE.defaultBlockState());
//         world.setBlock(i + 8, j + 6, k + 15, Blocks.COBBLESTONE.defaultBlockState());
//         world.setBlock(i + 8, j + 7, k + 3, Blocks.COBBLESTONE.defaultBlockState());
//         world.setBlock(i + 8, j + 7, k + 15, Blocks.COBBLESTONE.defaultBlockState());
//         world.setBlock(i + 8, j + 8, k, Blocks.DIRT.defaultBlockState());
//         world.setBlock(i + 8, j + 8, k + 1, Blocks.DIRT.defaultBlockState());
//         world.setBlock(i + 8, j + 8, k + 2, Blocks.DIRT.defaultBlockState());
//         world.setBlock(i + 8, j + 8, k + 3, Blocks.COBBLESTONE.defaultBlockState());
//         world.setBlock(i + 8, j + 8, k + 4, Blocks.COBBLESTONE.defaultBlockState());
//         world.setBlock(i + 8, j + 8, k + 5, Blocks.MOSSY_COBBLESTONE.defaultBlockState());
//         world.setBlock(i + 8, j + 8, k + 6, stoneStair7);
//         world.setBlock(i + 8, j + 8, k + 12, stoneStair6);
//         world.setBlock(i + 8, j + 8, k + 13, Blocks.COBBLESTONE.defaultBlockState());
//         world.setBlock(i + 8, j + 8, k + 14, Blocks.COBBLESTONE.defaultBlockState());
//         world.setBlock(i + 8, j + 8, k + 15, Blocks.COBBLESTONE.defaultBlockState());
//         world.setBlock(i + 8, j + 8, k + 16, Blocks.DIRT.defaultBlockState());
//         world.setBlock(i + 8, j + 8, k + 17, Blocks.DIRT.defaultBlockState());
//         world.setBlock(i + 8, j + 8, k + 18, Blocks.DIRT.defaultBlockState());
//         world.setBlock(i + 8, j + 9, k, Blocks.GRASS.defaultBlockState());
//         world.setBlock(i + 8, j + 9, k + 1, Blocks.DIRT.defaultBlockState());
//         world.setBlock(i + 8, j + 9, k + 2, Blocks.DIRT.defaultBlockState());
//         world.setBlock(i + 8, j + 9, k + 3, Blocks.COBBLESTONE.defaultBlockState());
//         world.setBlock(i + 8, j + 9, k + 15, Blocks.COBBLESTONE.defaultBlockState());
//         world.setBlock(i + 8, j + 9, k + 16, Blocks.DIRT.defaultBlockState());
//         world.setBlock(i + 8, j + 9, k + 17, Blocks.DIRT.defaultBlockState());
//         world.setBlock(i + 8, j + 9, k + 18, Blocks.GRASS.defaultBlockState());
//         world.setBlock(i + 8, j + 10, k + 1, Blocks.GRASS.defaultBlockState());
//         world.setBlock(i + 8, j + 10, k + 2, Blocks.DIRT.defaultBlockState());
//         world.setBlock(i + 8, j + 10, k + 3, Blocks.MOSSY_COBBLESTONE.defaultBlockState());
//         world.setBlock(i + 8, j + 10, k + 15, Blocks.MOSSY_COBBLESTONE.defaultBlockState());
//         world.setBlock(i + 8, j + 10, k + 16, Blocks.DIRT.defaultBlockState());
//         world.setBlock(i + 8, j + 10, k + 17, Blocks.DIRT.defaultBlockState());
//         world.setBlock(i + 8, j + 11, k + 2, Blocks.GRASS.defaultBlockState());
//         world.setBlock(i + 8, j + 11, k + 3, Blocks.COBBLESTONE.defaultBlockState());
//         world.setBlock(i + 8, j + 11, k + 15, Blocks.COBBLESTONE.defaultBlockState());
//         world.setBlock(i + 8, j + 11, k + 16, Blocks.GRASS.defaultBlockState());
//         world.setBlock(i + 8, j + 11, k + 17, Blocks.GRASS.defaultBlockState());
//         world.setBlock(i + 8, j + 12, k + 3, Blocks.GRASS.defaultBlockState());
//         world.setBlock(i + 8, j + 12, k + 4, Blocks.COBBLESTONE.defaultBlockState());
//         world.setBlock(i + 8, j + 12, k + 5, Blocks.COBBLESTONE.defaultBlockState());
//         world.setBlock(i + 8, j + 12, k + 6, Blocks.COBBLESTONE.defaultBlockState());
//         world.setBlock(i + 8, j + 12, k + 7, Blocks.MOSSY_COBBLESTONE.defaultBlockState());
//         world.setBlock(i + 8, j + 12, k + 8, Blocks.COBBLESTONE.defaultBlockState());
//         world.setBlock(i + 8, j + 12, k + 9, Blocks.COBBLESTONE.defaultBlockState());
//         world.setBlock(i + 8, j + 12, k + 10, Blocks.COBBLESTONE.defaultBlockState());
//         world.setBlock(i + 8, j + 12, k + 11, Blocks.COBBLESTONE.defaultBlockState());
//         world.setBlock(i + 8, j + 12, k + 12, Blocks.COBBLESTONE.defaultBlockState());
//         world.setBlock(i + 8, j + 12, k + 13, Blocks.COBBLESTONE.defaultBlockState());
//         world.setBlock(i + 8, j + 12, k + 14, Blocks.COBBLESTONE.defaultBlockState());
//         world.setBlock(i + 8, j + 12, k + 15, Blocks.GRASS.defaultBlockState());
//         world.setBlock(i + 8, j + 13, k + 4, Blocks.GRASS.defaultBlockState());
//         world.setBlock(i + 8, j + 13, k + 5, Blocks.GRASS.defaultBlockState());
//         world.setBlock(i + 8, j + 13, k + 6, Blocks.DIRT.defaultBlockState());
//         world.setBlock(i + 8, j + 13, k + 7, Blocks.DIRT.defaultBlockState());
//         world.setBlock(i + 8, j + 13, k + 8, Blocks.DIRT.defaultBlockState());
//         world.setBlock(i + 8, j + 13, k + 9, Blocks.DIRT.defaultBlockState());
//         world.setBlock(i + 8, j + 13, k + 10, Blocks.DIRT.defaultBlockState());
//         world.setBlock(i + 8, j + 13, k + 11, Blocks.GRASS.defaultBlockState());
//         world.setBlock(i + 8, j + 13, k + 12, Blocks.GRASS.defaultBlockState());
//         world.setBlock(i + 8, j + 13, k + 13, Blocks.GRASS.defaultBlockState());
//         world.setBlock(i + 8, j + 13, k + 14, Blocks.GRASS.defaultBlockState());
//         world.setBlock(i + 8, j + 14, k + 6, Blocks.GRASS.defaultBlockState());
//         world.setBlock(i + 8, j + 14, k + 7, Blocks.GRASS.defaultBlockState());
//         world.setBlock(i + 8, j + 14, k + 8, Blocks.GRASS.defaultBlockState());
//         world.setBlock(i + 8, j + 14, k + 9, Blocks.GRASS.defaultBlockState());
//         world.setBlock(i + 8, j + 14, k + 10, Blocks.GRASS.defaultBlockState());
//         world.setBlock(i + 9, j, k + 6, Blocks.COBBLESTONE.defaultBlockState());
//         world.setBlock(i + 9, j, k + 7, Blocks.COBBLESTONE.defaultBlockState());
//         world.setBlock(i + 9, j, k + 8, Blocks.MOSSY_COBBLESTONE.defaultBlockState());
//         world.setBlock(i + 9, j, k + 9, Blocks.COBBLESTONE.defaultBlockState());
//         world.setBlock(i + 9, j, k + 10, Blocks.MOSSY_COBBLESTONE.defaultBlockState());
//         world.setBlock(i + 9, j, k + 11, Blocks.MOSSY_COBBLESTONE.defaultBlockState());
//         world.setBlock(i + 9, j, k + 12, Blocks.COBBLESTONE.defaultBlockState());
//         world.setBlock(i + 9, j + 1, k + 6, Blocks.MOSSY_COBBLESTONE.defaultBlockState());
//         world.setBlock(i + 9, j + 1, k + 12, Blocks.MOSSY_COBBLESTONE.defaultBlockState());
//         world.setBlock(i + 9, j + 2, k + 6, Blocks.COBBLESTONE.defaultBlockState());
//         world.setBlock(i + 9, j + 2, k + 12, Blocks.COBBLESTONE.defaultBlockState());
//         world.setBlock(i + 9, j + 3, k + 6, Blocks.COBBLESTONE.defaultBlockState());
//         world.setBlock(i + 9, j + 3, k + 12, Blocks.MOSSY_COBBLESTONE.defaultBlockState());
//         world.setBlock(i + 9, j + 4, k + 3, Blocks.COBBLESTONE.defaultBlockState());
//         world.setBlock(i + 9, j + 4, k + 4, Blocks.COBBLESTONE.defaultBlockState());
//         world.setBlock(i + 9, j + 4, k + 5, Blocks.COBBLESTONE.defaultBlockState());
//         world.setBlock(i + 9, j + 4, k + 6, stoneStair3);
//         world.setBlock(i + 9, j + 4, k + 12, stoneStair2);
//         world.setBlock(i + 9, j + 4, k + 13, Blocks.COBBLESTONE.defaultBlockState());
//         world.setBlock(i + 9, j + 4, k + 14, Blocks.COBBLESTONE.defaultBlockState());
//         world.setBlock(i + 9, j + 4, k + 15, Blocks.COBBLESTONE.defaultBlockState());
//         world.setBlock(i + 9, j + 5, k + 3, Blocks.COBBLESTONE.defaultBlockState());
//         world.setBlock(i + 9, j + 5, k + 15, Blocks.COBBLESTONE.defaultBlockState());
//         world.setBlock(i + 9, j + 6, k + 3, Blocks.COBBLESTONE.defaultBlockState());
//         world.setBlock(i + 9, j + 6, k + 15, Blocks.COBBLESTONE.defaultBlockState());
//         world.setBlock(i + 9, j + 7, k + 3, Blocks.COBBLESTONE.defaultBlockState());
//         world.setBlock(i + 9, j + 7, k + 15, Blocks.COBBLESTONE.defaultBlockState());
//         world.setBlock(i + 9, j + 8, k, Blocks.DIRT.defaultBlockState());
//         world.setBlock(i + 9, j + 8, k + 1, Blocks.DIRT.defaultBlockState());
//         world.setBlock(i + 9, j + 8, k + 2, Blocks.DIRT.defaultBlockState());
//         world.setBlock(i + 9, j + 8, k + 3, Blocks.COBBLESTONE.defaultBlockState());
//         world.setBlock(i + 9, j + 8, k + 4, Blocks.COBBLESTONE.defaultBlockState());
//         world.setBlock(i + 9, j + 8, k + 5, Blocks.COBBLESTONE.defaultBlockState());
//         world.setBlock(i + 9, j + 8, k + 6, stoneStair7);
//         world.setBlock(i + 9, j + 8, k + 12, stoneStair6);
//         world.setBlock(i + 9, j + 8, k + 13, Blocks.MOSSY_COBBLESTONE.defaultBlockState());
//         world.setBlock(i + 9, j + 8, k + 14, Blocks.COBBLESTONE.defaultBlockState());
//         world.setBlock(i + 9, j + 8, k + 15, Blocks.COBBLESTONE.defaultBlockState());
//         world.setBlock(i + 9, j + 8, k + 16, Blocks.DIRT.defaultBlockState());
//         world.setBlock(i + 9, j + 8, k + 17, Blocks.DIRT.defaultBlockState());
//         world.setBlock(i + 9, j + 8, k + 18, Blocks.DIRT.defaultBlockState());
//         world.setBlock(i + 9, j + 9, k, Blocks.DIRT.defaultBlockState());
//         world.setBlock(i + 9, j + 9, k + 1, Blocks.DIRT.defaultBlockState());
//         world.setBlock(i + 9, j + 9, k + 2, Blocks.DIRT.defaultBlockState());
//         world.setBlock(i + 9, j + 9, k + 3, Blocks.COBBLESTONE.defaultBlockState());
//         world.setBlock(i + 9, j + 9, k + 15, Blocks.MOSSY_COBBLESTONE.defaultBlockState());
//         world.setBlock(i + 9, j + 9, k + 16, Blocks.DIRT.defaultBlockState());
//         world.setBlock(i + 9, j + 9, k + 17, Blocks.DIRT.defaultBlockState());
//         world.setBlock(i + 9, j + 9, k + 18, Blocks.GRASS.defaultBlockState());
//         world.setBlock(i + 9, j + 10, k, Blocks.GRASS.defaultBlockState());
//         world.setBlock(i + 9, j + 10, k + 1, Blocks.DIRT.defaultBlockState());
//         world.setBlock(i + 9, j + 10, k + 2, Blocks.DIRT.defaultBlockState());
//         world.setBlock(i + 9, j + 10, k + 3, Blocks.MOSSY_COBBLESTONE.defaultBlockState());
//         world.setBlock(i + 9, j + 10, k + 15, Blocks.MOSSY_COBBLESTONE.defaultBlockState());
//         world.setBlock(i + 9, j + 10, k + 16, Blocks.DIRT.defaultBlockState());
//         world.setBlock(i + 9, j + 10, k + 17, Blocks.GRASS.defaultBlockState());
//         world.setBlock(i + 9, j + 11, k + 1, Blocks.GRASS.defaultBlockState());
//         world.setBlock(i + 9, j + 11, k + 2, Blocks.DIRT.defaultBlockState());
//         world.setBlock(i + 9, j + 11, k + 3, Blocks.COBBLESTONE.defaultBlockState());
//         world.setBlock(i + 9, j + 11, k + 15, Blocks.COBBLESTONE.defaultBlockState());
//         world.setBlock(i + 9, j + 11, k + 16, Blocks.DIRT.defaultBlockState());
//         world.setBlock(i + 9, j + 12, k + 2, Blocks.GRASS.defaultBlockState());
//         world.setBlock(i + 9, j + 12, k + 3, Blocks.GRASS.defaultBlockState());
//         world.setBlock(i + 9, j + 12, k + 4, Blocks.COBBLESTONE.defaultBlockState());
//         world.setBlock(i + 9, j + 12, k + 5, Blocks.COBBLESTONE.defaultBlockState());
//         world.setBlock(i + 9, j + 12, k + 6, Blocks.COBBLESTONE.defaultBlockState());
//         world.setBlock(i + 9, j + 12, k + 7, Blocks.MOSSY_COBBLESTONE.defaultBlockState());
//         world.setBlock(i + 9, j + 12, k + 8, Blocks.COBBLESTONE.defaultBlockState());
//         world.setBlock(i + 9, j + 12, k + 9, Blocks.COBBLESTONE.defaultBlockState());
//         world.setBlock(i + 9, j + 12, k + 10, Blocks.COBBLESTONE.defaultBlockState());
//         world.setBlock(i + 9, j + 12, k + 11, Blocks.COBBLESTONE.defaultBlockState());
//         world.setBlock(i + 9, j + 12, k + 12, Blocks.COBBLESTONE.defaultBlockState());
//         world.setBlock(i + 9, j + 12, k + 13, Blocks.COBBLESTONE.defaultBlockState());
//         world.setBlock(i + 9, j + 12, k + 14, Blocks.COBBLESTONE.defaultBlockState());
//         world.setBlock(i + 9, j + 12, k + 15, Blocks.GRASS.defaultBlockState());
//         world.setBlock(i + 9, j + 12, k + 16, Blocks.GRASS.defaultBlockState());
//         world.setBlock(i + 9, j + 13, k + 4, Blocks.GRASS.defaultBlockState());
//         world.setBlock(i + 9, j + 13, k + 5, Blocks.GRASS.defaultBlockState());
//         world.setBlock(i + 9, j + 13, k + 6, Blocks.DIRT.defaultBlockState());
//         world.setBlock(i + 9, j + 13, k + 7, Blocks.DIRT.defaultBlockState());
//         world.setBlock(i + 9, j + 13, k + 8, Blocks.DIRT.defaultBlockState());
//         world.setBlock(i + 9, j + 13, k + 9, Blocks.DIRT.defaultBlockState());
//         world.setBlock(i + 9, j + 13, k + 10, Blocks.DIRT.defaultBlockState());
//         world.setBlock(i + 9, j + 13, k + 11, Blocks.DIRT.defaultBlockState());
//         world.setBlock(i + 9, j + 13, k + 12, Blocks.GRASS.defaultBlockState());
//         world.setBlock(i + 9, j + 13, k + 13, Blocks.GRASS.defaultBlockState());
//         world.setBlock(i + 9, j + 13, k + 14, Blocks.GRASS.defaultBlockState());
//         world.setBlock(i + 9, j + 14, k + 6, Blocks.GRASS.defaultBlockState());
//         world.setBlock(i + 9, j + 14, k + 7, Blocks.GRASS.defaultBlockState());
//         world.setBlock(i + 9, j + 14, k + 8, Blocks.GRASS.defaultBlockState());
//         world.setBlock(i + 9, j + 14, k + 9, Blocks.GRASS.defaultBlockState());
//         world.setBlock(i + 9, j + 14, k + 10, Blocks.GRASS.defaultBlockState());
//         world.setBlock(i + 9, j + 14, k + 11, Blocks.GRASS.defaultBlockState());
//         world.setBlock(i + 10, j, k + 6, Blocks.COBBLESTONE.defaultBlockState());
//         world.setBlock(i + 10, j, k + 7, Blocks.MOSSY_COBBLESTONE.defaultBlockState());
//         world.setBlock(i + 10, j, k + 8, Blocks.MOSSY_COBBLESTONE.defaultBlockState());
//         world.setBlock(i + 10, j, k + 9, Blocks.COBBLESTONE.defaultBlockState());
//         world.setBlock(i + 10, j, k + 10, Blocks.COBBLESTONE.defaultBlockState());
//         world.setBlock(i + 10, j, k + 11, Blocks.MOSSY_COBBLESTONE.defaultBlockState());
//         world.setBlock(i + 10, j, k + 12, Blocks.COBBLESTONE.defaultBlockState());
//         world.setBlock(i + 10, j + 1, k + 6, Blocks.COBBLESTONE.defaultBlockState());
//         world.setBlock(i + 10, j + 1, k + 12, Blocks.COBBLESTONE.defaultBlockState());
//         world.setBlock(i + 10, j + 2, k + 6, Blocks.COBBLESTONE.defaultBlockState());
//         world.setBlock(i + 10, j + 2, k + 12, Blocks.COBBLESTONE.defaultBlockState());
//         world.setBlock(i + 10, j + 3, k + 6, Blocks.COBBLESTONE.defaultBlockState());
//         world.setBlock(i + 10, j + 3, k + 12, Blocks.COBBLESTONE.defaultBlockState());
//         world.setBlock(i + 10, j + 4, k + 3, Blocks.COBBLESTONE.defaultBlockState());
//         world.setBlock(i + 10, j + 4, k + 4, Blocks.MOSSY_COBBLESTONE.defaultBlockState());
//         world.setBlock(i + 10, j + 4, k + 5, Blocks.COBBLESTONE.defaultBlockState());
//         world.setBlock(i + 10, j + 4, k + 6, stoneStair3);
//         world.setBlock(i + 10, j + 4, k + 12, stoneStair2);
//         world.setBlock(i + 10, j + 4, k + 13, Blocks.COBBLESTONE.defaultBlockState());
//         world.setBlock(i + 10, j + 4, k + 14, Blocks.COBBLESTONE.defaultBlockState());
//         world.setBlock(i + 10, j + 4, k + 15, Blocks.COBBLESTONE.defaultBlockState());
//         world.setBlock(i + 10, j + 5, k + 3, Blocks.COBBLESTONE.defaultBlockState());
//         world.setBlock(i + 10, j + 5, k + 15, Blocks.COBBLESTONE.defaultBlockState());
//         world.setBlock(i + 10, j + 6, k + 3, Blocks.COBBLESTONE.defaultBlockState());
//         world.setBlock(i + 10, j + 6, k + 15, Blocks.MOSSY_COBBLESTONE.defaultBlockState());
//         world.setBlock(i + 10, j + 7, k + 3, Blocks.COBBLESTONE.defaultBlockState());
//         world.setBlock(i + 10, j + 7, k + 15, Blocks.COBBLESTONE.defaultBlockState());
//         world.setBlock(i + 10, j + 8, k, Blocks.DIRT.defaultBlockState());
//         world.setBlock(i + 10, j + 8, k + 1, Blocks.DIRT.defaultBlockState());
//         world.setBlock(i + 10, j + 8, k + 2, Blocks.DIRT.defaultBlockState());
//         world.setBlock(i + 10, j + 8, k + 3, Blocks.COBBLESTONE.defaultBlockState());
//         world.setBlock(i + 10, j + 8, k + 4, Blocks.MOSSY_COBBLESTONE.defaultBlockState());
//         world.setBlock(i + 10, j + 8, k + 5, Blocks.COBBLESTONE.defaultBlockState());
//         world.setBlock(i + 10, j + 8, k + 6, stoneStair7);
//         world.setBlock(i + 10, j + 8, k + 12, stoneStair6);
//         world.setBlock(i + 10, j + 8, k + 13, Blocks.COBBLESTONE.defaultBlockState());
//         world.setBlock(i + 10, j + 8, k + 14, Blocks.COBBLESTONE.defaultBlockState());
//         world.setBlock(i + 10, j + 8, k + 15, Blocks.COBBLESTONE.defaultBlockState());
//         world.setBlock(i + 10, j + 8, k + 16, Blocks.DIRT.defaultBlockState());
//         world.setBlock(i + 10, j + 8, k + 17, Blocks.DIRT.defaultBlockState());
//         world.setBlock(i + 10, j + 8, k + 18, Blocks.DIRT.defaultBlockState());
//         world.setBlock(i + 10, j + 9, k, Blocks.DIRT.defaultBlockState());
//         world.setBlock(i + 10, j + 9, k + 1, Blocks.DIRT.defaultBlockState());
//         world.setBlock(i + 10, j + 9, k + 2, Blocks.DIRT.defaultBlockState());
//         world.setBlock(i + 10, j + 9, k + 3, Blocks.COBBLESTONE.defaultBlockState());
//         world.setBlock(i + 10, j + 9, k + 15, Blocks.COBBLESTONE.defaultBlockState());
//         world.setBlock(i + 10, j + 9, k + 16, Blocks.DIRT.defaultBlockState());
//         world.setBlock(i + 10, j + 9, k + 17, Blocks.DIRT.defaultBlockState());
//         world.setBlock(i + 10, j + 9, k + 18, Blocks.GRASS.defaultBlockState());
//         world.setBlock(i + 10, j + 10, k, Blocks.GRASS.defaultBlockState());
//         world.setBlock(i + 10, j + 10, k + 1, Blocks.DIRT.defaultBlockState());
//         world.setBlock(i + 10, j + 10, k + 2, Blocks.DIRT.defaultBlockState());
//         world.setBlock(i + 10, j + 10, k + 3, Blocks.COBBLESTONE.defaultBlockState());
//         world.setBlock(i + 10, j + 10, k + 15, Blocks.COBBLESTONE.defaultBlockState());
//         world.setBlock(i + 10, j + 10, k + 16, Blocks.DIRT.defaultBlockState());
//         world.setBlock(i + 10, j + 10, k + 17, Blocks.GRASS.defaultBlockState());
//         world.setBlock(i + 10, j + 11, k + 1, Blocks.GRASS.defaultBlockState());
//         world.setBlock(i + 10, j + 11, k + 2, Blocks.GRASS.defaultBlockState());
//         world.setBlock(i + 10, j + 11, k + 3, Blocks.COBBLESTONE.defaultBlockState());
//         world.setBlock(i + 10, j + 11, k + 6, stoneStair4);
//         world.setBlock(i + 10, j + 11, k + 12, stoneStair4);
//         world.setBlock(i + 10, j + 11, k + 15, Blocks.COBBLESTONE.defaultBlockState());
//         world.setBlock(i + 10, j + 11, k + 16, Blocks.DIRT.defaultBlockState());
//         world.setBlock(i + 10, j + 12, k + 3, Blocks.GRASS.defaultBlockState());
//         world.setBlock(i + 10, j + 12, k + 4, Blocks.COBBLESTONE.defaultBlockState());
//         world.setBlock(i + 10, j + 12, k + 5, Blocks.COBBLESTONE.defaultBlockState());
//         world.setBlock(i + 10, j + 12, k + 6, Blocks.COBBLESTONE.defaultBlockState());
//         world.setBlock(i + 10, j + 12, k + 7, Blocks.COBBLESTONE.defaultBlockState());
//         world.setBlock(i + 10, j + 12, k + 8, Blocks.COBBLESTONE.defaultBlockState());
//         world.setBlock(i + 10, j + 12, k + 9, Blocks.MOSSY_COBBLESTONE.defaultBlockState());
//         world.setBlock(i + 10, j + 12, k + 10, Blocks.COBBLESTONE.defaultBlockState());
//         world.setBlock(i + 10, j + 12, k + 11, Blocks.COBBLESTONE.defaultBlockState());
//         world.setBlock(i + 10, j + 12, k + 12, Blocks.MOSSY_COBBLESTONE.defaultBlockState());
//         world.setBlock(i + 10, j + 12, k + 13, Blocks.COBBLESTONE.defaultBlockState());
//         world.setBlock(i + 10, j + 12, k + 14, Blocks.COBBLESTONE.defaultBlockState());
//         world.setBlock(i + 10, j + 12, k + 15, Blocks.GRASS.defaultBlockState());
//         world.setBlock(i + 10, j + 12, k + 16, Blocks.GRASS.defaultBlockState());
//         world.setBlock(i + 10, j + 13, k + 4, Blocks.GRASS.defaultBlockState());
//         world.setBlock(i + 10, j + 13, k + 5, Blocks.DIRT.defaultBlockState());
//         world.setBlock(i + 10, j + 13, k + 6, Blocks.DIRT.defaultBlockState());
//         world.setBlock(i + 10, j + 13, k + 7, Blocks.GRASS.defaultBlockState());
//         world.setBlock(i + 10, j + 13, k + 8, Blocks.DIRT.defaultBlockState());
//         world.setBlock(i + 10, j + 13, k + 9, Blocks.DIRT.defaultBlockState());
//         world.setBlock(i + 10, j + 13, k + 10, Blocks.DIRT.defaultBlockState());
//         world.setBlock(i + 10, j + 13, k + 11, Blocks.DIRT.defaultBlockState());
//         world.setBlock(i + 10, j + 13, k + 12, Blocks.GRASS.defaultBlockState());
//         world.setBlock(i + 10, j + 13, k + 13, Blocks.GRASS.defaultBlockState());
//         world.setBlock(i + 10, j + 13, k + 14, Blocks.GRASS.defaultBlockState());
//         world.setBlock(i + 10, j + 14, k + 5, Blocks.GRASS.defaultBlockState());
//         world.setBlock(i + 10, j + 14, k + 6, Blocks.GRASS.defaultBlockState());
//         world.setBlock(i + 10, j + 14, k + 8, Blocks.GRASS.defaultBlockState());
//         world.setBlock(i + 10, j + 14, k + 9, Blocks.GRASS.defaultBlockState());
//         world.setBlock(i + 10, j + 14, k + 10, Blocks.GRASS.defaultBlockState());
//         world.setBlock(i + 10, j + 14, k + 11, Blocks.GRASS.defaultBlockState());
//         world.setBlock(i + 11, j, k + 6, Blocks.COBBLESTONE.defaultBlockState());
//         world.setBlock(i + 11, j, k + 7, Blocks.COBBLESTONE.defaultBlockState());
//         world.setBlock(i + 11, j, k + 8, Blocks.COBBLESTONE.defaultBlockState());
//         world.setBlock(i + 11, j, k + 9, Blocks.COBBLESTONE.defaultBlockState());
//         world.setBlock(i + 11, j, k + 10, Blocks.MOSSY_COBBLESTONE.defaultBlockState());
//         world.setBlock(i + 11, j, k + 11, Blocks.COBBLESTONE.defaultBlockState());
//         world.setBlock(i + 11, j, k + 12, Blocks.COBBLESTONE.defaultBlockState());
//         world.setBlock(i + 11, j + 1, k + 6, Blocks.COBBLESTONE.defaultBlockState());
//         world.setBlock(i + 11, j + 1, k + 7, Blocks.COBBLESTONE.defaultBlockState());
//         world.setBlock(i + 11, j + 1, k + 8, Blocks.COBBLESTONE.defaultBlockState());
//         world.setBlock(i + 11, j + 1, k + 9, Blocks.COBBLESTONE.defaultBlockState());
//         world.setBlock(i + 11, j + 1, k + 10, Blocks.COBBLESTONE.defaultBlockState());
//         world.setBlock(i + 11, j + 1, k + 11, Blocks.COBBLESTONE.defaultBlockState());
//         world.setBlock(i + 11, j + 1, k + 12, Blocks.COBBLESTONE.defaultBlockState());
//         world.setBlock(i + 11, j + 2, k + 6, Blocks.COBBLESTONE.defaultBlockState());
//         world.setBlock(i + 11, j + 2, k + 7, Blocks.COBBLESTONE.defaultBlockState());
//         world.setBlock(i + 11, j + 2, k + 8, Blocks.COBBLESTONE.defaultBlockState());
//         world.setBlock(i + 11, j + 2, k + 9, Blocks.COBBLESTONE.defaultBlockState());
//         world.setBlock(i + 11, j + 2, k + 10, Blocks.MOSSY_COBBLESTONE.defaultBlockState());
//         world.setBlock(i + 11, j + 2, k + 11, Blocks.COBBLESTONE.defaultBlockState());
//         world.setBlock(i + 11, j + 2, k + 12, Blocks.COBBLESTONE.defaultBlockState());
//         world.setBlock(i + 11, j + 3, k + 6, Blocks.COBBLESTONE.defaultBlockState());
//         world.setBlock(i + 11, j + 3, k + 7, Blocks.COBBLESTONE.defaultBlockState());
//         world.setBlock(i + 11, j + 3, k + 8, Blocks.COBBLESTONE.defaultBlockState());
//         world.setBlock(i + 11, j + 3, k + 9, Blocks.MOSSY_COBBLESTONE.defaultBlockState());
//         world.setBlock(i + 11, j + 3, k + 10, Blocks.COBBLESTONE.defaultBlockState());
//         world.setBlock(i + 11, j + 3, k + 11, Blocks.COBBLESTONE.defaultBlockState());
//         world.setBlock(i + 11, j + 3, k + 12, Blocks.COBBLESTONE.defaultBlockState());
//         world.setBlock(i + 11, j + 4, k + 3, Blocks.COBBLESTONE.defaultBlockState());
//         world.setBlock(i + 11, j + 4, k + 4, Blocks.COBBLESTONE.defaultBlockState());
//         world.setBlock(i + 11, j + 4, k + 5, Blocks.COBBLESTONE.defaultBlockState());
//         world.setBlock(i + 11, j + 4, k + 6, Blocks.COBBLESTONE.defaultBlockState());
//         world.setBlock(i + 11, j + 4, k + 7, Blocks.STONE_STAIRS.defaultBlockState());
//         world.setBlock(i + 11, j + 4, k + 8, Blocks.STONE_STAIRS.defaultBlockState());
//         world.setBlock(i + 11, j + 4, k + 9, Blocks.STONE_STAIRS.defaultBlockState());
//         world.setBlock(i + 11, j + 4, k + 10, Blocks.STONE_STAIRS.defaultBlockState());
//         world.setBlock(i + 11, j + 4, k + 11, Blocks.STONE_STAIRS.defaultBlockState());
//         world.setBlock(i + 11, j + 4, k + 12, Blocks.COBBLESTONE.defaultBlockState());
//         world.setBlock(i + 11, j + 4, k + 13, Blocks.COBBLESTONE.defaultBlockState());
//         world.setBlock(i + 11, j + 4, k + 14, Blocks.COBBLESTONE.defaultBlockState());
//         world.setBlock(i + 11, j + 4, k + 15, Blocks.COBBLESTONE.defaultBlockState());
//         world.setBlock(i + 11, j + 5, k + 3, Blocks.COBBLESTONE.defaultBlockState());
//         world.setBlock(i + 11, j + 5, k + 6, Blocks.COBBLESTONE.defaultBlockState());
//         world.setBlock(i + 11, j + 5, k + 12, Blocks.COBBLESTONE.defaultBlockState());
//         world.setBlock(i + 11, j + 5, k + 15, Blocks.COBBLESTONE.defaultBlockState());
//         world.setBlock(i + 11, j + 6, k + 3, Blocks.MOSSY_COBBLESTONE.defaultBlockState());
//         world.setBlock(i + 11, j + 6, k + 6, Blocks.MOSSY_COBBLESTONE.defaultBlockState());
//         world.setBlock(i + 11, j + 6, k + 12, Blocks.COBBLESTONE.defaultBlockState());
//         world.setBlock(i + 11, j + 6, k + 15, Blocks.COBBLESTONE.defaultBlockState());
//         world.setBlock(i + 11, j + 7, k + 3, Blocks.COBBLESTONE.defaultBlockState());
//         world.setBlock(i + 11, j + 7, k + 6, Blocks.COBBLESTONE.defaultBlockState());
//         world.setBlock(i + 11, j + 7, k + 12, Blocks.MOSSY_COBBLESTONE.defaultBlockState());
//         world.setBlock(i + 11, j + 7, k + 15, Blocks.COBBLESTONE.defaultBlockState());
//         world.setBlock(i + 11, j + 8, k, Blocks.DIRT.defaultBlockState());
//         world.setBlock(i + 11, j + 8, k + 1, Blocks.DIRT.defaultBlockState());
//         world.setBlock(i + 11, j + 8, k + 2, Blocks.DIRT.defaultBlockState());
//         world.setBlock(i + 11, j + 8, k + 3, Blocks.COBBLESTONE.defaultBlockState());
//         world.setBlock(i + 11, j + 8, k + 4, Blocks.COBBLESTONE.defaultBlockState());
//         world.setBlock(i + 11, j + 8, k + 5, Blocks.COBBLESTONE.defaultBlockState());
//         world.setBlock(i + 11, j + 8, k + 6, Blocks.COBBLESTONE.defaultBlockState());
//         world.setBlock(i + 11, j + 8, k + 7, stoneStair4);
//         world.setBlock(i + 11, j + 8, k + 8, stoneStair4);
//         world.setBlock(i + 11, j + 8, k + 9, stoneStair4);
//         world.setBlock(i + 11, j + 8, k + 10, stoneStair4);
//         world.setBlock(i + 11, j + 8, k + 11, stoneStair4);
//         world.setBlock(i + 11, j + 8, k + 12, Blocks.COBBLESTONE.defaultBlockState());
//         world.setBlock(i + 11, j + 8, k + 13, Blocks.COBBLESTONE.defaultBlockState());
//         world.setBlock(i + 11, j + 8, k + 14, Blocks.COBBLESTONE.defaultBlockState());
//         world.setBlock(i + 11, j + 8, k + 15, Blocks.COBBLESTONE.defaultBlockState());
//         world.setBlock(i + 11, j + 8, k + 16, Blocks.DIRT.defaultBlockState());
//         world.setBlock(i + 11, j + 8, k + 17, Blocks.DIRT.defaultBlockState());
//         world.setBlock(i + 11, j + 8, k + 18, Blocks.DIRT.defaultBlockState());
//         world.setBlock(i + 11, j + 9, k, Blocks.GRASS.defaultBlockState());
//         world.setBlock(i + 11, j + 9, k + 1, Blocks.DIRT.defaultBlockState());
//         world.setBlock(i + 11, j + 9, k + 2, Blocks.DIRT.defaultBlockState());
//         world.setBlock(i + 11, j + 9, k + 3, Blocks.COBBLESTONE.defaultBlockState());
//         world.setBlock(i + 11, j + 9, k + 6, Blocks.COBBLESTONE.defaultBlockState());
//         world.setBlock(i + 11, j + 9, k + 12, Blocks.MOSSY_COBBLESTONE.defaultBlockState());
//         world.setBlock(i + 11, j + 9, k + 15, Blocks.COBBLESTONE.defaultBlockState());
//         world.setBlock(i + 11, j + 9, k + 16, Blocks.DIRT.defaultBlockState());
//         world.setBlock(i + 11, j + 9, k + 17, Blocks.DIRT.defaultBlockState());
//         world.setBlock(i + 11, j + 9, k + 18, Blocks.GRASS.defaultBlockState());
//         world.setBlock(i + 11, j + 10, k + 1, Blocks.DIRT.defaultBlockState());
//         world.setBlock(i + 11, j + 10, k + 2, Blocks.DIRT.defaultBlockState());
//         world.setBlock(i + 11, j + 10, k + 3, Blocks.COBBLESTONE.defaultBlockState());
//         world.setBlock(i + 11, j + 10, k + 6, Blocks.COBBLESTONE.defaultBlockState());
//         world.setBlock(i + 11, j + 10, k + 12, Blocks.MOSSY_COBBLESTONE.defaultBlockState());
//         world.setBlock(i + 11, j + 10, k + 15, Blocks.MOSSY_COBBLESTONE.defaultBlockState());
//         world.setBlock(i + 11, j + 10, k + 16, Blocks.DIRT.defaultBlockState());
//         world.setBlock(i + 11, j + 10, k + 17, Blocks.DIRT.defaultBlockState());
//         world.setBlock(i + 11, j + 11, k + 1, Blocks.GRASS.defaultBlockState());
//         world.setBlock(i + 11, j + 11, k + 2, Blocks.GRASS.defaultBlockState());
//         world.setBlock(i + 11, j + 11, k + 3, Blocks.MOSSY_COBBLESTONE.defaultBlockState());
//         world.setBlock(i + 11, j + 11, k + 5, stoneStair6);
//         world.setBlock(i + 11, j + 11, k + 6, Blocks.COBBLESTONE.defaultBlockState());
//         world.setBlock(i + 11, j + 11, k + 7, stoneStair7);
//         world.setBlock(i + 11, j + 11, k + 11, stoneStair6);
//         world.setBlock(i + 11, j + 11, k + 12, Blocks.COBBLESTONE.defaultBlockState());
//         world.setBlock(i + 11, j + 11, k + 13, stoneStair7);
//         world.setBlock(i + 11, j + 11, k + 15, Blocks.COBBLESTONE.defaultBlockState());
//         world.setBlock(i + 11, j + 11, k + 16, Blocks.GRASS.defaultBlockState());
//         world.setBlock(i + 11, j + 11, k + 17, Blocks.GRASS.defaultBlockState());
//         world.setBlock(i + 11, j + 12, k + 3, Blocks.GRASS.defaultBlockState());
//         world.setBlock(i + 11, j + 12, k + 4, Blocks.COBBLESTONE.defaultBlockState());
//         world.setBlock(i + 11, j + 12, k + 5, Blocks.COBBLESTONE.defaultBlockState());
//         world.setBlock(i + 11, j + 12, k + 6, Blocks.COBBLESTONE.defaultBlockState());
//         world.setBlock(i + 11, j + 12, k + 7, Blocks.COBBLESTONE.defaultBlockState());
//         world.setBlock(i + 11, j + 12, k + 8, Blocks.COBBLESTONE.defaultBlockState());
//         world.setBlock(i + 11, j + 12, k + 9, Blocks.COBBLESTONE.defaultBlockState());
//         world.setBlock(i + 11, j + 12, k + 10, Blocks.COBBLESTONE.defaultBlockState());
//         world.setBlock(i + 11, j + 12, k + 11, Blocks.COBBLESTONE.defaultBlockState());
//         world.setBlock(i + 11, j + 12, k + 12, Blocks.COBBLESTONE.defaultBlockState());
//         world.setBlock(i + 11, j + 12, k + 13, Blocks.COBBLESTONE.defaultBlockState());
//         world.setBlock(i + 11, j + 12, k + 14, Blocks.COBBLESTONE.defaultBlockState());
//         world.setBlock(i + 11, j + 12, k + 15, Blocks.GRASS.defaultBlockState());
//         world.setBlock(i + 11, j + 13, k + 4, Blocks.GRASS.defaultBlockState());
//         world.setBlock(i + 11, j + 13, k + 5, Blocks.GRASS.defaultBlockState());
//         world.setBlock(i + 11, j + 13, k + 6, Blocks.DIRT.defaultBlockState());
//         world.setBlock(i + 11, j + 13, k + 7, Blocks.DIRT.defaultBlockState());
//         world.setBlock(i + 11, j + 13, k + 8, Blocks.DIRT.defaultBlockState());
//         world.setBlock(i + 11, j + 13, k + 9, Blocks.DIRT.defaultBlockState());
//         world.setBlock(i + 11, j + 13, k + 10, Blocks.DIRT.defaultBlockState());
//         world.setBlock(i + 11, j + 13, k + 11, Blocks.GRASS.defaultBlockState());
//         world.setBlock(i + 11, j + 13, k + 12, Blocks.GRASS.defaultBlockState());
//         world.setBlock(i + 11, j + 13, k + 13, Blocks.GRASS.defaultBlockState());
//         world.setBlock(i + 11, j + 13, k + 14, Blocks.GRASS.defaultBlockState());
//         world.setBlock(i + 11, j + 14, k + 6, Blocks.GRASS.defaultBlockState());
//         world.setBlock(i + 11, j + 14, k + 7, Blocks.GRASS.defaultBlockState());
//         world.setBlock(i + 11, j + 14, k + 8, Blocks.GRASS.defaultBlockState());
//         world.setBlock(i + 11, j + 14, k + 9, Blocks.GRASS.defaultBlockState());
//         world.setBlock(i + 11, j + 14, k + 10, Blocks.GRASS.defaultBlockState());
//         world.setBlock(i + 12, j, k + 6, Blocks.COBBLESTONE.defaultBlockState());
//         world.setBlock(i + 12, j, k + 7, Blocks.COBBLESTONE.defaultBlockState());
//         world.setBlock(i + 12, j, k + 8, Blocks.COBBLESTONE.defaultBlockState());
//         world.setBlock(i + 12, j, k + 9, Blocks.COBBLESTONE.defaultBlockState());
//         world.setBlock(i + 12, j, k + 10, Blocks.COBBLESTONE.defaultBlockState());
//         world.setBlock(i + 12, j, k + 11, Blocks.COBBLESTONE.defaultBlockState());
//         world.setBlock(i + 12, j, k + 12, Blocks.COBBLESTONE.defaultBlockState());
//         world.setBlock(i + 12, j + 1, k + 6, Blocks.MOSSY_COBBLESTONE.defaultBlockState());
//         world.setBlock(i + 12, j + 1, k + 7, Blocks.COBBLESTONE.defaultBlockState());
//         world.setBlock(i + 12, j + 1, k + 8, Blocks.COBBLESTONE.defaultBlockState());
//         world.setBlock(i + 12, j + 1, k + 9, Blocks.MOSSY_COBBLESTONE.defaultBlockState());
//         world.setBlock(i + 12, j + 1, k + 10, Blocks.COBBLESTONE.defaultBlockState());
//         world.setBlock(i + 12, j + 1, k + 11, Blocks.MOSSY_COBBLESTONE.defaultBlockState());
//         world.setBlock(i + 12, j + 1, k + 12, Blocks.MOSSY_COBBLESTONE.defaultBlockState());
//         world.setBlock(i + 12, j + 2, k + 6, Blocks.COBBLESTONE.defaultBlockState());
//         world.setBlock(i + 12, j + 2, k + 7, Blocks.COBBLESTONE.defaultBlockState());
//         world.setBlock(i + 12, j + 2, k + 8, Blocks.COBBLESTONE.defaultBlockState());
//         world.setBlock(i + 12, j + 2, k + 9, Blocks.COBBLESTONE.defaultBlockState());
//         world.setBlock(i + 12, j + 2, k + 10, Blocks.COBBLESTONE.defaultBlockState());
//         world.setBlock(i + 12, j + 2, k + 11, Blocks.COBBLESTONE.defaultBlockState());
//         world.setBlock(i + 12, j + 2, k + 12, Blocks.COBBLESTONE.defaultBlockState());
//         world.setBlock(i + 12, j + 3, k + 6, Blocks.COBBLESTONE.defaultBlockState());
//         world.setBlock(i + 12, j + 3, k + 7, Blocks.COBBLESTONE.defaultBlockState());
//         world.setBlock(i + 12, j + 3, k + 8, Blocks.COBBLESTONE.defaultBlockState());
//         world.setBlock(i + 12, j + 3, k + 9, Blocks.COBBLESTONE.defaultBlockState());
//         world.setBlock(i + 12, j + 3, k + 10, Blocks.COBBLESTONE.defaultBlockState());
//         world.setBlock(i + 12, j + 3, k + 11, Blocks.COBBLESTONE.defaultBlockState());
//         world.setBlock(i + 12, j + 3, k + 12, Blocks.COBBLESTONE.defaultBlockState());
//         world.setBlock(i + 12, j + 4, k + 3, Blocks.COBBLESTONE.defaultBlockState());
//         world.setBlock(i + 12, j + 4, k + 4, Blocks.COBBLESTONE.defaultBlockState());
//         world.setBlock(i + 12, j + 4, k + 5, Blocks.COBBLESTONE.defaultBlockState());
//         world.setBlock(i + 12, j + 4, k + 6, Blocks.COBBLESTONE.defaultBlockState());
//         world.setBlock(i + 12, j + 4, k + 7, Blocks.COBBLESTONE.defaultBlockState());
//         world.setBlock(i + 12, j + 4, k + 8, Blocks.MOSSY_COBBLESTONE.defaultBlockState());
//         world.setBlock(i + 12, j + 4, k + 9, Blocks.COBBLESTONE.defaultBlockState());
//         world.setBlock(i + 12, j + 4, k + 10, Blocks.COBBLESTONE.defaultBlockState());
//         world.setBlock(i + 12, j + 4, k + 11, Blocks.COBBLESTONE.defaultBlockState());
//         world.setBlock(i + 12, j + 4, k + 12, Blocks.COBBLESTONE.defaultBlockState());
//         world.setBlock(i + 12, j + 4, k + 13, Blocks.MOSSY_COBBLESTONE.defaultBlockState());
//         world.setBlock(i + 12, j + 4, k + 14, Blocks.COBBLESTONE.defaultBlockState());
//         world.setBlock(i + 12, j + 4, k + 15, Blocks.COBBLESTONE.defaultBlockState());
//         world.setBlock(i + 12, j + 5, k + 3, Blocks.COBBLESTONE.defaultBlockState());
//         world.setBlock(i + 12, j + 5, k + 15, Blocks.COBBLESTONE.defaultBlockState());
//         world.setBlock(i + 12, j + 6, k + 3, Blocks.COBBLESTONE.defaultBlockState());
//         world.setBlock(i + 12, j + 6, k + 15, Blocks.COBBLESTONE.defaultBlockState());
//         world.setBlock(i + 12, j + 7, k + 3, Blocks.COBBLESTONE.defaultBlockState());
//         world.setBlock(i + 12, j + 7, k + 15, Blocks.COBBLESTONE.defaultBlockState());
//         world.setBlock(i + 12, j + 8, k, Blocks.DIRT.defaultBlockState());
//         world.setBlock(i + 12, j + 8, k + 1, Blocks.DIRT.defaultBlockState());
//         world.setBlock(i + 12, j + 8, k + 2, Blocks.DIRT.defaultBlockState());
//         world.setBlock(i + 12, j + 8, k + 3, Blocks.COBBLESTONE.defaultBlockState());
//         world.setBlock(i + 12, j + 8, k + 4, Blocks.MOSSY_COBBLESTONE.defaultBlockState());
//         world.setBlock(i + 12, j + 8, k + 5, Blocks.COBBLESTONE.defaultBlockState());
//         world.setBlock(i + 12, j + 8, k + 6, Blocks.COBBLESTONE.defaultBlockState());
//         world.setBlock(i + 12, j + 8, k + 7, Blocks.MOSSY_COBBLESTONE.defaultBlockState());
//         world.setBlock(i + 12, j + 8, k + 8, Blocks.MOSSY_COBBLESTONE.defaultBlockState());
//         world.setBlock(i + 12, j + 8, k + 9, Blocks.COBBLESTONE.defaultBlockState());
//         world.setBlock(i + 12, j + 8, k + 10, Blocks.COBBLESTONE.defaultBlockState());
//         world.setBlock(i + 12, j + 8, k + 11, Blocks.COBBLESTONE.defaultBlockState());
//         world.setBlock(i + 12, j + 8, k + 12, Blocks.COBBLESTONE.defaultBlockState());
//         world.setBlock(i + 12, j + 8, k + 13, Blocks.COBBLESTONE.defaultBlockState());
//         world.setBlock(i + 12, j + 8, k + 14, Blocks.MOSSY_COBBLESTONE.defaultBlockState());
//         world.setBlock(i + 12, j + 8, k + 15, Blocks.COBBLESTONE.defaultBlockState());
//         world.setBlock(i + 12, j + 8, k + 16, Blocks.DIRT.defaultBlockState());
//         world.setBlock(i + 12, j + 8, k + 17, Blocks.DIRT.defaultBlockState());
//         world.setBlock(i + 12, j + 8, k + 18, Blocks.DIRT.defaultBlockState());
//         world.setBlock(i + 12, j + 9, k, Blocks.GRASS.defaultBlockState());
//         world.setBlock(i + 12, j + 9, k + 1, Blocks.DIRT.defaultBlockState());
//         world.setBlock(i + 12, j + 9, k + 2, Blocks.DIRT.defaultBlockState());
//         world.setBlock(i + 12, j + 9, k + 3, Blocks.COBBLESTONE.defaultBlockState());
//         world.setBlock(i + 12, j + 9, k + 15, Blocks.COBBLESTONE.defaultBlockState());
//         world.setBlock(i + 12, j + 9, k + 16, Blocks.DIRT.defaultBlockState());
//         world.setBlock(i + 12, j + 9, k + 17, Blocks.DIRT.defaultBlockState());
//         world.setBlock(i + 12, j + 9, k + 18, Blocks.GRASS.defaultBlockState());
//         world.setBlock(i + 12, j + 10, k + 1, Blocks.GRASS.defaultBlockState());
//         world.setBlock(i + 12, j + 10, k + 2, Blocks.DIRT.defaultBlockState());
//         world.setBlock(i + 12, j + 10, k + 3, Blocks.COBBLESTONE.defaultBlockState());
//         world.setBlock(i + 12, j + 10, k + 15, Blocks.COBBLESTONE.defaultBlockState());
//         world.setBlock(i + 12, j + 10, k + 16, Blocks.DIRT.defaultBlockState());
//         world.setBlock(i + 12, j + 10, k + 17, Blocks.DIRT.defaultBlockState());
//         world.setBlock(i + 12, j + 11, k + 2, Blocks.DIRT.defaultBlockState());
//         world.setBlock(i + 12, j + 11, k + 3, Blocks.COBBLESTONE.defaultBlockState());
//         world.setBlock(i + 12, j + 11, k + 6, stoneStair5);
//         world.setBlock(i + 12, j + 11, k + 12, stoneStair5);
//         world.setBlock(i + 12, j + 11, k + 15, Blocks.COBBLESTONE.defaultBlockState());
//         world.setBlock(i + 12, j + 11, k + 16, Blocks.GRASS.defaultBlockState());
//         world.setBlock(i + 12, j + 11, k + 17, Blocks.GRASS.defaultBlockState());
//         world.setBlock(i + 12, j + 12, k + 2, Blocks.GRASS.defaultBlockState());
//         world.setBlock(i + 12, j + 12, k + 3, Blocks.GRASS.defaultBlockState());
//         world.setBlock(i + 12, j + 12, k + 4, Blocks.COBBLESTONE.defaultBlockState());
//         world.setBlock(i + 12, j + 12, k + 5, Blocks.COBBLESTONE.defaultBlockState());
//         world.setBlock(i + 12, j + 12, k + 6, Blocks.MOSSY_COBBLESTONE.defaultBlockState());
//         world.setBlock(i + 12, j + 12, k + 7, Blocks.COBBLESTONE.defaultBlockState());
//         world.setBlock(i + 12, j + 12, k + 8, Blocks.COBBLESTONE.defaultBlockState());
//         world.setBlock(i + 12, j + 12, k + 9, Blocks.COBBLESTONE.defaultBlockState());
//         world.setBlock(i + 12, j + 12, k + 10, Blocks.COBBLESTONE.defaultBlockState());
//         world.setBlock(i + 12, j + 12, k + 11, Blocks.MOSSY_COBBLESTONE.defaultBlockState());
//         world.setBlock(i + 12, j + 12, k + 12, Blocks.COBBLESTONE.defaultBlockState());
//         world.setBlock(i + 12, j + 12, k + 13, Blocks.COBBLESTONE.defaultBlockState());
//         world.setBlock(i + 12, j + 12, k + 14, Blocks.COBBLESTONE.defaultBlockState());
//         world.setBlock(i + 12, j + 12, k + 15, Blocks.GRASS.defaultBlockState());
//         world.setBlock(i + 12, j + 13, k + 4, Blocks.GRASS.defaultBlockState());
//         world.setBlock(i + 12, j + 13, k + 5, Blocks.GRASS.defaultBlockState());
//         world.setBlock(i + 12, j + 13, k + 6, Blocks.GRASS.defaultBlockState());
//         world.setBlock(i + 12, j + 13, k + 7, Blocks.DIRT.defaultBlockState());
//         world.setBlock(i + 12, j + 13, k + 8, Blocks.DIRT.defaultBlockState());
//         world.setBlock(i + 12, j + 13, k + 9, Blocks.GRASS.defaultBlockState());
