package thaumcraft.common.lib.world.structure;

import net.minecraft.core.BlockPos;
import net.minecraft.core.Direction;
import net.minecraft.world.level.WorldGenLevel;
import net.minecraft.world.level.block.Blocks;
import net.minecraft.world.level.block.LadderBlock;
import net.minecraft.world.level.block.StairBlock;
import net.minecraft.world.level.block.state.BlockState;
import net.minecraft.world.level.block.state.properties.Half;

public class MoundStructureSetBlocks {
    public static void setBlocks(WorldGenLevel level, BlockPos startPos){
        BlockState ladder0 = Blocks.LADDER.defaultBlockState()
                .setValue(LadderBlock.FACING, Direction.NORTH); // metadata 2
        BlockState ladder1 = Blocks.LADDER.defaultBlockState()
                .setValue(LadderBlock.FACING, Direction.SOUTH); // metadata 3
        BlockState ladder2 = Blocks.LADDER.defaultBlockState()
                .setValue(LadderBlock.FACING, Direction.WEST);  // metadata 4
        BlockState ladder3 = Blocks.LADDER.defaultBlockState()
                .setValue(LadderBlock.FACING, Direction.EAST);  // metadata 5
        // 老版只有 2~5 有效，0~1 不使用，可留作占位
        BlockState ladder4 = Blocks.LADDER.defaultBlockState()
                .setValue(LadderBlock.FACING, Direction.NORTH);
        BlockState ladder5 = Blocks.LADDER.defaultBlockState()
                .setValue(LadderBlock.FACING, Direction.SOUTH);
        BlockState stoneStair0 = Blocks.STONE_STAIRS.defaultBlockState()
                .setValue(StairBlock.FACING, Direction.SOUTH)
                .setValue(StairBlock.HALF, Half.BOTTOM);
        BlockState stoneStair1 = Blocks.STONE_STAIRS.defaultBlockState()
                .setValue(StairBlock.FACING, Direction.WEST)
                .setValue(StairBlock.HALF, Half.BOTTOM);
        BlockState stoneStair2 = Blocks.STONE_STAIRS.defaultBlockState()
                .setValue(StairBlock.FACING, Direction.NORTH)
                .setValue(StairBlock.HALF, Half.BOTTOM);
        BlockState stoneStair3 = Blocks.STONE_STAIRS.defaultBlockState()
                .setValue(StairBlock.FACING, Direction.EAST)
                .setValue(StairBlock.HALF, Half.BOTTOM);
        BlockState stoneStair4 = Blocks.STONE_STAIRS.defaultBlockState()
                .setValue(StairBlock.FACING, Direction.SOUTH)
                .setValue(StairBlock.HALF, Half.TOP);
        BlockState stoneStair5 = Blocks.STONE_STAIRS.defaultBlockState()
                .setValue(StairBlock.FACING, Direction.WEST)
                .setValue(StairBlock.HALF, Half.TOP);
        BlockState stoneStair6 = Blocks.STONE_STAIRS.defaultBlockState()
                .setValue(StairBlock.FACING, Direction.NORTH)
                .setValue(StairBlock.HALF, Half.TOP);
        BlockState stoneStair7 = Blocks.STONE_STAIRS.defaultBlockState()
                .setValue(StairBlock.FACING, Direction.EAST)
                .setValue(StairBlock.HALF, Half.TOP);
        level.setBlock(startPos.offset(0, 8, 4),Blocks.DIRT.defaultBlockState(),3);
        level.setBlock(startPos.offset(0, 8, 5),Blocks.DIRT.defaultBlockState(),3);
        level.setBlock(startPos.offset(0, 8, 6),Blocks.DIRT.defaultBlockState(),3);
        level.setBlock(startPos.offset(0, 8, 7),Blocks.DIRT.defaultBlockState(),3);
        level.setBlock(startPos.offset(0, 8, 8),Blocks.COBBLESTONE.defaultBlockState(),3);
        level.setBlock(startPos.offset(0, 8, 9),Blocks.COBBLESTONE.defaultBlockState(),3);
        level.setBlock(startPos.offset(0, 8, 10),Blocks.COBBLESTONE.defaultBlockState(),3);
        level.setBlock(startPos.offset(0, 8, 11),Blocks.DIRT.defaultBlockState(),3);
        level.setBlock(startPos.offset(0, 8, 12),Blocks.DIRT.defaultBlockState(),3);
        level.setBlock(startPos.offset(0, 8, 13),Blocks.DIRT.defaultBlockState(),3);
        level.setBlock(startPos.offset(0, 8, 14),Blocks.DIRT.defaultBlockState(),3);
        level.setBlock(startPos.offset(0, 9, 4),Blocks.GRASS.defaultBlockState(),3);
        level.setBlock(startPos.offset(0, 9, 5),Blocks.GRASS.defaultBlockState(),3);
        level.setBlock(startPos.offset(0, 9, 6),Blocks.GRASS.defaultBlockState(),3);
        level.setBlock(startPos.offset(0, 9, 7),Blocks.GRASS.defaultBlockState(),3);
        level.setBlock(startPos.offset(0, 9, 8),Blocks.STONE_STAIRS.defaultBlockState(),3);
        level.setBlock(startPos.offset(0, 9, 9),Blocks.AIR.defaultBlockState(),3);
        level.setBlock(startPos.offset(0, 9, 10),Blocks.STONE_STAIRS.defaultBlockState(),3);
        level.setBlock(startPos.offset(0, 9, 11),Blocks.GRASS.defaultBlockState(),3);
        level.setBlock(startPos.offset(0, 9, 12),Blocks.GRASS.defaultBlockState(),3);
        level.setBlock(startPos.offset(0, 9, 13),Blocks.GRASS.defaultBlockState(),3);
        level.setBlock(startPos.offset(0, 9, 14),Blocks.GRASS.defaultBlockState(),3);
        level.setBlock(startPos.offset(0, 10, 8),Blocks.AIR.defaultBlockState(),3);
        level.setBlock(startPos.offset(0, 10, 9),Blocks.AIR.defaultBlockState(),3);
        level.setBlock(startPos.offset(0, 10, 10),Blocks.AIR.defaultBlockState(),3);
        level.setBlock(startPos.offset(1, 8, 3),Blocks.DIRT.defaultBlockState(),3);
        level.setBlock(startPos.offset(1, 8, 4),Blocks.DIRT.defaultBlockState(),3);
        level.setBlock(startPos.offset(1, 8, 5),Blocks.DIRT.defaultBlockState(),3);
        level.setBlock(startPos.offset(1, 8, 6),Blocks.DIRT.defaultBlockState(),3);
        level.setBlock(startPos.offset(1, 8, 7),Blocks.DIRT.defaultBlockState(),3);
        level.setBlock(startPos.offset(1, 8, 8),Blocks.COBBLESTONE.defaultBlockState(),3);
        level.setBlock(startPos.offset(1, 8, 9),Blocks.COBBLESTONE.defaultBlockState(),3);
        level.setBlock(startPos.offset(1, 8, 10),Blocks.COBBLESTONE.defaultBlockState(),3);
        level.setBlock(startPos.offset(1, 8, 11),Blocks.DIRT.defaultBlockState(),3);
        level.setBlock(startPos.offset(1, 8, 12),Blocks.DIRT.defaultBlockState(),3);
        level.setBlock(startPos.offset(1, 8, 13),Blocks.DIRT.defaultBlockState(),3);
        level.setBlock(startPos.offset(1, 8, 14),Blocks.DIRT.defaultBlockState(),3);
        level.setBlock(startPos.offset(1, 8, 15),Blocks.DIRT.defaultBlockState(),3);
        level.setBlock(startPos.offset(1, 9, 3),Blocks.GRASS.defaultBlockState(),3);
        level.setBlock(startPos.offset(1, 9, 4),Blocks.DIRT.defaultBlockState(),3);
        level.setBlock(startPos.offset(1, 9, 5),Blocks.DIRT.defaultBlockState(),3);
        level.setBlock(startPos.offset(1, 9, 6),Blocks.DIRT.defaultBlockState(),3);
        level.setBlock(startPos.offset(1, 9, 7),Blocks.DIRT.defaultBlockState(),3);
        level.setBlock(startPos.offset(1, 9, 8),Blocks.COBBLESTONE.defaultBlockState(),3);
        level.setBlock(startPos.offset(1, 9, 9),Blocks.AIR.defaultBlockState(),3);
        level.setBlock(startPos.offset(1, 9, 10),Blocks.COBBLESTONE.defaultBlockState(),3);
        level.setBlock(startPos.offset(1, 9, 11),Blocks.DIRT.defaultBlockState(),3);
        level.setBlock(startPos.offset(1, 9, 12),Blocks.DIRT.defaultBlockState(),3);
        level.setBlock(startPos.offset(1, 9, 13),Blocks.DIRT.defaultBlockState(),3);
        level.setBlock(startPos.offset(1, 9, 14),Blocks.DIRT.defaultBlockState(),3);
        level.setBlock(startPos.offset(1, 9, 15),Blocks.GRASS.defaultBlockState(),3);
        level.setBlock(startPos.offset(1, 10, 4),Blocks.GRASS.defaultBlockState(),3);
        level.setBlock(startPos.offset(1, 10, 5),Blocks.GRASS.defaultBlockState(),3);
        level.setBlock(startPos.offset(1, 10, 6),Blocks.DIRT.defaultBlockState(),3);
        level.setBlock(startPos.offset(1, 10, 7),Blocks.DIRT.defaultBlockState(),3);
        level.setBlock(startPos.offset(1, 10, 8),Blocks.STONE_STAIRS.defaultBlockState(),3);
        level.setBlock(startPos.offset(1, 10, 9),Blocks.AIR.defaultBlockState(),3);
        level.setBlock(startPos.offset(1, 10, 10),Blocks.STONE_STAIRS.defaultBlockState(),3);
        level.setBlock(startPos.offset(1, 10, 11),Blocks.GRASS.defaultBlockState(),3);
        level.setBlock(startPos.offset(1, 10, 12),Blocks.GRASS.defaultBlockState(),3);
        level.setBlock(startPos.offset(1, 10, 13),Blocks.GRASS.defaultBlockState(),3);
        level.setBlock(startPos.offset(1, 10, 14),Blocks.GRASS.defaultBlockState(),3);
        level.setBlock(startPos.offset(1, 11, 6),Blocks.GRASS.defaultBlockState(),3);
        level.setBlock(startPos.offset(1, 11, 7),Blocks.GRASS.defaultBlockState(),3);
        level.setBlock(startPos.offset(1, 11, 8),Blocks.AIR.defaultBlockState(),3);
        level.setBlock(startPos.offset(1, 11, 9),Blocks.AIR.defaultBlockState(),3);
        level.setBlock(startPos.offset(1, 11, 10),Blocks.AIR.defaultBlockState(),3);
        level.setBlock(startPos.offset(2, 8, 2),Blocks.DIRT.defaultBlockState(),3);
        level.setBlock(startPos.offset(2, 8, 3),Blocks.DIRT.defaultBlockState(),3);
        level.setBlock(startPos.offset(2, 8, 4),Blocks.DIRT.defaultBlockState(),3);
        level.setBlock(startPos.offset(2, 8, 5),Blocks.DIRT.defaultBlockState(),3);
        level.setBlock(startPos.offset(2, 8, 6),Blocks.DIRT.defaultBlockState(),3);
        level.setBlock(startPos.offset(2, 8, 7),Blocks.COBBLESTONE.defaultBlockState(),3);
        level.setBlock(startPos.offset(2, 8, 8),Blocks.COBBLESTONE.defaultBlockState(),3);
        level.setBlock(startPos.offset(2, 8, 9),Blocks.MOSSY_COBBLESTONE.defaultBlockState(),3);
        level.setBlock(startPos.offset(2, 8, 10),Blocks.COBBLESTONE.defaultBlockState(),3);
        level.setBlock(startPos.offset(2, 8, 11),Blocks.COBBLESTONE.defaultBlockState(),3);
        level.setBlock(startPos.offset(2, 8, 12),Blocks.DIRT.defaultBlockState(),3);
        level.setBlock(startPos.offset(2, 8, 13),Blocks.DIRT.defaultBlockState(),3);
        level.setBlock(startPos.offset(2, 8, 14),Blocks.DIRT.defaultBlockState(),3);
        level.setBlock(startPos.offset(2, 8, 15),Blocks.DIRT.defaultBlockState(),3);
        level.setBlock(startPos.offset(2, 8, 16),Blocks.DIRT.defaultBlockState(),3);
        level.setBlock(startPos.offset(2, 9, 2),Blocks.GRASS.defaultBlockState(),3);
        level.setBlock(startPos.offset(2, 9, 3),Blocks.DIRT.defaultBlockState(),3);
        level.setBlock(startPos.offset(2, 9, 4),Blocks.DIRT.defaultBlockState(),3);
        level.setBlock(startPos.offset(2, 9, 5),Blocks.DIRT.defaultBlockState(),3);
        level.setBlock(startPos.offset(2, 9, 6),Blocks.DIRT.defaultBlockState(),3);
        level.setBlock(startPos.offset(2, 9, 7),Blocks.DIRT.defaultBlockState(),3);
        level.setBlock(startPos.offset(2, 9, 8),Blocks.COBBLESTONE.defaultBlockState(),3);
        level.setBlock(startPos.offset(2, 9, 9),Blocks.AIR.defaultBlockState(),3);
        level.setBlock(startPos.offset(2, 9, 10),Blocks.COBBLESTONE.defaultBlockState(),3);
        level.setBlock(startPos.offset(2, 9, 11),Blocks.DIRT.defaultBlockState(),3);
        level.setBlock(startPos.offset(2, 9, 12),Blocks.DIRT.defaultBlockState(),3);
        level.setBlock(startPos.offset(2, 9, 13),Blocks.DIRT.defaultBlockState(),3);
        level.setBlock(startPos.offset(2, 9, 14),Blocks.DIRT.defaultBlockState(),3);
        level.setBlock(startPos.offset(2, 9, 15),Blocks.DIRT.defaultBlockState(),3);
        level.setBlock(startPos.offset(2, 9, 16),Blocks.GRASS.defaultBlockState(),3);
        level.setBlock(startPos.offset(2, 10, 3),Blocks.GRASS.defaultBlockState(),3);
        level.setBlock(startPos.offset(2, 10, 4),Blocks.DIRT.defaultBlockState(),3);
        level.setBlock(startPos.offset(2, 10, 5),Blocks.DIRT.defaultBlockState(),3);
        level.setBlock(startPos.offset(2, 10, 6),Blocks.DIRT.defaultBlockState(),3);
        level.setBlock(startPos.offset(2, 10, 7),Blocks.DIRT.defaultBlockState(),3);
        level.setBlock(startPos.offset(2, 10, 8),Blocks.COBBLESTONE.defaultBlockState(),3);
        level.setBlock(startPos.offset(2, 10, 9),Blocks.AIR.defaultBlockState(),3);
        level.setBlock(startPos.offset(2, 10, 10),Blocks.MOSSY_COBBLESTONE.defaultBlockState(),3);
        level.setBlock(startPos.offset(2, 10, 11),Blocks.DIRT.defaultBlockState(),3);
        level.setBlock(startPos.offset(2, 10, 12),Blocks.DIRT.defaultBlockState(),3);
        level.setBlock(startPos.offset(2, 10, 13),Blocks.DIRT.defaultBlockState(),3);
        level.setBlock(startPos.offset(2, 10, 14),Blocks.DIRT.defaultBlockState(),3);
        level.setBlock(startPos.offset(2, 10, 15),Blocks.GRASS.defaultBlockState(),3);
        level.setBlock(startPos.offset(2, 11, 4),Blocks.GRASS.defaultBlockState(),3);
        level.setBlock(startPos.offset(2, 11, 5),Blocks.GRASS.defaultBlockState(),3);
        level.setBlock(startPos.offset(2, 11, 6),Blocks.DIRT.defaultBlockState(),3);
        level.setBlock(startPos.offset(2, 11, 7),Blocks.DIRT.defaultBlockState(),3);
        level.setBlock(startPos.offset(2, 11, 8),Blocks.COBBLESTONE.defaultBlockState(),3);
        level.setBlock(startPos.offset(2, 11, 9),Blocks.CHISELED_STONE_BRICKS.defaultBlockState(),3);
        level.setBlock(startPos.offset(2, 11, 10),Blocks.MOSSY_COBBLESTONE.defaultBlockState(),3);
        level.setBlock(startPos.offset(2, 11, 11),Blocks.DIRT.defaultBlockState(),3);
        level.setBlock(startPos.offset(2, 11, 12),Blocks.GRASS.defaultBlockState(),3);
        level.setBlock(startPos.offset(2, 11, 13),Blocks.GRASS.defaultBlockState(),3);
        level.setBlock(startPos.offset(2, 11, 14),Blocks.GRASS.defaultBlockState(),3);
        level.setBlock(startPos.offset(2, 12, 6),Blocks.GRASS.defaultBlockState(),3);
        level.setBlock(startPos.offset(2, 12, 7),Blocks.GRASS.defaultBlockState(),3);
        level.setBlock(startPos.offset(2, 12, 8),Blocks.GRASS.defaultBlockState(),3);
        level.setBlock(startPos.offset(2, 12, 9),Blocks.GRASS.defaultBlockState(),3);
        level.setBlock(startPos.offset(2, 12, 10),Blocks.GRASS.defaultBlockState(),3);
        level.setBlock(startPos.offset(2, 12, 11),Blocks.GRASS.defaultBlockState(),3);
        level.setBlock(startPos.offset(3, 4, 3),Blocks.COBBLESTONE.defaultBlockState(),3);
        level.setBlock(startPos.offset(3, 4, 4),Blocks.COBBLESTONE.defaultBlockState(),3);
        level.setBlock(startPos.offset(3, 4, 5),Blocks.COBBLESTONE.defaultBlockState(),3);
        level.setBlock(startPos.offset(3, 4, 6),Blocks.COBBLESTONE.defaultBlockState(),3);
        level.setBlock(startPos.offset(3, 4, 7),Blocks.COBBLESTONE.defaultBlockState(),3);
        level.setBlock(startPos.offset(3, 4, 8),Blocks.COBBLESTONE.defaultBlockState(),3);
        level.setBlock(startPos.offset(3, 4, 9),Blocks.COBBLESTONE.defaultBlockState(),3);
        level.setBlock(startPos.offset(3, 4, 10),Blocks.COBBLESTONE.defaultBlockState(),3);
        level.setBlock(startPos.offset(3, 4, 11),Blocks.COBBLESTONE.defaultBlockState(),3);
        level.setBlock(startPos.offset(3, 4, 12),Blocks.COBBLESTONE.defaultBlockState(),3);
        level.setBlock(startPos.offset(3, 4, 13),Blocks.COBBLESTONE.defaultBlockState(),3);
        level.setBlock(startPos.offset(3, 4, 14),Blocks.COBBLESTONE.defaultBlockState(),3);
        level.setBlock(startPos.offset(3, 4, 15),Blocks.COBBLESTONE.defaultBlockState(),3);
        level.setBlock(startPos.offset(3, 5, 3),Blocks.COBBLESTONE.defaultBlockState(),3);
        level.setBlock(startPos.offset(3, 5, 4),Blocks.COBBLESTONE.defaultBlockState(),3);
        level.setBlock(startPos.offset(3, 5, 5),Blocks.COBBLESTONE.defaultBlockState(),3);
        level.setBlock(startPos.offset(3, 5, 6),Blocks.COBBLESTONE.defaultBlockState(),3);
        level.setBlock(startPos.offset(3, 5, 7),Blocks.MOSSY_COBBLESTONE.defaultBlockState(),3);
        level.setBlock(startPos.offset(3, 5, 8),Blocks.MOSSY_COBBLESTONE.defaultBlockState(),3);
        level.setBlock(startPos.offset(3, 5, 9),Blocks.COBBLESTONE.defaultBlockState(),3);
        level.setBlock(startPos.offset(3, 5, 10),Blocks.COBBLESTONE.defaultBlockState(),3);
        level.setBlock(startPos.offset(3, 5, 11),Blocks.COBBLESTONE.defaultBlockState(),3);
        level.setBlock(startPos.offset(3, 5, 12),Blocks.COBBLESTONE.defaultBlockState(),3);
        level.setBlock(startPos.offset(3, 5, 13),Blocks.COBBLESTONE.defaultBlockState(),3);
        level.setBlock(startPos.offset(3, 5, 14),Blocks.COBBLESTONE.defaultBlockState(),3);
        level.setBlock(startPos.offset(3, 5, 15),Blocks.COBBLESTONE.defaultBlockState(),3);
        level.setBlock(startPos.offset(3, 6, 3),Blocks.COBBLESTONE.defaultBlockState(),3);
        level.setBlock(startPos.offset(3, 6, 4),Blocks.COBBLESTONE.defaultBlockState(),3);
        level.setBlock(startPos.offset(3, 6, 5),Blocks.COBBLESTONE.defaultBlockState(),3);
        level.setBlock(startPos.offset(3, 6, 6),Blocks.COBBLESTONE.defaultBlockState(),3);
        level.setBlock(startPos.offset(3, 6, 7),Blocks.COBBLESTONE.defaultBlockState(),3);
        level.setBlock(startPos.offset(3, 6, 8),Blocks.COBBLESTONE.defaultBlockState(),3);
        level.setBlock(startPos.offset(3, 6, 9),Blocks.COBBLESTONE.defaultBlockState(),3);
        level.setBlock(startPos.offset(3, 6, 10),Blocks.COBBLESTONE.defaultBlockState(),3);
        level.setBlock(startPos.offset(3, 6, 11),Blocks.COBBLESTONE.defaultBlockState(),3);
        level.setBlock(startPos.offset(3, 6, 12),Blocks.COBBLESTONE.defaultBlockState(),3);
        level.setBlock(startPos.offset(3, 6, 13),Blocks.MOSSY_COBBLESTONE.defaultBlockState(),3);
        level.setBlock(startPos.offset(3, 6, 14),Blocks.COBBLESTONE.defaultBlockState(),3);
        level.setBlock(startPos.offset(3, 6, 15),Blocks.COBBLESTONE.defaultBlockState(),3);
        level.setBlock(startPos.offset(3, 7, 3),Blocks.COBBLESTONE.defaultBlockState(),3);
        level.setBlock(startPos.offset(3, 7, 4),Blocks.COBBLESTONE.defaultBlockState(),3);
        level.setBlock(startPos.offset(3, 7, 5),Blocks.COBBLESTONE.defaultBlockState(),3);
        level.setBlock(startPos.offset(3, 7, 6),Blocks.COBBLESTONE.defaultBlockState(),3);
        level.setBlock(startPos.offset(3, 7, 7),Blocks.COBBLESTONE.defaultBlockState(),3);
        level.setBlock(startPos.offset(3, 7, 8),Blocks.COBBLESTONE.defaultBlockState(),3);
        level.setBlock(startPos.offset(3, 7, 9),Blocks.COBBLESTONE.defaultBlockState(),3);
        level.setBlock(startPos.offset(3, 7, 10),Blocks.COBBLESTONE.defaultBlockState(),3);
        level.setBlock(startPos.offset(3, 7, 11),Blocks.MOSSY_COBBLESTONE.defaultBlockState(),3);
        level.setBlock(startPos.offset(3, 7, 12),Blocks.COBBLESTONE.defaultBlockState(),3);
        level.setBlock(startPos.offset(3, 7, 13),Blocks.COBBLESTONE.defaultBlockState(),3);
        level.setBlock(startPos.offset(3, 7, 14),Blocks.COBBLESTONE.defaultBlockState(),3);
        level.setBlock(startPos.offset(3, 7, 15),Blocks.COBBLESTONE.defaultBlockState(),3);
        level.setBlock(startPos.offset(3, 8, 1),Blocks.DIRT.defaultBlockState(),3);
        level.setBlock(startPos.offset(3, 8, 2),Blocks.DIRT.defaultBlockState(),3);
        level.setBlock(startPos.offset(3, 8, 3),Blocks.COBBLESTONE.defaultBlockState(),3);
        level.setBlock(startPos.offset(3, 8, 4),Blocks.COBBLESTONE.defaultBlockState(),3);
        level.setBlock(startPos.offset(3, 8, 5),Blocks.COBBLESTONE.defaultBlockState(),3);
        level.setBlock(startPos.offset(3, 8, 6),Blocks.COBBLESTONE.defaultBlockState(),3);
        level.setBlock(startPos.offset(3, 8, 7),Blocks.MOSSY_COBBLESTONE.defaultBlockState(),3);
        level.setBlock(startPos.offset(3, 8, 8),Blocks.COBBLESTONE.defaultBlockState(),3);
        level.setBlock(startPos.offset(3, 8, 9),Blocks.COBBLESTONE.defaultBlockState(),3);
        level.setBlock(startPos.offset(3, 8, 10),Blocks.COBBLESTONE.defaultBlockState(),3);
        level.setBlock(startPos.offset(3, 8, 11),Blocks.COBBLESTONE.defaultBlockState(),3);
        level.setBlock(startPos.offset(3, 8, 12),Blocks.COBBLESTONE.defaultBlockState(),3);
        level.setBlock(startPos.offset(3, 8, 13),Blocks.COBBLESTONE.defaultBlockState(),3);
        level.setBlock(startPos.offset(3, 8, 14),Blocks.COBBLESTONE.defaultBlockState(),3);
        level.setBlock(startPos.offset(3, 8, 15),Blocks.COBBLESTONE.defaultBlockState(),3);
        level.setBlock(startPos.offset(3, 8, 16),Blocks.DIRT.defaultBlockState(),3);
        level.setBlock(startPos.offset(3, 8, 17),Blocks.DIRT.defaultBlockState(),3);
        level.setBlock(startPos.offset(3, 9, 1),Blocks.GRASS.defaultBlockState(),3);
        level.setBlock(startPos.offset(3, 9, 2),Blocks.DIRT.defaultBlockState(),3);
        level.setBlock(startPos.offset(3, 9, 3),Blocks.COBBLESTONE.defaultBlockState(),3);
        level.setBlock(startPos.offset(3, 9, 4),Blocks.COBBLESTONE.defaultBlockState(),3);
        level.setBlock(startPos.offset(3, 9, 5),Blocks.COBBLESTONE.defaultBlockState(),3);
        level.setBlock(startPos.offset(3, 9, 6),Blocks.COBBLESTONE.defaultBlockState(),3);
        level.setBlock(startPos.offset(3, 9, 7),Blocks.COBBLESTONE.defaultBlockState(),3);
        level.setBlock(startPos.offset(3, 9, 8),Blocks.COBBLESTONE.defaultBlockState(),3);
        level.setBlock(startPos.offset(3, 9, 9),Blocks.IRON_BARS.defaultBlockState(),3);
        level.setBlock(startPos.offset(3, 9, 10),Blocks.COBBLESTONE.defaultBlockState(),3);
        level.setBlock(startPos.offset(3, 9, 11),Blocks.COBBLESTONE.defaultBlockState(),3);
        level.setBlock(startPos.offset(3, 9, 12),Blocks.MOSSY_COBBLESTONE.defaultBlockState(),3);
        level.setBlock(startPos.offset(3, 9, 13),Blocks.COBBLESTONE.defaultBlockState(),3);
        level.setBlock(startPos.offset(3, 9, 14),Blocks.COBBLESTONE.defaultBlockState(),3);
        level.setBlock(startPos.offset(3, 9, 15),Blocks.COBBLESTONE.defaultBlockState(),3);
        level.setBlock(startPos.offset(3, 9, 16),Blocks.DIRT.defaultBlockState(),3);
        level.setBlock(startPos.offset(3, 9, 17),Blocks.GRASS.defaultBlockState(),3);
        level.setBlock(startPos.offset(3, 10, 2),Blocks.GRASS.defaultBlockState(),3);
        level.setBlock(startPos.offset(3, 10, 3),Blocks.COBBLESTONE.defaultBlockState(),3);
        level.setBlock(startPos.offset(3, 10, 4),Blocks.MOSSY_COBBLESTONE.defaultBlockState(),3);
        level.setBlock(startPos.offset(3, 10, 5),Blocks.MOSSY_COBBLESTONE.defaultBlockState(),3);
        level.setBlock(startPos.offset(3, 10, 6),Blocks.COBBLESTONE.defaultBlockState(),3);
        level.setBlock(startPos.offset(3, 10, 7),Blocks.MOSSY_COBBLESTONE.defaultBlockState(),3);
        level.setBlock(startPos.offset(3, 10, 8),Blocks.COBBLESTONE.defaultBlockState(),3);
        level.setBlock(startPos.offset(3, 10, 9),Blocks.IRON_BARS.defaultBlockState(),3);
        level.setBlock(startPos.offset(3, 10, 10),Blocks.COBBLESTONE.defaultBlockState(),3);
        level.setBlock(startPos.offset(3, 10, 11),Blocks.COBBLESTONE.defaultBlockState(),3);
        level.setBlock(startPos.offset(3, 10, 12),Blocks.COBBLESTONE.defaultBlockState(),3);
        level.setBlock(startPos.offset(3, 10, 13),Blocks.COBBLESTONE.defaultBlockState(),3);
        level.setBlock(startPos.offset(3, 10, 14),Blocks.COBBLESTONE.defaultBlockState(),3);
        level.setBlock(startPos.offset(3, 10, 15),Blocks.COBBLESTONE.defaultBlockState(),3);
        level.setBlock(startPos.offset(3, 10, 16),Blocks.GRASS.defaultBlockState(),3);
        level.setBlock(startPos.offset(3, 11, 3),Blocks.GRASS.defaultBlockState(),3);
        level.setBlock(startPos.offset(3, 11, 4),Blocks.DIRT.defaultBlockState(),3);
        level.setBlock(startPos.offset(3, 11, 5),Blocks.COBBLESTONE.defaultBlockState(),3);
        level.setBlock(startPos.offset(3, 11, 6),Blocks.COBBLESTONE.defaultBlockState(),3);
        level.setBlock(startPos.offset(3, 11, 7),Blocks.COBBLESTONE.defaultBlockState(),3);
        level.setBlock(startPos.offset(3, 11, 8),Blocks.COBBLESTONE.defaultBlockState(),3);
        level.setBlock(startPos.offset(3, 11, 9),Blocks.MOSSY_COBBLESTONE.defaultBlockState(),3);
        level.setBlock(startPos.offset(3, 11, 10),Blocks.COBBLESTONE.defaultBlockState(),3);
        level.setBlock(startPos.offset(3, 11, 11),Blocks.COBBLESTONE.defaultBlockState(),3);
        level.setBlock(startPos.offset(3, 11, 12),Blocks.COBBLESTONE.defaultBlockState(),3);
        level.setBlock(startPos.offset(3, 11, 13),Blocks.COBBLESTONE.defaultBlockState(),3);
        level.setBlock(startPos.offset(3, 11, 14),Blocks.DIRT.defaultBlockState(),3);
        level.setBlock(startPos.offset(3, 11, 15),Blocks.GRASS.defaultBlockState(),3);
        level.setBlock(startPos.offset(3, 12, 4),Blocks.GRASS.defaultBlockState(),3);
        level.setBlock(startPos.offset(3, 12, 5),Blocks.GRASS.defaultBlockState(),3);
        level.setBlock(startPos.offset(3, 12, 6),Blocks.GRASS.defaultBlockState(),3);
        level.setBlock(startPos.offset(3, 12, 7),Blocks.GRASS.defaultBlockState(),3);
        level.setBlock(startPos.offset(3, 12, 8),Blocks.GRASS.defaultBlockState(),3);
        level.setBlock(startPos.offset(3, 12, 9),Blocks.GRASS.defaultBlockState(),3);
        level.setBlock(startPos.offset(3, 12, 10),Blocks.GRASS.defaultBlockState(),3);
        level.setBlock(startPos.offset(3, 12, 11),Blocks.GRASS.defaultBlockState(),3);
        level.setBlock(startPos.offset(3, 12, 12),Blocks.GRASS.defaultBlockState(),3);
        level.setBlock(startPos.offset(3, 12, 13),Blocks.GRASS.defaultBlockState(),3);
        level.setBlock(startPos.offset(3, 12, 14),Blocks.GRASS.defaultBlockState(),3);
        level.setBlock(startPos.offset(4, 4, 3),Blocks.COBBLESTONE.defaultBlockState(),3);
        level.setBlock(startPos.offset(4, 4, 4),Blocks.COBBLESTONE.defaultBlockState(),3);
        level.setBlock(startPos.offset(4, 4, 5),Blocks.COBBLESTONE.defaultBlockState(),3);
        level.setBlock(startPos.offset(4, 4, 6),Blocks.COBBLESTONE.defaultBlockState(),3);
        level.setBlock(startPos.offset(4, 4, 7),Blocks.COBBLESTONE.defaultBlockState(),3);
        level.setBlock(startPos.offset(4, 4, 8),Blocks.COBBLESTONE.defaultBlockState(),3);
        level.setBlock(startPos.offset(4, 4, 9),Blocks.COBBLESTONE.defaultBlockState(),3);
        level.setBlock(startPos.offset(4, 4, 10),Blocks.COBBLESTONE.defaultBlockState(),3);
        level.setBlock(startPos.offset(4, 4, 11),Blocks.COBBLESTONE.defaultBlockState(),3);
        level.setBlock(startPos.offset(4, 4, 12),Blocks.COBBLESTONE.defaultBlockState(),3);
        level.setBlock(startPos.offset(4, 4, 13),Blocks.COBBLESTONE.defaultBlockState(),3);
        level.setBlock(startPos.offset(4, 4, 14),Blocks.COBBLESTONE.defaultBlockState(),3);
        level.setBlock(startPos.offset(4, 4, 15),Blocks.COBBLESTONE.defaultBlockState(),3);
        level.setBlock(startPos.offset(4, 5, 3),Blocks.COBBLESTONE.defaultBlockState(),3);
        level.setBlock(startPos.offset(4, 5, 15),Blocks.COBBLESTONE.defaultBlockState(),3);
        level.setBlock(startPos.offset(4, 6, 3),Blocks.COBBLESTONE.defaultBlockState(),3);
        level.setBlock(startPos.offset(4, 6, 15),Blocks.COBBLESTONE.defaultBlockState(),3);
        level.setBlock(startPos.offset(4, 7, 3),Blocks.MOSSY_COBBLESTONE.defaultBlockState(),3);
        level.setBlock(startPos.offset(4, 7, 15),Blocks.COBBLESTONE.defaultBlockState(),3);
        level.setBlock(startPos.offset(4, 8, 0),Blocks.DIRT.defaultBlockState(),3);
        level.setBlock(startPos.offset(4, 8, 1),Blocks.DIRT.defaultBlockState(),3);
        level.setBlock(startPos.offset(4, 8, 2),Blocks.DIRT.defaultBlockState(),3);
        level.setBlock(startPos.offset(4, 8, 3),Blocks.COBBLESTONE.defaultBlockState(),3);
        level.setBlock(startPos.offset(4, 8, 4),Blocks.MOSSY_COBBLESTONE.defaultBlockState(),3);
        level.setBlock(startPos.offset(4, 8, 5),Blocks.MOSSY_COBBLESTONE.defaultBlockState(),3);
        level.setBlock(startPos.offset(4, 8, 6),Blocks.COBBLESTONE.defaultBlockState(),3);
        level.setBlock(startPos.offset(4, 8, 7),Blocks.COBBLESTONE.defaultBlockState(),3);
        level.setBlock(startPos.offset(4, 8, 8),Blocks.COBBLESTONE.defaultBlockState(),3);
        level.setBlock(startPos.offset(4, 8, 9),Blocks.MOSSY_COBBLESTONE.defaultBlockState(),3);
        level.setBlock(startPos.offset(4, 8, 10),Blocks.MOSSY_COBBLESTONE.defaultBlockState(),3);
        level.setBlock(startPos.offset(4, 8, 11),Blocks.COBBLESTONE.defaultBlockState(),3);
        level.setBlock(startPos.offset(4, 8, 12),Blocks.COBBLESTONE.defaultBlockState(),3);
        level.setBlock(startPos.offset(4, 8, 13),Blocks.COBBLESTONE.defaultBlockState(),3);
        level.setBlock(startPos.offset(4, 8, 14),Blocks.COBBLESTONE.defaultBlockState(),3);
        level.setBlock(startPos.offset(4, 8, 15),Blocks.COBBLESTONE.defaultBlockState(),3);
        level.setBlock(startPos.offset(4, 8, 16),Blocks.DIRT.defaultBlockState(),3);
        level.setBlock(startPos.offset(4, 8, 17),Blocks.DIRT.defaultBlockState(),3);
        level.setBlock(startPos.offset(4, 8, 18),Blocks.DIRT.defaultBlockState(),3);
        level.setBlock(startPos.offset(4, 9, 0),Blocks.GRASS.defaultBlockState(),3);
        level.setBlock(startPos.offset(4, 9, 1),Blocks.DIRT.defaultBlockState(),3);
        level.setBlock(startPos.offset(4, 9, 2),Blocks.DIRT.defaultBlockState(),3);
        level.setBlock(startPos.offset(4, 9, 3),Blocks.COBBLESTONE.defaultBlockState(),3);
        level.setBlock(startPos.offset(4, 9, 15),Blocks.COBBLESTONE.defaultBlockState(),3);
        level.setBlock(startPos.offset(4, 9, 16),Blocks.DIRT.defaultBlockState(),3);
        level.setBlock(startPos.offset(4, 9, 17),Blocks.DIRT.defaultBlockState(),3);
        level.setBlock(startPos.offset(4, 9, 18),Blocks.GRASS.defaultBlockState(),3);
        level.setBlock(startPos.offset(4, 10, 1),Blocks.GRASS.defaultBlockState(),3);
        level.setBlock(startPos.offset(4, 10, 2),Blocks.DIRT.defaultBlockState(),3);
        level.setBlock(startPos.offset(4, 10, 3),Blocks.COBBLESTONE.defaultBlockState(),3);
        level.setBlock(startPos.offset(4, 10, 15),Blocks.MOSSY_COBBLESTONE.defaultBlockState(),3);
        level.setBlock(startPos.offset(4, 10, 16),Blocks.DIRT.defaultBlockState(),3);
        level.setBlock(startPos.offset(4, 10, 17),Blocks.GRASS.defaultBlockState(),3);
        level.setBlock(startPos.offset(4, 11, 2),Blocks.GRASS.defaultBlockState(),3);
        level.setBlock(startPos.offset(4, 11, 3),Blocks.DIRT.defaultBlockState(),3);
        level.setBlock(startPos.offset(4, 11, 4),Blocks.COBBLESTONE.defaultBlockState(),3);
        level.setBlock(startPos.offset(4, 11, 14),Blocks.MOSSY_COBBLESTONE.defaultBlockState(),3);
        level.setBlock(startPos.offset(4, 11, 15),Blocks.DIRT.defaultBlockState(),3);
        level.setBlock(startPos.offset(4, 11, 16),Blocks.GRASS.defaultBlockState(),3);
        level.setBlock(startPos.offset(4, 12, 3),Blocks.GRASS.defaultBlockState(),3);
        level.setBlock(startPos.offset(4, 12, 4),Blocks.GRASS.defaultBlockState(),3);
        level.setBlock(startPos.offset(4, 12, 5),Blocks.COBBLESTONE.defaultBlockState(),3);
        level.setBlock(startPos.offset(4, 12, 6),Blocks.COBBLESTONE.defaultBlockState(),3);
        level.setBlock(startPos.offset(4, 12, 7),Blocks.COBBLESTONE.defaultBlockState(),3);
        level.setBlock(startPos.offset(4, 12, 8),Blocks.COBBLESTONE.defaultBlockState(),3);
        level.setBlock(startPos.offset(4, 12, 9),Blocks.COBBLESTONE.defaultBlockState(),3);
        level.setBlock(startPos.offset(4, 12, 10),Blocks.COBBLESTONE.defaultBlockState(),3);
        level.setBlock(startPos.offset(4, 12, 11),Blocks.COBBLESTONE.defaultBlockState(),3);
        level.setBlock(startPos.offset(4, 12, 12),Blocks.COBBLESTONE.defaultBlockState(),3);
        level.setBlock(startPos.offset(4, 12, 13),Blocks.COBBLESTONE.defaultBlockState(),3);
        level.setBlock(startPos.offset(4, 12, 14),Blocks.DIRT.defaultBlockState(),3);
        level.setBlock(startPos.offset(4, 12, 15),Blocks.GRASS.defaultBlockState(),3);
        level.setBlock(startPos.offset(4, 13, 5),Blocks.GRASS.defaultBlockState(),3);
        level.setBlock(startPos.offset(4, 13, 6),Blocks.GRASS.defaultBlockState(),3);
        level.setBlock(startPos.offset(4, 13, 7),Blocks.GRASS.defaultBlockState(),3);
        level.setBlock(startPos.offset(4, 13, 8),Blocks.GRASS.defaultBlockState(),3);
        level.setBlock(startPos.offset(4, 13, 9),Blocks.GRASS.defaultBlockState(),3);
        level.setBlock(startPos.offset(4, 13, 10),Blocks.GRASS.defaultBlockState(),3);
        level.setBlock(startPos.offset(4, 13, 11),Blocks.GRASS.defaultBlockState(),3);
        level.setBlock(startPos.offset(4, 13, 12),Blocks.GRASS.defaultBlockState(),3);
        level.setBlock(startPos.offset(4, 13, 13),Blocks.GRASS.defaultBlockState(),3);
        level.setBlock(startPos.offset(4, 13, 14),Blocks.GRASS.defaultBlockState(),3);
        level.setBlock(startPos.offset(5, 4, 3),Blocks.COBBLESTONE.defaultBlockState(),3);
        level.setBlock(startPos.offset(5, 4, 4),Blocks.COBBLESTONE.defaultBlockState(),3);
        level.setBlock(startPos.offset(5, 4, 5),Blocks.COBBLESTONE.defaultBlockState(),3);
        level.setBlock(startPos.offset(5, 4, 6),Blocks.COBBLESTONE.defaultBlockState(),3);
        level.setBlock(startPos.offset(5, 4, 7),Blocks.COBBLESTONE.defaultBlockState(),3);
        level.setBlock(startPos.offset(5, 4, 8),Blocks.COBBLESTONE.defaultBlockState(),3);
        level.setBlock(startPos.offset(5, 4, 9),Blocks.COBBLESTONE.defaultBlockState(),3);
        level.setBlock(startPos.offset(5, 4, 10),Blocks.MOSSY_COBBLESTONE.defaultBlockState(),3);
        level.setBlock(startPos.offset(5, 4, 11),Blocks.COBBLESTONE.defaultBlockState(),3);
        level.setBlock(startPos.offset(5, 4, 12),Blocks.COBBLESTONE.defaultBlockState(),3);
        level.setBlock(startPos.offset(5, 4, 13),Blocks.MOSSY_COBBLESTONE.defaultBlockState(),3);
        level.setBlock(startPos.offset(5, 4, 14),Blocks.COBBLESTONE.defaultBlockState(),3);
        level.setBlock(startPos.offset(5, 4, 15),Blocks.COBBLESTONE.defaultBlockState(),3);
        level.setBlock(startPos.offset(5, 5, 3),Blocks.COBBLESTONE.defaultBlockState(),3);
        level.setBlock(startPos.offset(5, 5, 15),Blocks.COBBLESTONE.defaultBlockState(),3);
        level.setBlock(startPos.offset(5, 6, 3),Blocks.MOSSY_COBBLESTONE.defaultBlockState(),3);
        level.setBlock(startPos.offset(5, 6, 15),Blocks.COBBLESTONE.defaultBlockState(),3);
        level.setBlock(startPos.offset(5, 7, 3),Blocks.COBBLESTONE.defaultBlockState(),3);
        level.setBlock(startPos.offset(5, 7, 15),Blocks.COBBLESTONE.defaultBlockState(),3);
        level.setBlock(startPos.offset(5, 8, 0),Blocks.DIRT.defaultBlockState(),3);
        level.setBlock(startPos.offset(5, 8, 1),Blocks.DIRT.defaultBlockState(),3);
        level.setBlock(startPos.offset(5, 8, 2),Blocks.DIRT.defaultBlockState(),3);
        level.setBlock(startPos.offset(5, 8, 3),Blocks.COBBLESTONE.defaultBlockState(),3);
        level.setBlock(startPos.offset(5, 8, 4),Blocks.MOSSY_COBBLESTONE.defaultBlockState(),3);
        level.setBlock(startPos.offset(5, 8, 5),Blocks.COBBLESTONE.defaultBlockState(),3);
        level.setBlock(startPos.offset(5, 8, 6),Blocks.COBBLESTONE.defaultBlockState(),3);
        level.setBlock(startPos.offset(5, 8, 7),Blocks.COBBLESTONE.defaultBlockState(),3);
        level.setBlock(startPos.offset(5, 8, 8),Blocks.COBBLESTONE.defaultBlockState(),3);
        level.setBlock(startPos.offset(5, 8, 9),Blocks.COBBLESTONE.defaultBlockState(),3);
        level.setBlock(startPos.offset(5, 8, 10),Blocks.COBBLESTONE.defaultBlockState(),3);
        level.setBlock(startPos.offset(5, 8, 11),Blocks.COBBLESTONE.defaultBlockState(),3);
        level.setBlock(startPos.offset(5, 8, 12),Blocks.COBBLESTONE.defaultBlockState(),3);
        level.setBlock(startPos.offset(5, 8, 13),Blocks.MOSSY_COBBLESTONE.defaultBlockState(),3);
        level.setBlock(startPos.offset(5, 8, 14),Blocks.COBBLESTONE.defaultBlockState(),3);
        level.setBlock(startPos.offset(5, 8, 15),Blocks.COBBLESTONE.defaultBlockState(),3);
        level.setBlock(startPos.offset(5, 8, 16),Blocks.DIRT.defaultBlockState(),3);
        level.setBlock(startPos.offset(5, 8, 17),Blocks.DIRT.defaultBlockState(),3);
        level.setBlock(startPos.offset(5, 8, 18),Blocks.DIRT.defaultBlockState(),3);
        level.setBlock(startPos.offset(5, 9, 0),Blocks.GRASS.defaultBlockState(),3);
        level.setBlock(startPos.offset(5, 9, 1),Blocks.DIRT.defaultBlockState(),3);
        level.setBlock(startPos.offset(5, 9, 2),Blocks.DIRT.defaultBlockState(),3);
        level.setBlock(startPos.offset(5, 9, 3),Blocks.COBBLESTONE.defaultBlockState(),3);
        level.setBlock(startPos.offset(5, 9, 15),Blocks.COBBLESTONE.defaultBlockState(),3);
        level.setBlock(startPos.offset(5, 9, 16),Blocks.DIRT.defaultBlockState(),3);
        level.setBlock(startPos.offset(5, 9, 17),Blocks.DIRT.defaultBlockState(),3);
        level.setBlock(startPos.offset(5, 9, 18),Blocks.GRASS.defaultBlockState(),3);
        level.setBlock(startPos.offset(5, 10, 1),Blocks.GRASS.defaultBlockState(),3);
        level.setBlock(startPos.offset(5, 10, 2),Blocks.DIRT.defaultBlockState(),3);
        level.setBlock(startPos.offset(5, 10, 3),Blocks.COBBLESTONE.defaultBlockState(),3);
        level.setBlock(startPos.offset(5, 10, 15),Blocks.COBBLESTONE.defaultBlockState(),3);
        level.setBlock(startPos.offset(5, 10, 16),Blocks.DIRT.defaultBlockState(),3);
        level.setBlock(startPos.offset(5, 10, 17),Blocks.GRASS.defaultBlockState(),3);
        level.setBlock(startPos.offset(5, 11, 2),Blocks.DIRT.defaultBlockState(),3);
        level.setBlock(startPos.offset(5, 11, 3),Blocks.COBBLESTONE.defaultBlockState(),3);
        level.setBlock(startPos.offset(5, 11, 6),stoneStair4,3);
        level.setBlock(startPos.offset(5, 11, 12),stoneStair4,3);
        level.setBlock(startPos.offset(5, 11, 15),Blocks.COBBLESTONE.defaultBlockState(),3);
        level.setBlock(startPos.offset(5, 11, 16),Blocks.GRASS.defaultBlockState(),3);
        level.setBlock(startPos.offset(5, 12, 2),Blocks.GRASS.defaultBlockState(),3);
        level.setBlock(startPos.offset(5, 12, 3),Blocks.GRASS.defaultBlockState(),3);
        level.setBlock(startPos.offset(5, 12, 4),Blocks.COBBLESTONE.defaultBlockState(),3);
        level.setBlock(startPos.offset(5, 12, 5),Blocks.COBBLESTONE.defaultBlockState(),3);
        level.setBlock(startPos.offset(5, 12, 6),Blocks.COBBLESTONE.defaultBlockState(),3);
        level.setBlock(startPos.offset(5, 12, 7),Blocks.COBBLESTONE.defaultBlockState(),3);
        level.setBlock(startPos.offset(5, 12, 8),Blocks.COBBLESTONE.defaultBlockState(),3);
        level.setBlock(startPos.offset(5, 12, 9),Blocks.COBBLESTONE.defaultBlockState(),3);
        level.setBlock(startPos.offset(5, 12, 10),Blocks.COBBLESTONE.defaultBlockState(),3);
        level.setBlock(startPos.offset(5, 12, 11),Blocks.COBBLESTONE.defaultBlockState(),3);
        level.setBlock(startPos.offset(5, 12, 12),Blocks.MOSSY_COBBLESTONE.defaultBlockState(),3);
        level.setBlock(startPos.offset(5, 12, 13),Blocks.COBBLESTONE.defaultBlockState(),3);
        level.setBlock(startPos.offset(5, 12, 14),Blocks.COBBLESTONE.defaultBlockState(),3);
        level.setBlock(startPos.offset(5, 12, 15),Blocks.DIRT.defaultBlockState(),3);
        level.setBlock(startPos.offset(5, 13, 4),Blocks.GRASS.defaultBlockState(),3);
        level.setBlock(startPos.offset(5, 13, 5),Blocks.GRASS.defaultBlockState(),3);
        level.setBlock(startPos.offset(5, 13, 6),Blocks.GRASS.defaultBlockState(),3);
        level.setBlock(startPos.offset(5, 13, 7),Blocks.GRASS.defaultBlockState(),3);
        level.setBlock(startPos.offset(5, 13, 8),Blocks.GRASS.defaultBlockState(),3);
        level.setBlock(startPos.offset(5, 13, 9),Blocks.GRASS.defaultBlockState(),3);
        level.setBlock(startPos.offset(5, 13, 10),Blocks.GRASS.defaultBlockState(),3);
        level.setBlock(startPos.offset(5, 13, 11),Blocks.GRASS.defaultBlockState(),3);
        level.setBlock(startPos.offset(5, 13, 12),Blocks.GRASS.defaultBlockState(),3);
        level.setBlock(startPos.offset(5, 13, 13),Blocks.GRASS.defaultBlockState(),3);
        level.setBlock(startPos.offset(5, 13, 14),Blocks.GRASS.defaultBlockState(),3);
        level.setBlock(startPos.offset(5, 13, 15),Blocks.GRASS.defaultBlockState(),3);
        level.setBlock(startPos.offset(6, 0, 6),Blocks.COBBLESTONE.defaultBlockState(),3);
        level.setBlock(startPos.offset(6, 0, 7),Blocks.COBBLESTONE.defaultBlockState(),3);
        level.setBlock(startPos.offset(6, 0, 8),Blocks.COBBLESTONE.defaultBlockState(),3);
        level.setBlock(startPos.offset(6, 0, 9),Blocks.COBBLESTONE.defaultBlockState(),3);
        level.setBlock(startPos.offset(6, 0, 10),Blocks.COBBLESTONE.defaultBlockState(),3);
        level.setBlock(startPos.offset(6, 0, 11),Blocks.COBBLESTONE.defaultBlockState(),3);
        level.setBlock(startPos.offset(6, 0, 12),Blocks.COBBLESTONE.defaultBlockState(),3);
        level.setBlock(startPos.offset(6, 1, 6),Blocks.MOSSY_COBBLESTONE.defaultBlockState(),3);
        level.setBlock(startPos.offset(6, 1, 7),Blocks.COBBLESTONE.defaultBlockState(),3);
        level.setBlock(startPos.offset(6, 1, 8),Blocks.COBBLESTONE.defaultBlockState(),3);
        level.setBlock(startPos.offset(6, 1, 9),Blocks.MOSSY_COBBLESTONE.defaultBlockState(),3);
        level.setBlock(startPos.offset(6, 1, 10),Blocks.MOSSY_COBBLESTONE.defaultBlockState(),3);
        level.setBlock(startPos.offset(6, 1, 11),Blocks.COBBLESTONE.defaultBlockState(),3);
        level.setBlock(startPos.offset(6, 1, 12),Blocks.COBBLESTONE.defaultBlockState(),3);
        level.setBlock(startPos.offset(6, 2, 6),Blocks.COBBLESTONE.defaultBlockState(),3);
        level.setBlock(startPos.offset(6, 2, 7),Blocks.COBBLESTONE.defaultBlockState(),3);
        level.setBlock(startPos.offset(6, 2, 8),Blocks.COBBLESTONE.defaultBlockState(),3);
        level.setBlock(startPos.offset(6, 2, 9),Blocks.COBBLESTONE.defaultBlockState(),3);
        level.setBlock(startPos.offset(6, 2, 10),Blocks.COBBLESTONE.defaultBlockState(),3);
        level.setBlock(startPos.offset(6, 2, 11),Blocks.COBBLESTONE.defaultBlockState(),3);
        level.setBlock(startPos.offset(6, 2, 12),Blocks.COBBLESTONE.defaultBlockState(),3);
        level.setBlock(startPos.offset(6, 3, 6),Blocks.COBBLESTONE.defaultBlockState(),3);
        level.setBlock(startPos.offset(6, 3, 7),Blocks.COBBLESTONE.defaultBlockState(),3);
        level.setBlock(startPos.offset(6, 3, 8),Blocks.MOSSY_COBBLESTONE.defaultBlockState(),3);
        level.setBlock(startPos.offset(6, 3, 9),Blocks.COBBLESTONE.defaultBlockState(),3);
        level.setBlock(startPos.offset(6, 3, 10),Blocks.COBBLESTONE.defaultBlockState(),3);
        level.setBlock(startPos.offset(6, 3, 11),Blocks.COBBLESTONE.defaultBlockState(),3);
        level.setBlock(startPos.offset(6, 3, 12),Blocks.COBBLESTONE.defaultBlockState(),3);
        level.setBlock(startPos.offset(6, 4, 3),Blocks.COBBLESTONE.defaultBlockState(),3);
        level.setBlock(startPos.offset(6, 4, 4),Blocks.COBBLESTONE.defaultBlockState(),3);
        level.setBlock(startPos.offset(6, 4, 5),Blocks.COBBLESTONE.defaultBlockState(),3);
        level.setBlock(startPos.offset(6, 4, 6),Blocks.COBBLESTONE.defaultBlockState(),3);
        level.setBlock(startPos.offset(6, 4, 7),stoneStair1,3);
        level.setBlock(startPos.offset(6, 4, 8),stoneStair1,3);
        level.setBlock(startPos.offset(6, 4, 9),Blocks.COBBLESTONE.defaultBlockState(),3);
        level.setBlock(startPos.offset(6, 4, 10),stoneStair1,3);
        level.setBlock(startPos.offset(6, 4, 11),stoneStair1,3);
        level.setBlock(startPos.offset(6, 4, 12),Blocks.COBBLESTONE.defaultBlockState(),3);
        level.setBlock(startPos.offset(6, 4, 13),Blocks.COBBLESTONE.defaultBlockState(),3);
        level.setBlock(startPos.offset(6, 4, 14),Blocks.COBBLESTONE.defaultBlockState(),3);
        level.setBlock(startPos.offset(6, 4, 15),Blocks.COBBLESTONE.defaultBlockState(),3);
        level.setBlock(startPos.offset(6, 5, 3),Blocks.COBBLESTONE.defaultBlockState(),3);
        level.setBlock(startPos.offset(6, 5, 6),Blocks.MOSSY_COBBLESTONE.defaultBlockState(),3);
        level.setBlock(startPos.offset(6, 5, 12),Blocks.COBBLESTONE.defaultBlockState(),3);
        level.setBlock(startPos.offset(6, 5, 15),Blocks.MOSSY_COBBLESTONE.defaultBlockState(),3);
        level.setBlock(startPos.offset(6, 6, 3),Blocks.COBBLESTONE.defaultBlockState(),3);
        level.setBlock(startPos.offset(6, 6, 6),Blocks.MOSSY_COBBLESTONE.defaultBlockState(),3);
        level.setBlock(startPos.offset(6, 6, 12),Blocks.COBBLESTONE.defaultBlockState(),3);
        level.setBlock(startPos.offset(6, 6, 15),Blocks.COBBLESTONE.defaultBlockState(),3);
        level.setBlock(startPos.offset(6, 7, 3),Blocks.COBBLESTONE.defaultBlockState(),3);
        level.setBlock(startPos.offset(6, 7, 6),Blocks.COBBLESTONE.defaultBlockState(),3);
        level.setBlock(startPos.offset(6, 7, 12),Blocks.COBBLESTONE.defaultBlockState(),3);
        level.setBlock(startPos.offset(6, 7, 15),Blocks.COBBLESTONE.defaultBlockState(),3);
        level.setBlock(startPos.offset(6, 8, 0),Blocks.DIRT.defaultBlockState(),3);
        level.setBlock(startPos.offset(6, 8, 1),Blocks.DIRT.defaultBlockState(),3);
        level.setBlock(startPos.offset(6, 8, 2),Blocks.DIRT.defaultBlockState(),3);
        level.setBlock(startPos.offset(6, 8, 3),Blocks.COBBLESTONE.defaultBlockState(),3);
        level.setBlock(startPos.offset(6, 8, 4),Blocks.COBBLESTONE.defaultBlockState(),3);
        level.setBlock(startPos.offset(6, 8, 5),Blocks.COBBLESTONE.defaultBlockState(),3);
        level.setBlock(startPos.offset(6, 8, 6),Blocks.COBBLESTONE.defaultBlockState(),3);
        level.setBlock(startPos.offset(6, 8, 7),stoneStair5,3);
        level.setBlock(startPos.offset(6, 8, 8),stoneStair5,3);
        level.setBlock(startPos.offset(6, 8, 9),stoneStair5,3);
        level.setBlock(startPos.offset(6, 8, 10),stoneStair5,3);
        level.setBlock(startPos.offset(6, 8, 11),stoneStair5,3);
        level.setBlock(startPos.offset(6, 8, 12),Blocks.MOSSY_COBBLESTONE.defaultBlockState(),3);
        level.setBlock(startPos.offset(6, 8, 13),Blocks.COBBLESTONE.defaultBlockState(),3);
        level.setBlock(startPos.offset(6, 8, 14),Blocks.COBBLESTONE.defaultBlockState(),3);
        level.setBlock(startPos.offset(6, 8, 15),Blocks.COBBLESTONE.defaultBlockState(),3);
        level.setBlock(startPos.offset(6, 8, 16),Blocks.DIRT.defaultBlockState(),3);
        level.setBlock(startPos.offset(6, 8, 17),Blocks.DIRT.defaultBlockState(),3);
        level.setBlock(startPos.offset(6, 8, 18),Blocks.DIRT.defaultBlockState(),3);
        level.setBlock(startPos.offset(6, 9, 0),Blocks.GRASS.defaultBlockState(),3);
        level.setBlock(startPos.offset(6, 9, 1),Blocks.DIRT.defaultBlockState(),3);
        level.setBlock(startPos.offset(6, 9, 2),Blocks.DIRT.defaultBlockState(),3);
        level.setBlock(startPos.offset(6, 9, 3),Blocks.COBBLESTONE.defaultBlockState(),3);
        level.setBlock(startPos.offset(6, 9, 6),Blocks.MOSSY_COBBLESTONE.defaultBlockState(),3);
        level.setBlock(startPos.offset(6, 9, 12),Blocks.COBBLESTONE.defaultBlockState(),3);
        level.setBlock(startPos.offset(6, 9, 15),Blocks.COBBLESTONE.defaultBlockState(),3);
        level.setBlock(startPos.offset(6, 9, 16),Blocks.DIRT.defaultBlockState(),3);
        level.setBlock(startPos.offset(6, 9, 17),Blocks.DIRT.defaultBlockState(),3);
        level.setBlock(startPos.offset(6, 9, 18),Blocks.GRASS.defaultBlockState(),3);
        level.setBlock(startPos.offset(6, 10, 1),Blocks.GRASS.defaultBlockState(),3);
        level.setBlock(startPos.offset(6, 10, 2),Blocks.DIRT.defaultBlockState(),3);
        level.setBlock(startPos.offset(6, 10, 3),Blocks.COBBLESTONE.defaultBlockState(),3);
        level.setBlock(startPos.offset(6, 10, 6),Blocks.COBBLESTONE.defaultBlockState(),3);
        level.setBlock(startPos.offset(6, 10, 12),Blocks.MOSSY_COBBLESTONE.defaultBlockState(),3);
        level.setBlock(startPos.offset(6, 10, 15),Blocks.COBBLESTONE.defaultBlockState(),3);
        level.setBlock(startPos.offset(6, 10, 16),Blocks.DIRT.defaultBlockState(),3);
        level.setBlock(startPos.offset(6, 10, 17),Blocks.GRASS.defaultBlockState(),3);
        level.setBlock(startPos.offset(6, 11, 2),Blocks.GRASS.defaultBlockState(),3);
        level.setBlock(startPos.offset(6, 11, 3),Blocks.COBBLESTONE.defaultBlockState(),3);
        level.setBlock(startPos.offset(6, 11, 5),stoneStair6,3);
        level.setBlock(startPos.offset(6, 11, 6),Blocks.COBBLESTONE.defaultBlockState(),3);
        level.setBlock(startPos.offset(6, 11, 7),stoneStair7,3);
        level.setBlock(startPos.offset(6, 11, 11),stoneStair6,3);
        level.setBlock(startPos.offset(6, 11, 12),Blocks.COBBLESTONE.defaultBlockState(),3);
        level.setBlock(startPos.offset(6, 11, 13),stoneStair7,3);
        level.setBlock(startPos.offset(6, 11, 15),Blocks.MOSSY_COBBLESTONE.defaultBlockState(),3);
        level.setBlock(startPos.offset(6, 11, 16),Blocks.GRASS.defaultBlockState(),3);
        level.setBlock(startPos.offset(6, 12, 3),Blocks.GRASS.defaultBlockState(),3);
        level.setBlock(startPos.offset(6, 12, 4),Blocks.COBBLESTONE.defaultBlockState(),3);
        level.setBlock(startPos.offset(6, 12, 5),Blocks.COBBLESTONE.defaultBlockState(),3);
        level.setBlock(startPos.offset(6, 12, 6),Blocks.MOSSY_COBBLESTONE.defaultBlockState(),3);
        level.setBlock(startPos.offset(6, 12, 7),Blocks.COBBLESTONE.defaultBlockState(),3);
        level.setBlock(startPos.offset(6, 12, 8),Blocks.COBBLESTONE.defaultBlockState(),3);
        level.setBlock(startPos.offset(6, 12, 9),Blocks.MOSSY_COBBLESTONE.defaultBlockState(),3);
        level.setBlock(startPos.offset(6, 12, 10),Blocks.COBBLESTONE.defaultBlockState(),3);
        level.setBlock(startPos.offset(6, 12, 11),Blocks.COBBLESTONE.defaultBlockState(),3);
        level.setBlock(startPos.offset(6, 12, 12),Blocks.COBBLESTONE.defaultBlockState(),3);
        level.setBlock(startPos.offset(6, 12, 13),Blocks.COBBLESTONE.defaultBlockState(),3);
        level.setBlock(startPos.offset(6, 12, 14),Blocks.COBBLESTONE.defaultBlockState(),3);
        level.setBlock(startPos.offset(6, 12, 15),Blocks.GRASS.defaultBlockState(),3);
        level.setBlock(startPos.offset(6, 13, 4),Blocks.GRASS.defaultBlockState(),3);
        level.setBlock(startPos.offset(6, 13, 5),Blocks.GRASS.defaultBlockState(),3);
        level.setBlock(startPos.offset(6, 13, 6),Blocks.GRASS.defaultBlockState(),3);
        level.setBlock(startPos.offset(6, 13, 7),Blocks.GRASS.defaultBlockState(),3);
        level.setBlock(startPos.offset(6, 13, 8),Blocks.GRASS.defaultBlockState(),3);
        level.setBlock(startPos.offset(6, 13, 9),Blocks.GRASS.defaultBlockState(),3);
        level.setBlock(startPos.offset(6, 13, 10),Blocks.GRASS.defaultBlockState(),3);
        level.setBlock(startPos.offset(6, 13, 11),Blocks.GRASS.defaultBlockState(),3);
        level.setBlock(startPos.offset(6, 13, 12),Blocks.GRASS.defaultBlockState(),3);
        level.setBlock(startPos.offset(6, 13, 13),Blocks.GRASS.defaultBlockState(),3);
        level.setBlock(startPos.offset(6, 13, 14),Blocks.GRASS.defaultBlockState(),3);
        level.setBlock(startPos.offset(7, 0, 6),Blocks.COBBLESTONE.defaultBlockState(),3);
        level.setBlock(startPos.offset(7, 0, 7),Blocks.MOSSY_COBBLESTONE.defaultBlockState(),3);
        level.setBlock(startPos.offset(7, 0, 8),Blocks.COBBLESTONE.defaultBlockState(),3);
        level.setBlock(startPos.offset(7, 0, 9),Blocks.COBBLESTONE.defaultBlockState(),3);
        level.setBlock(startPos.offset(7, 0, 10),Blocks.MOSSY_COBBLESTONE.defaultBlockState(),3);
        level.setBlock(startPos.offset(7, 0, 11),Blocks.MOSSY_COBBLESTONE.defaultBlockState(),3);
        level.setBlock(startPos.offset(7, 0, 12),Blocks.COBBLESTONE.defaultBlockState(),3);
        level.setBlock(startPos.offset(7, 1, 6),Blocks.MOSSY_COBBLESTONE.defaultBlockState(),3);
        level.setBlock(startPos.offset(7, 1, 12),Blocks.COBBLESTONE.defaultBlockState(),3);
        level.setBlock(startPos.offset(7, 2, 6),Blocks.COBBLESTONE.defaultBlockState(),3);
        level.setBlock(startPos.offset(7, 2, 12),Blocks.COBBLESTONE.defaultBlockState(),3);
        level.setBlock(startPos.offset(7, 3, 6),Blocks.COBBLESTONE.defaultBlockState(),3);
        level.setBlock(startPos.offset(7, 3, 12),Blocks.COBBLESTONE.defaultBlockState(),3);
        level.setBlock(startPos.offset(7, 4, 3),Blocks.COBBLESTONE.defaultBlockState(),3);
        level.setBlock(startPos.offset(7, 4, 4),Blocks.COBBLESTONE.defaultBlockState(),3);
        level.setBlock(startPos.offset(7, 4, 5),Blocks.COBBLESTONE.defaultBlockState(),3);
        level.setBlock(startPos.offset(7, 4, 6),stoneStair3,3);
        level.setBlock(startPos.offset(7, 4, 12),stoneStair2,3);
        level.setBlock(startPos.offset(7, 4, 13),Blocks.COBBLESTONE.defaultBlockState(),3);
        level.setBlock(startPos.offset(7, 4, 14),Blocks.COBBLESTONE.defaultBlockState(),3);
        level.setBlock(startPos.offset(7, 4, 15),Blocks.COBBLESTONE.defaultBlockState(),3);
        level.setBlock(startPos.offset(7, 5, 3),Blocks.COBBLESTONE.defaultBlockState(),3);
        level.setBlock(startPos.offset(7, 5, 15),Blocks.COBBLESTONE.defaultBlockState(),3);
        level.setBlock(startPos.offset(7, 6, 3),Blocks.COBBLESTONE.defaultBlockState(),3);
        level.setBlock(startPos.offset(7, 6, 15),Blocks.MOSSY_COBBLESTONE.defaultBlockState(),3);
        level.setBlock(startPos.offset(7, 7, 3),Blocks.COBBLESTONE.defaultBlockState(),3);
        level.setBlock(startPos.offset(7, 7, 15),Blocks.COBBLESTONE.defaultBlockState(),3);
        level.setBlock(startPos.offset(7, 8, 0),Blocks.DIRT.defaultBlockState(),3);
        level.setBlock(startPos.offset(7, 8, 1),Blocks.DIRT.defaultBlockState(),3);
        level.setBlock(startPos.offset(7, 8, 2),Blocks.DIRT.defaultBlockState(),3);
        level.setBlock(startPos.offset(7, 8, 3),Blocks.COBBLESTONE.defaultBlockState(),3);
        level.setBlock(startPos.offset(7, 8, 4),Blocks.COBBLESTONE.defaultBlockState(),3);
        level.setBlock(startPos.offset(7, 8, 5),Blocks.COBBLESTONE.defaultBlockState(),3);
        level.setBlock(startPos.offset(7, 8, 6),stoneStair7,3);
        level.setBlock(startPos.offset(7, 8, 12),stoneStair6,3);
        level.setBlock(startPos.offset(7, 8, 13),Blocks.COBBLESTONE.defaultBlockState(),3);
        level.setBlock(startPos.offset(7, 8, 14),Blocks.MOSSY_COBBLESTONE.defaultBlockState(),3);
        level.setBlock(startPos.offset(7, 8, 15),Blocks.COBBLESTONE.defaultBlockState(),3);
        level.setBlock(startPos.offset(7, 8, 16),Blocks.DIRT.defaultBlockState(),3);
        level.setBlock(startPos.offset(7, 8, 17),Blocks.DIRT.defaultBlockState(),3);
        level.setBlock(startPos.offset(7, 8, 18),Blocks.DIRT.defaultBlockState(),3);
        level.setBlock(startPos.offset(7, 9, 0),Blocks.GRASS.defaultBlockState(),3);
        level.setBlock(startPos.offset(7, 9, 1),Blocks.DIRT.defaultBlockState(),3);
        level.setBlock(startPos.offset(7, 9, 2),Blocks.DIRT.defaultBlockState(),3);
        level.setBlock(startPos.offset(7, 9, 3),Blocks.COBBLESTONE.defaultBlockState(),3);
        level.setBlock(startPos.offset(7, 9, 15),Blocks.COBBLESTONE.defaultBlockState(),3);
        level.setBlock(startPos.offset(7, 9, 16),Blocks.DIRT.defaultBlockState(),3);
        level.setBlock(startPos.offset(7, 9, 17),Blocks.DIRT.defaultBlockState(),3);
        level.setBlock(startPos.offset(7, 9, 18),Blocks.GRASS.defaultBlockState(),3);
        level.setBlock(startPos.offset(7, 10, 1),Blocks.DIRT.defaultBlockState(),3);
        level.setBlock(startPos.offset(7, 10, 2),Blocks.DIRT.defaultBlockState(),3);
        level.setBlock(startPos.offset(7, 10, 3),Blocks.COBBLESTONE.defaultBlockState(),3);
        level.setBlock(startPos.offset(7, 10, 15),Blocks.COBBLESTONE.defaultBlockState(),3);
        level.setBlock(startPos.offset(7, 10, 16),Blocks.DIRT.defaultBlockState(),3);
        level.setBlock(startPos.offset(7, 10, 17),Blocks.DIRT.defaultBlockState(),3);
        level.setBlock(startPos.offset(7, 11, 1),Blocks.GRASS.defaultBlockState(),3);
        level.setBlock(startPos.offset(7, 11, 2),Blocks.GRASS.defaultBlockState(),3);
        level.setBlock(startPos.offset(7, 11, 3),Blocks.MOSSY_COBBLESTONE.defaultBlockState(),3);
        level.setBlock(startPos.offset(7, 11, 6),stoneStair5,3);
        level.setBlock(startPos.offset(7, 11, 12),stoneStair5,3);
        level.setBlock(startPos.offset(7, 11, 15),Blocks.COBBLESTONE.defaultBlockState(),3);
        level.setBlock(startPos.offset(7, 11, 16),Blocks.GRASS.defaultBlockState(),3);
        level.setBlock(startPos.offset(7, 11, 17),Blocks.GRASS.defaultBlockState(),3);
        level.setBlock(startPos.offset(7, 12, 3),Blocks.GRASS.defaultBlockState(),3);
        level.setBlock(startPos.offset(7, 12, 4),Blocks.COBBLESTONE.defaultBlockState(),3);
        level.setBlock(startPos.offset(7, 12, 5),Blocks.COBBLESTONE.defaultBlockState(),3);
        level.setBlock(startPos.offset(7, 12, 6),Blocks.COBBLESTONE.defaultBlockState(),3);
        level.setBlock(startPos.offset(7, 12, 7),Blocks.COBBLESTONE.defaultBlockState(),3);
        level.setBlock(startPos.offset(7, 12, 8),Blocks.COBBLESTONE.defaultBlockState(),3);
        level.setBlock(startPos.offset(7, 12, 9),Blocks.MOSSY_COBBLESTONE.defaultBlockState(),3);
        level.setBlock(startPos.offset(7, 12, 10),Blocks.COBBLESTONE.defaultBlockState(),3);
        level.setBlock(startPos.offset(7, 12, 11),Blocks.COBBLESTONE.defaultBlockState(),3);
        level.setBlock(startPos.offset(7, 12, 12),Blocks.COBBLESTONE.defaultBlockState(),3);
        level.setBlock(startPos.offset(7, 12, 13),Blocks.COBBLESTONE.defaultBlockState(),3);
        level.setBlock(startPos.offset(7, 12, 14),Blocks.COBBLESTONE.defaultBlockState(),3);
        level.setBlock(startPos.offset(7, 12, 15),Blocks.GRASS.defaultBlockState(),3);
        level.setBlock(startPos.offset(7, 13, 4),Blocks.GRASS.defaultBlockState(),3);
        level.setBlock(startPos.offset(7, 13, 5),Blocks.GRASS.defaultBlockState(),3);
        level.setBlock(startPos.offset(7, 13, 6),Blocks.GRASS.defaultBlockState(),3);
        level.setBlock(startPos.offset(7, 13, 7),Blocks.DIRT.defaultBlockState(),3);
        level.setBlock(startPos.offset(7, 13, 8),Blocks.DIRT.defaultBlockState(),3);
        level.setBlock(startPos.offset(7, 13, 9),Blocks.DIRT.defaultBlockState(),3);
        level.setBlock(startPos.offset(7, 13, 10),Blocks.GRASS.defaultBlockState(),3);
        level.setBlock(startPos.offset(7, 13, 11),Blocks.GRASS.defaultBlockState(),3);
        level.setBlock(startPos.offset(7, 13, 12),Blocks.GRASS.defaultBlockState(),3);
        level.setBlock(startPos.offset(7, 13, 13),Blocks.GRASS.defaultBlockState(),3);
        level.setBlock(startPos.offset(7, 13, 14),Blocks.GRASS.defaultBlockState(),3);
        level.setBlock(startPos.offset(7, 14, 7),Blocks.GRASS.defaultBlockState(),3);
        level.setBlock(startPos.offset(7, 14, 8),Blocks.GRASS.defaultBlockState(),3);
        level.setBlock(startPos.offset(7, 14, 9),Blocks.GRASS.defaultBlockState(),3);
        level.setBlock(startPos.offset(8, 0, 6),Blocks.COBBLESTONE.defaultBlockState(),3);
        level.setBlock(startPos.offset(8, 0, 7),Blocks.COBBLESTONE.defaultBlockState(),3);
        level.setBlock(startPos.offset(8, 0, 8),Blocks.COBBLESTONE.defaultBlockState(),3);
        level.setBlock(startPos.offset(8, 0, 9),Blocks.COBBLESTONE.defaultBlockState(),3);
        level.setBlock(startPos.offset(8, 0, 10),Blocks.COBBLESTONE.defaultBlockState(),3);
        level.setBlock(startPos.offset(8, 0, 11),Blocks.COBBLESTONE.defaultBlockState(),3);
        level.setBlock(startPos.offset(8, 0, 12),Blocks.COBBLESTONE.defaultBlockState(),3);
        level.setBlock(startPos.offset(8, 1, 6),Blocks.COBBLESTONE.defaultBlockState(),3);
        level.setBlock(startPos.offset(8, 1, 12),Blocks.MOSSY_COBBLESTONE.defaultBlockState(),3);
        level.setBlock(startPos.offset(8, 2, 6),Blocks.COBBLESTONE.defaultBlockState(),3);
        level.setBlock(startPos.offset(8, 2, 12),Blocks.COBBLESTONE.defaultBlockState(),3);
        level.setBlock(startPos.offset(8, 3, 6),Blocks.COBBLESTONE.defaultBlockState(),3);
        level.setBlock(startPos.offset(8, 3, 12),Blocks.COBBLESTONE.defaultBlockState(),3);
        level.setBlock(startPos.offset(8, 4, 3),Blocks.COBBLESTONE.defaultBlockState(),3);
        level.setBlock(startPos.offset(8, 4, 4),Blocks.COBBLESTONE.defaultBlockState(),3);
        level.setBlock(startPos.offset(8, 4, 5),Blocks.MOSSY_COBBLESTONE.defaultBlockState(),3);
        level.setBlock(startPos.offset(8, 4, 6),stoneStair3,3);
        level.setBlock(startPos.offset(8, 4, 12),stoneStair2,3);
        level.setBlock(startPos.offset(8, 4, 13),Blocks.COBBLESTONE.defaultBlockState(),3);
        level.setBlock(startPos.offset(8, 4, 14),Blocks.COBBLESTONE.defaultBlockState(),3);
        level.setBlock(startPos.offset(8, 4, 15),Blocks.COBBLESTONE.defaultBlockState(),3);
        level.setBlock(startPos.offset(8, 5, 3),Blocks.COBBLESTONE.defaultBlockState(),3);
        level.setBlock(startPos.offset(8, 5, 15),Blocks.COBBLESTONE.defaultBlockState(),3);
        level.setBlock(startPos.offset(8, 6, 3),Blocks.MOSSY_COBBLESTONE.defaultBlockState(),3);
        level.setBlock(startPos.offset(8, 6, 15),Blocks.COBBLESTONE.defaultBlockState(),3);
        level.setBlock(startPos.offset(8, 7, 3),Blocks.COBBLESTONE.defaultBlockState(),3);
        level.setBlock(startPos.offset(8, 7, 15),Blocks.COBBLESTONE.defaultBlockState(),3);
        level.setBlock(startPos.offset(8, 8, 0),Blocks.DIRT.defaultBlockState(),3);
        level.setBlock(startPos.offset(8, 8, 1),Blocks.DIRT.defaultBlockState(),3);
        level.setBlock(startPos.offset(8, 8, 2),Blocks.DIRT.defaultBlockState(),3);
        level.setBlock(startPos.offset(8, 8, 3),Blocks.COBBLESTONE.defaultBlockState(),3);
        level.setBlock(startPos.offset(8, 8, 4),Blocks.COBBLESTONE.defaultBlockState(),3);
        level.setBlock(startPos.offset(8, 8, 5),Blocks.MOSSY_COBBLESTONE.defaultBlockState(),3);
        level.setBlock(startPos.offset(8, 8, 6),stoneStair7,3);
        level.setBlock(startPos.offset(8, 8, 12),stoneStair6,3);
        level.setBlock(startPos.offset(8, 8, 13),Blocks.COBBLESTONE.defaultBlockState(),3);
        level.setBlock(startPos.offset(8, 8, 14),Blocks.COBBLESTONE.defaultBlockState(),3);
        level.setBlock(startPos.offset(8, 8, 15),Blocks.COBBLESTONE.defaultBlockState(),3);
        level.setBlock(startPos.offset(8, 8, 16),Blocks.DIRT.defaultBlockState(),3);
        level.setBlock(startPos.offset(8, 8, 17),Blocks.DIRT.defaultBlockState(),3);
        level.setBlock(startPos.offset(8, 8, 18),Blocks.DIRT.defaultBlockState(),3);
        level.setBlock(startPos.offset(8, 9, 0),Blocks.GRASS.defaultBlockState(),3);
        level.setBlock(startPos.offset(8, 9, 1),Blocks.DIRT.defaultBlockState(),3);
        level.setBlock(startPos.offset(8, 9, 2),Blocks.DIRT.defaultBlockState(),3);
        level.setBlock(startPos.offset(8, 9, 3),Blocks.COBBLESTONE.defaultBlockState(),3);
        level.setBlock(startPos.offset(8, 9, 15),Blocks.COBBLESTONE.defaultBlockState(),3);
        level.setBlock(startPos.offset(8, 9, 16),Blocks.DIRT.defaultBlockState(),3);
        level.setBlock(startPos.offset(8, 9, 17),Blocks.DIRT.defaultBlockState(),3);
        level.setBlock(startPos.offset(8, 9, 18),Blocks.GRASS.defaultBlockState(),3);
        level.setBlock(startPos.offset(8, 10, 1),Blocks.GRASS.defaultBlockState(),3);
        level.setBlock(startPos.offset(8, 10, 2),Blocks.DIRT.defaultBlockState(),3);
        level.setBlock(startPos.offset(8, 10, 3),Blocks.MOSSY_COBBLESTONE.defaultBlockState(),3);
        level.setBlock(startPos.offset(8, 10, 15),Blocks.MOSSY_COBBLESTONE.defaultBlockState(),3);
        level.setBlock(startPos.offset(8, 10, 16),Blocks.DIRT.defaultBlockState(),3);
        level.setBlock(startPos.offset(8, 10, 17),Blocks.DIRT.defaultBlockState(),3);
        level.setBlock(startPos.offset(8, 11, 2),Blocks.GRASS.defaultBlockState(),3);
        level.setBlock(startPos.offset(8, 11, 3),Blocks.COBBLESTONE.defaultBlockState(),3);
        level.setBlock(startPos.offset(8, 11, 15),Blocks.COBBLESTONE.defaultBlockState(),3);
        level.setBlock(startPos.offset(8, 11, 16),Blocks.GRASS.defaultBlockState(),3);
        level.setBlock(startPos.offset(8, 11, 17),Blocks.GRASS.defaultBlockState(),3);
        level.setBlock(startPos.offset(8, 12, 3),Blocks.GRASS.defaultBlockState(),3);
        level.setBlock(startPos.offset(8, 12, 4),Blocks.COBBLESTONE.defaultBlockState(),3);
        level.setBlock(startPos.offset(8, 12, 5),Blocks.COBBLESTONE.defaultBlockState(),3);
        level.setBlock(startPos.offset(8, 12, 6),Blocks.COBBLESTONE.defaultBlockState(),3);
        level.setBlock(startPos.offset(8, 12, 7),Blocks.MOSSY_COBBLESTONE.defaultBlockState(),3);
        level.setBlock(startPos.offset(8, 12, 8),Blocks.COBBLESTONE.defaultBlockState(),3);
        level.setBlock(startPos.offset(8, 12, 9),Blocks.COBBLESTONE.defaultBlockState(),3);
        level.setBlock(startPos.offset(8, 12, 10),Blocks.COBBLESTONE.defaultBlockState(),3);
        level.setBlock(startPos.offset(8, 12, 11),Blocks.COBBLESTONE.defaultBlockState(),3);
        level.setBlock(startPos.offset(8, 12, 12),Blocks.COBBLESTONE.defaultBlockState(),3);
        level.setBlock(startPos.offset(8, 12, 13),Blocks.COBBLESTONE.defaultBlockState(),3);
        level.setBlock(startPos.offset(8, 12, 14),Blocks.COBBLESTONE.defaultBlockState(),3);
        level.setBlock(startPos.offset(8, 12, 15),Blocks.GRASS.defaultBlockState(),3);
        level.setBlock(startPos.offset(8, 13, 4),Blocks.GRASS.defaultBlockState(),3);
        level.setBlock(startPos.offset(8, 13, 5),Blocks.GRASS.defaultBlockState(),3);
        level.setBlock(startPos.offset(8, 13, 6),Blocks.DIRT.defaultBlockState(),3);
        level.setBlock(startPos.offset(8, 13, 7),Blocks.DIRT.defaultBlockState(),3);
        level.setBlock(startPos.offset(8, 13, 8),Blocks.DIRT.defaultBlockState(),3);
        level.setBlock(startPos.offset(8, 13, 9),Blocks.DIRT.defaultBlockState(),3);
        level.setBlock(startPos.offset(8, 13, 10),Blocks.DIRT.defaultBlockState(),3);
        level.setBlock(startPos.offset(8, 13, 11),Blocks.GRASS.defaultBlockState(),3);
        level.setBlock(startPos.offset(8, 13, 12),Blocks.GRASS.defaultBlockState(),3);
        level.setBlock(startPos.offset(8, 13, 13),Blocks.GRASS.defaultBlockState(),3);
        level.setBlock(startPos.offset(8, 13, 14),Blocks.GRASS.defaultBlockState(),3);
        level.setBlock(startPos.offset(8, 14, 6),Blocks.GRASS.defaultBlockState(),3);
        level.setBlock(startPos.offset(8, 14, 7),Blocks.GRASS.defaultBlockState(),3);
        level.setBlock(startPos.offset(8, 14, 8),Blocks.GRASS.defaultBlockState(),3);
        level.setBlock(startPos.offset(8, 14, 9),Blocks.GRASS.defaultBlockState(),3);
        level.setBlock(startPos.offset(8, 14, 10),Blocks.GRASS.defaultBlockState(),3);
        level.setBlock(startPos.offset(9, 0, 6),Blocks.COBBLESTONE.defaultBlockState(),3);
        level.setBlock(startPos.offset(9, 0, 7),Blocks.COBBLESTONE.defaultBlockState(),3);
        level.setBlock(startPos.offset(9, 0, 8),Blocks.MOSSY_COBBLESTONE.defaultBlockState(),3);
        level.setBlock(startPos.offset(9, 0, 9),Blocks.COBBLESTONE.defaultBlockState(),3);
        level.setBlock(startPos.offset(9, 0, 10),Blocks.MOSSY_COBBLESTONE.defaultBlockState(),3);
        level.setBlock(startPos.offset(9, 0, 11),Blocks.MOSSY_COBBLESTONE.defaultBlockState(),3);
        level.setBlock(startPos.offset(9, 0, 12),Blocks.COBBLESTONE.defaultBlockState(),3);
        level.setBlock(startPos.offset(9, 1, 6),Blocks.MOSSY_COBBLESTONE.defaultBlockState(),3);
        level.setBlock(startPos.offset(9, 1, 12),Blocks.MOSSY_COBBLESTONE.defaultBlockState(),3);
        level.setBlock(startPos.offset(9, 2, 6),Blocks.COBBLESTONE.defaultBlockState(),3);
        level.setBlock(startPos.offset(9, 2, 12),Blocks.COBBLESTONE.defaultBlockState(),3);
        level.setBlock(startPos.offset(9, 3, 6),Blocks.COBBLESTONE.defaultBlockState(),3);
        level.setBlock(startPos.offset(9, 3, 12),Blocks.MOSSY_COBBLESTONE.defaultBlockState(),3);
        level.setBlock(startPos.offset(9, 4, 3),Blocks.COBBLESTONE.defaultBlockState(),3);
        level.setBlock(startPos.offset(9, 4, 4),Blocks.COBBLESTONE.defaultBlockState(),3);
        level.setBlock(startPos.offset(9, 4, 5),Blocks.COBBLESTONE.defaultBlockState(),3);
        level.setBlock(startPos.offset(9, 4, 6),stoneStair3,3);
        level.setBlock(startPos.offset(9, 4, 12),stoneStair2,3);
        level.setBlock(startPos.offset(9, 4, 13),Blocks.COBBLESTONE.defaultBlockState(),3);
        level.setBlock(startPos.offset(9, 4, 14),Blocks.COBBLESTONE.defaultBlockState(),3);
        level.setBlock(startPos.offset(9, 4, 15),Blocks.COBBLESTONE.defaultBlockState(),3);
        level.setBlock(startPos.offset(9, 5, 3),Blocks.COBBLESTONE.defaultBlockState(),3);
        level.setBlock(startPos.offset(9, 5, 15),Blocks.COBBLESTONE.defaultBlockState(),3);
        level.setBlock(startPos.offset(9, 6, 3),Blocks.COBBLESTONE.defaultBlockState(),3);
        level.setBlock(startPos.offset(9, 6, 15),Blocks.COBBLESTONE.defaultBlockState(),3);
        level.setBlock(startPos.offset(9, 7, 3),Blocks.COBBLESTONE.defaultBlockState(),3);
        level.setBlock(startPos.offset(9, 7, 15),Blocks.COBBLESTONE.defaultBlockState(),3);
        level.setBlock(startPos.offset(9, 8, 0),Blocks.DIRT.defaultBlockState(),3);
        level.setBlock(startPos.offset(9, 8, 1),Blocks.DIRT.defaultBlockState(),3);
        level.setBlock(startPos.offset(9, 8, 2),Blocks.DIRT.defaultBlockState(),3);
        level.setBlock(startPos.offset(9, 8, 3),Blocks.COBBLESTONE.defaultBlockState(),3);
        level.setBlock(startPos.offset(9, 8, 4),Blocks.COBBLESTONE.defaultBlockState(),3);
        level.setBlock(startPos.offset(9, 8, 5),Blocks.COBBLESTONE.defaultBlockState(),3);
        level.setBlock(startPos.offset(9, 8, 6),stoneStair7,3);
        level.setBlock(startPos.offset(9, 8, 12),stoneStair6,3);
        level.setBlock(startPos.offset(9, 8, 13),Blocks.MOSSY_COBBLESTONE.defaultBlockState(),3);
        level.setBlock(startPos.offset(9, 8, 14),Blocks.COBBLESTONE.defaultBlockState(),3);
        level.setBlock(startPos.offset(9, 8, 15),Blocks.COBBLESTONE.defaultBlockState(),3);
        level.setBlock(startPos.offset(9, 8, 16),Blocks.DIRT.defaultBlockState(),3);
        level.setBlock(startPos.offset(9, 8, 17),Blocks.DIRT.defaultBlockState(),3);
        level.setBlock(startPos.offset(9, 8, 18),Blocks.DIRT.defaultBlockState(),3);
        level.setBlock(startPos.offset(9, 9, 0),Blocks.DIRT.defaultBlockState(),3);
        level.setBlock(startPos.offset(9, 9, 1),Blocks.DIRT.defaultBlockState(),3);
        level.setBlock(startPos.offset(9, 9, 2),Blocks.DIRT.defaultBlockState(),3);
        level.setBlock(startPos.offset(9, 9, 3),Blocks.COBBLESTONE.defaultBlockState(),3);
        level.setBlock(startPos.offset(9, 9, 15),Blocks.MOSSY_COBBLESTONE.defaultBlockState(),3);
        level.setBlock(startPos.offset(9, 9, 16),Blocks.DIRT.defaultBlockState(),3);
        level.setBlock(startPos.offset(9, 9, 17),Blocks.DIRT.defaultBlockState(),3);
        level.setBlock(startPos.offset(9, 9, 18),Blocks.GRASS.defaultBlockState(),3);
        level.setBlock(startPos.offset(9, 10, 0),Blocks.GRASS.defaultBlockState(),3);
        level.setBlock(startPos.offset(9, 10, 1),Blocks.DIRT.defaultBlockState(),3);
        level.setBlock(startPos.offset(9, 10, 2),Blocks.DIRT.defaultBlockState(),3);
        level.setBlock(startPos.offset(9, 10, 3),Blocks.MOSSY_COBBLESTONE.defaultBlockState(),3);
        level.setBlock(startPos.offset(9, 10, 15),Blocks.MOSSY_COBBLESTONE.defaultBlockState(),3);
        level.setBlock(startPos.offset(9, 10, 16),Blocks.DIRT.defaultBlockState(),3);
        level.setBlock(startPos.offset(9, 10, 17),Blocks.GRASS.defaultBlockState(),3);
        level.setBlock(startPos.offset(9, 11, 1),Blocks.GRASS.defaultBlockState(),3);
        level.setBlock(startPos.offset(9, 11, 2),Blocks.DIRT.defaultBlockState(),3);
        level.setBlock(startPos.offset(9, 11, 3),Blocks.COBBLESTONE.defaultBlockState(),3);
        level.setBlock(startPos.offset(9, 11, 15),Blocks.COBBLESTONE.defaultBlockState(),3);
        level.setBlock(startPos.offset(9, 11, 16),Blocks.DIRT.defaultBlockState(),3);
        level.setBlock(startPos.offset(9, 12, 2),Blocks.GRASS.defaultBlockState(),3);
        level.setBlock(startPos.offset(9, 12, 3),Blocks.GRASS.defaultBlockState(),3);
        level.setBlock(startPos.offset(9, 12, 4),Blocks.COBBLESTONE.defaultBlockState(),3);
        level.setBlock(startPos.offset(9, 12, 5),Blocks.COBBLESTONE.defaultBlockState(),3);
        level.setBlock(startPos.offset(9, 12, 6),Blocks.COBBLESTONE.defaultBlockState(),3);
        level.setBlock(startPos.offset(9, 12, 7),Blocks.MOSSY_COBBLESTONE.defaultBlockState(),3);
        level.setBlock(startPos.offset(9, 12, 8),Blocks.COBBLESTONE.defaultBlockState(),3);
        level.setBlock(startPos.offset(9, 12, 9),Blocks.COBBLESTONE.defaultBlockState(),3);
        level.setBlock(startPos.offset(9, 12, 10),Blocks.COBBLESTONE.defaultBlockState(),3);
        level.setBlock(startPos.offset(9, 12, 11),Blocks.COBBLESTONE.defaultBlockState(),3);
        level.setBlock(startPos.offset(9, 12, 12),Blocks.COBBLESTONE.defaultBlockState(),3);
        level.setBlock(startPos.offset(9, 12, 13),Blocks.COBBLESTONE.defaultBlockState(),3);
        level.setBlock(startPos.offset(9, 12, 14),Blocks.COBBLESTONE.defaultBlockState(),3);
        level.setBlock(startPos.offset(9, 12, 15),Blocks.GRASS.defaultBlockState(),3);
        level.setBlock(startPos.offset(9, 12, 16),Blocks.GRASS.defaultBlockState(),3);
        level.setBlock(startPos.offset(9, 13, 4),Blocks.GRASS.defaultBlockState(),3);
        level.setBlock(startPos.offset(9, 13, 5),Blocks.GRASS.defaultBlockState(),3);
        level.setBlock(startPos.offset(9, 13, 6),Blocks.DIRT.defaultBlockState(),3);
        level.setBlock(startPos.offset(9, 13, 7),Blocks.DIRT.defaultBlockState(),3);
        level.setBlock(startPos.offset(9, 13, 8),Blocks.DIRT.defaultBlockState(),3);
        level.setBlock(startPos.offset(9, 13, 9),Blocks.DIRT.defaultBlockState(),3);
        level.setBlock(startPos.offset(9, 13, 10),Blocks.DIRT.defaultBlockState(),3);
        level.setBlock(startPos.offset(9, 13, 11),Blocks.DIRT.defaultBlockState(),3);
        level.setBlock(startPos.offset(9, 13, 12),Blocks.GRASS.defaultBlockState(),3);
        level.setBlock(startPos.offset(9, 13, 13),Blocks.GRASS.defaultBlockState(),3);
        level.setBlock(startPos.offset(9, 13, 14),Blocks.GRASS.defaultBlockState(),3);
        level.setBlock(startPos.offset(9, 14, 6),Blocks.GRASS.defaultBlockState(),3);
        level.setBlock(startPos.offset(9, 14, 7),Blocks.GRASS.defaultBlockState(),3);
        level.setBlock(startPos.offset(9, 14, 8),Blocks.GRASS.defaultBlockState(),3);
        level.setBlock(startPos.offset(9, 14, 9),Blocks.GRASS.defaultBlockState(),3);
        level.setBlock(startPos.offset(9, 14, 10),Blocks.GRASS.defaultBlockState(),3);
        level.setBlock(startPos.offset(9, 14, 11),Blocks.GRASS.defaultBlockState(),3);
        level.setBlock(startPos.offset(10, 0, 6),Blocks.COBBLESTONE.defaultBlockState(),3);
        level.setBlock(startPos.offset(10, 0, 7),Blocks.MOSSY_COBBLESTONE.defaultBlockState(),3);
        level.setBlock(startPos.offset(10, 0, 8),Blocks.MOSSY_COBBLESTONE.defaultBlockState(),3);
        level.setBlock(startPos.offset(10, 0, 9),Blocks.COBBLESTONE.defaultBlockState(),3);
        level.setBlock(startPos.offset(10, 0, 10),Blocks.COBBLESTONE.defaultBlockState(),3);
        level.setBlock(startPos.offset(10, 0, 11),Blocks.MOSSY_COBBLESTONE.defaultBlockState(),3);
        level.setBlock(startPos.offset(10, 0, 12),Blocks.COBBLESTONE.defaultBlockState(),3);
        level.setBlock(startPos.offset(10, 1, 6),Blocks.COBBLESTONE.defaultBlockState(),3);
        level.setBlock(startPos.offset(10, 1, 12),Blocks.COBBLESTONE.defaultBlockState(),3);
        level.setBlock(startPos.offset(10, 2, 6),Blocks.COBBLESTONE.defaultBlockState(),3);
        level.setBlock(startPos.offset(10, 2, 12),Blocks.COBBLESTONE.defaultBlockState(),3);
        level.setBlock(startPos.offset(10, 3, 6),Blocks.COBBLESTONE.defaultBlockState(),3);
        level.setBlock(startPos.offset(10, 3, 12),Blocks.COBBLESTONE.defaultBlockState(),3);
        level.setBlock(startPos.offset(10, 4, 3),Blocks.COBBLESTONE.defaultBlockState(),3);
        level.setBlock(startPos.offset(10, 4, 4),Blocks.MOSSY_COBBLESTONE.defaultBlockState(),3);
        level.setBlock(startPos.offset(10, 4, 5),Blocks.COBBLESTONE.defaultBlockState(),3);
        level.setBlock(startPos.offset(10, 4, 6),stoneStair3,3);
        level.setBlock(startPos.offset(10, 4, 12),stoneStair2,3);
        level.setBlock(startPos.offset(10, 4, 13),Blocks.COBBLESTONE.defaultBlockState(),3);
        level.setBlock(startPos.offset(10, 4, 14),Blocks.COBBLESTONE.defaultBlockState(),3);
        level.setBlock(startPos.offset(10, 4, 15),Blocks.COBBLESTONE.defaultBlockState(),3);
        level.setBlock(startPos.offset(10, 5, 3),Blocks.COBBLESTONE.defaultBlockState(),3);
        level.setBlock(startPos.offset(10, 5, 15),Blocks.COBBLESTONE.defaultBlockState(),3);
        level.setBlock(startPos.offset(10, 6, 3),Blocks.COBBLESTONE.defaultBlockState(),3);
        level.setBlock(startPos.offset(10, 6, 15),Blocks.MOSSY_COBBLESTONE.defaultBlockState(),3);
        level.setBlock(startPos.offset(10, 7, 3),Blocks.COBBLESTONE.defaultBlockState(),3);
        level.setBlock(startPos.offset(10, 7, 15),Blocks.COBBLESTONE.defaultBlockState(),3);
        level.setBlock(startPos.offset(10, 8, 0),Blocks.DIRT.defaultBlockState(),3);
        level.setBlock(startPos.offset(10, 8, 1),Blocks.DIRT.defaultBlockState(),3);
        level.setBlock(startPos.offset(10, 8, 2),Blocks.DIRT.defaultBlockState(),3);
        level.setBlock(startPos.offset(10, 8, 3),Blocks.COBBLESTONE.defaultBlockState(),3);
        level.setBlock(startPos.offset(10, 8, 4),Blocks.MOSSY_COBBLESTONE.defaultBlockState(),3);
        level.setBlock(startPos.offset(10, 8, 5),Blocks.COBBLESTONE.defaultBlockState(),3);
        level.setBlock(startPos.offset(10, 8, 6),stoneStair7,3);
        level.setBlock(startPos.offset(10, 8, 12),stoneStair6,3);
        level.setBlock(startPos.offset(10, 8, 13),Blocks.COBBLESTONE.defaultBlockState(),3);
        level.setBlock(startPos.offset(10, 8, 14),Blocks.COBBLESTONE.defaultBlockState(),3);
        level.setBlock(startPos.offset(10, 8, 15),Blocks.COBBLESTONE.defaultBlockState(),3);
        level.setBlock(startPos.offset(10, 8, 16),Blocks.DIRT.defaultBlockState(),3);
        level.setBlock(startPos.offset(10, 8, 17),Blocks.DIRT.defaultBlockState(),3);
        level.setBlock(startPos.offset(10, 8, 18),Blocks.DIRT.defaultBlockState(),3);
        level.setBlock(startPos.offset(10, 9, 0),Blocks.DIRT.defaultBlockState(),3);
        level.setBlock(startPos.offset(10, 9, 1),Blocks.DIRT.defaultBlockState(),3);
        level.setBlock(startPos.offset(10, 9, 2),Blocks.DIRT.defaultBlockState(),3);
        level.setBlock(startPos.offset(10, 9, 3),Blocks.COBBLESTONE.defaultBlockState(),3);
        level.setBlock(startPos.offset(10, 9, 15),Blocks.COBBLESTONE.defaultBlockState(),3);
        level.setBlock(startPos.offset(10, 9, 16),Blocks.DIRT.defaultBlockState(),3);
        level.setBlock(startPos.offset(10, 9, 17),Blocks.DIRT.defaultBlockState(),3);
        level.setBlock(startPos.offset(10, 9, 18),Blocks.GRASS.defaultBlockState(),3);
        level.setBlock(startPos.offset(10, 10, 0),Blocks.GRASS.defaultBlockState(),3);
        level.setBlock(startPos.offset(10, 10, 1),Blocks.DIRT.defaultBlockState(),3);
        level.setBlock(startPos.offset(10, 10, 2),Blocks.DIRT.defaultBlockState(),3);
        level.setBlock(startPos.offset(10, 10, 3),Blocks.COBBLESTONE.defaultBlockState(),3);
        level.setBlock(startPos.offset(10, 10, 15),Blocks.COBBLESTONE.defaultBlockState(),3);
        level.setBlock(startPos.offset(10, 10, 16),Blocks.DIRT.defaultBlockState(),3);
        level.setBlock(startPos.offset(10, 10, 17),Blocks.GRASS.defaultBlockState(),3);
        level.setBlock(startPos.offset(10, 11, 1),Blocks.GRASS.defaultBlockState(),3);
        level.setBlock(startPos.offset(10, 11, 2),Blocks.GRASS.defaultBlockState(),3);
        level.setBlock(startPos.offset(10, 11, 3),Blocks.COBBLESTONE.defaultBlockState(),3);
        level.setBlock(startPos.offset(10, 11, 6),stoneStair4,3);
        level.setBlock(startPos.offset(10, 11, 12),stoneStair4,3);
        level.setBlock(startPos.offset(10, 11, 15),Blocks.COBBLESTONE.defaultBlockState(),3);
        level.setBlock(startPos.offset(10, 11, 16),Blocks.DIRT.defaultBlockState(),3);
        level.setBlock(startPos.offset(10, 12, 3),Blocks.GRASS.defaultBlockState(),3);
        level.setBlock(startPos.offset(10, 12, 4),Blocks.COBBLESTONE.defaultBlockState(),3);
        level.setBlock(startPos.offset(10, 12, 5),Blocks.COBBLESTONE.defaultBlockState(),3);
        level.setBlock(startPos.offset(10, 12, 6),Blocks.COBBLESTONE.defaultBlockState(),3);
        level.setBlock(startPos.offset(10, 12, 7),Blocks.COBBLESTONE.defaultBlockState(),3);
        level.setBlock(startPos.offset(10, 12, 8),Blocks.COBBLESTONE.defaultBlockState(),3);
        level.setBlock(startPos.offset(10, 12, 9),Blocks.MOSSY_COBBLESTONE.defaultBlockState(),3);
        level.setBlock(startPos.offset(10, 12, 10),Blocks.COBBLESTONE.defaultBlockState(),3);
        level.setBlock(startPos.offset(10, 12, 11),Blocks.COBBLESTONE.defaultBlockState(),3);
        level.setBlock(startPos.offset(10, 12, 12),Blocks.MOSSY_COBBLESTONE.defaultBlockState(),3);
        level.setBlock(startPos.offset(10, 12, 13),Blocks.COBBLESTONE.defaultBlockState(),3);
        level.setBlock(startPos.offset(10, 12, 14),Blocks.COBBLESTONE.defaultBlockState(),3);
        level.setBlock(startPos.offset(10, 12, 15),Blocks.GRASS.defaultBlockState(),3);
        level.setBlock(startPos.offset(10, 12, 16),Blocks.GRASS.defaultBlockState(),3);
        level.setBlock(startPos.offset(10, 13, 4),Blocks.GRASS.defaultBlockState(),3);
        level.setBlock(startPos.offset(10, 13, 5),Blocks.DIRT.defaultBlockState(),3);
        level.setBlock(startPos.offset(10, 13, 6),Blocks.DIRT.defaultBlockState(),3);
        level.setBlock(startPos.offset(10, 13, 7),Blocks.GRASS.defaultBlockState(),3);
        level.setBlock(startPos.offset(10, 13, 8),Blocks.DIRT.defaultBlockState(),3);
        level.setBlock(startPos.offset(10, 13, 9),Blocks.DIRT.defaultBlockState(),3);
        level.setBlock(startPos.offset(10, 13, 10),Blocks.DIRT.defaultBlockState(),3);
        level.setBlock(startPos.offset(10, 13, 11),Blocks.DIRT.defaultBlockState(),3);
        level.setBlock(startPos.offset(10, 13, 12),Blocks.GRASS.defaultBlockState(),3);
        level.setBlock(startPos.offset(10, 13, 13),Blocks.GRASS.defaultBlockState(),3);
        level.setBlock(startPos.offset(10, 13, 14),Blocks.GRASS.defaultBlockState(),3);
        level.setBlock(startPos.offset(10, 14, 5),Blocks.GRASS.defaultBlockState(),3);
        level.setBlock(startPos.offset(10, 14, 6),Blocks.GRASS.defaultBlockState(),3);
        level.setBlock(startPos.offset(10, 14, 8),Blocks.GRASS.defaultBlockState(),3);
        level.setBlock(startPos.offset(10, 14, 9),Blocks.GRASS.defaultBlockState(),3);
        level.setBlock(startPos.offset(10, 14, 10),Blocks.GRASS.defaultBlockState(),3);
        level.setBlock(startPos.offset(10, 14, 11),Blocks.GRASS.defaultBlockState(),3);
        level.setBlock(startPos.offset(11, 0, 6),Blocks.COBBLESTONE.defaultBlockState(),3);
        level.setBlock(startPos.offset(11, 0, 7),Blocks.COBBLESTONE.defaultBlockState(),3);
        level.setBlock(startPos.offset(11, 0, 8),Blocks.COBBLESTONE.defaultBlockState(),3);
        level.setBlock(startPos.offset(11, 0, 9),Blocks.COBBLESTONE.defaultBlockState(),3);
        level.setBlock(startPos.offset(11, 0, 10),Blocks.MOSSY_COBBLESTONE.defaultBlockState(),3);
        level.setBlock(startPos.offset(11, 0, 11),Blocks.COBBLESTONE.defaultBlockState(),3);
        level.setBlock(startPos.offset(11, 0, 12),Blocks.COBBLESTONE.defaultBlockState(),3);
        level.setBlock(startPos.offset(11, 1, 6),Blocks.COBBLESTONE.defaultBlockState(),3);
        level.setBlock(startPos.offset(11, 1, 7),Blocks.COBBLESTONE.defaultBlockState(),3);
        level.setBlock(startPos.offset(11, 1, 8),Blocks.COBBLESTONE.defaultBlockState(),3);
        level.setBlock(startPos.offset(11, 1, 9),Blocks.COBBLESTONE.defaultBlockState(),3);
        level.setBlock(startPos.offset(11, 1, 10),Blocks.COBBLESTONE.defaultBlockState(),3);
        level.setBlock(startPos.offset(11, 1, 11),Blocks.COBBLESTONE.defaultBlockState(),3);
        level.setBlock(startPos.offset(11, 1, 12),Blocks.COBBLESTONE.defaultBlockState(),3);
        level.setBlock(startPos.offset(11, 2, 6),Blocks.COBBLESTONE.defaultBlockState(),3);
        level.setBlock(startPos.offset(11, 2, 7),Blocks.COBBLESTONE.defaultBlockState(),3);
        level.setBlock(startPos.offset(11, 2, 8),Blocks.COBBLESTONE.defaultBlockState(),3);
        level.setBlock(startPos.offset(11, 2, 9),Blocks.COBBLESTONE.defaultBlockState(),3);
        level.setBlock(startPos.offset(11, 2, 10),Blocks.MOSSY_COBBLESTONE.defaultBlockState(),3);
        level.setBlock(startPos.offset(11, 2, 11),Blocks.COBBLESTONE.defaultBlockState(),3);
        level.setBlock(startPos.offset(11, 2, 12),Blocks.COBBLESTONE.defaultBlockState(),3);
        level.setBlock(startPos.offset(11, 3, 6),Blocks.COBBLESTONE.defaultBlockState(),3);
        level.setBlock(startPos.offset(11, 3, 7),Blocks.COBBLESTONE.defaultBlockState(),3);
        level.setBlock(startPos.offset(11, 3, 8),Blocks.COBBLESTONE.defaultBlockState(),3);
        level.setBlock(startPos.offset(11, 3, 9),Blocks.MOSSY_COBBLESTONE.defaultBlockState(),3);
        level.setBlock(startPos.offset(11, 3, 10),Blocks.COBBLESTONE.defaultBlockState(),3);
        level.setBlock(startPos.offset(11, 3, 11),Blocks.COBBLESTONE.defaultBlockState(),3);
        level.setBlock(startPos.offset(11, 3, 12),Blocks.COBBLESTONE.defaultBlockState(),3);
        level.setBlock(startPos.offset(11, 4, 3),Blocks.COBBLESTONE.defaultBlockState(),3);
        level.setBlock(startPos.offset(11, 4, 4),Blocks.COBBLESTONE.defaultBlockState(),3);
        level.setBlock(startPos.offset(11, 4, 5),Blocks.COBBLESTONE.defaultBlockState(),3);
        level.setBlock(startPos.offset(11, 4, 6),Blocks.COBBLESTONE.defaultBlockState(),3);
        level.setBlock(startPos.offset(11, 4, 7),Blocks.STONE_STAIRS.defaultBlockState(),3);
        level.setBlock(startPos.offset(11, 4, 8),Blocks.STONE_STAIRS.defaultBlockState(),3);
        level.setBlock(startPos.offset(11, 4, 9),Blocks.STONE_STAIRS.defaultBlockState(),3);
        level.setBlock(startPos.offset(11, 4, 10),Blocks.STONE_STAIRS.defaultBlockState(),3);
        level.setBlock(startPos.offset(11, 4, 11),Blocks.STONE_STAIRS.defaultBlockState(),3);
        level.setBlock(startPos.offset(11, 4, 12),Blocks.COBBLESTONE.defaultBlockState(),3);
        level.setBlock(startPos.offset(11, 4, 13),Blocks.COBBLESTONE.defaultBlockState(),3);
        level.setBlock(startPos.offset(11, 4, 14),Blocks.COBBLESTONE.defaultBlockState(),3);
        level.setBlock(startPos.offset(11, 4, 15),Blocks.COBBLESTONE.defaultBlockState(),3);
        level.setBlock(startPos.offset(11, 5, 3),Blocks.COBBLESTONE.defaultBlockState(),3);
        level.setBlock(startPos.offset(11, 5, 6),Blocks.COBBLESTONE.defaultBlockState(),3);
        level.setBlock(startPos.offset(11, 5, 12),Blocks.COBBLESTONE.defaultBlockState(),3);
        level.setBlock(startPos.offset(11, 5, 15),Blocks.COBBLESTONE.defaultBlockState(),3);
        level.setBlock(startPos.offset(11, 6, 3),Blocks.MOSSY_COBBLESTONE.defaultBlockState(),3);
        level.setBlock(startPos.offset(11, 6, 6),Blocks.MOSSY_COBBLESTONE.defaultBlockState(),3);
        level.setBlock(startPos.offset(11, 6, 12),Blocks.COBBLESTONE.defaultBlockState(),3);
        level.setBlock(startPos.offset(11, 6, 15),Blocks.COBBLESTONE.defaultBlockState(),3);
        level.setBlock(startPos.offset(11, 7, 3),Blocks.COBBLESTONE.defaultBlockState(),3);
        level.setBlock(startPos.offset(11, 7, 6),Blocks.COBBLESTONE.defaultBlockState(),3);
        level.setBlock(startPos.offset(11, 7, 12),Blocks.MOSSY_COBBLESTONE.defaultBlockState(),3);
        level.setBlock(startPos.offset(11, 7, 15),Blocks.COBBLESTONE.defaultBlockState(),3);
        level.setBlock(startPos.offset(11, 8, 0),Blocks.DIRT.defaultBlockState(),3);
        level.setBlock(startPos.offset(11, 8, 1),Blocks.DIRT.defaultBlockState(),3);
        level.setBlock(startPos.offset(11, 8, 2),Blocks.DIRT.defaultBlockState(),3);
        level.setBlock(startPos.offset(11, 8, 3),Blocks.COBBLESTONE.defaultBlockState(),3);
        level.setBlock(startPos.offset(11, 8, 4),Blocks.COBBLESTONE.defaultBlockState(),3);
        level.setBlock(startPos.offset(11, 8, 5),Blocks.COBBLESTONE.defaultBlockState(),3);
        level.setBlock(startPos.offset(11, 8, 6),Blocks.COBBLESTONE.defaultBlockState(),3);
        level.setBlock(startPos.offset(11, 8, 7),stoneStair4,3);
        level.setBlock(startPos.offset(11, 8, 8),stoneStair4,3);
        level.setBlock(startPos.offset(11, 8, 9),stoneStair4,3);
        level.setBlock(startPos.offset(11, 8, 10),stoneStair4,3);
        level.setBlock(startPos.offset(11, 8, 11),stoneStair4,3);
        level.setBlock(startPos.offset(11, 8, 12),Blocks.COBBLESTONE.defaultBlockState(),3);
        level.setBlock(startPos.offset(11, 8, 13),Blocks.COBBLESTONE.defaultBlockState(),3);
        level.setBlock(startPos.offset(11, 8, 14),Blocks.COBBLESTONE.defaultBlockState(),3);
        level.setBlock(startPos.offset(11, 8, 15),Blocks.COBBLESTONE.defaultBlockState(),3);
        level.setBlock(startPos.offset(11, 8, 16),Blocks.DIRT.defaultBlockState(),3);
        level.setBlock(startPos.offset(11, 8, 17),Blocks.DIRT.defaultBlockState(),3);
        level.setBlock(startPos.offset(11, 8, 18),Blocks.DIRT.defaultBlockState(),3);
        level.setBlock(startPos.offset(11, 9, 0),Blocks.GRASS.defaultBlockState(),3);
        level.setBlock(startPos.offset(11, 9, 1),Blocks.DIRT.defaultBlockState(),3);
        level.setBlock(startPos.offset(11, 9, 2),Blocks.DIRT.defaultBlockState(),3);
        level.setBlock(startPos.offset(11, 9, 3),Blocks.COBBLESTONE.defaultBlockState(),3);
        level.setBlock(startPos.offset(11, 9, 6),Blocks.COBBLESTONE.defaultBlockState(),3);
        level.setBlock(startPos.offset(11, 9, 12),Blocks.MOSSY_COBBLESTONE.defaultBlockState(),3);
        level.setBlock(startPos.offset(11, 9, 15),Blocks.COBBLESTONE.defaultBlockState(),3);
        level.setBlock(startPos.offset(11, 9, 16),Blocks.DIRT.defaultBlockState(),3);
        level.setBlock(startPos.offset(11, 9, 17),Blocks.DIRT.defaultBlockState(),3);
        level.setBlock(startPos.offset(11, 9, 18),Blocks.GRASS.defaultBlockState(),3);
        level.setBlock(startPos.offset(11, 10, 1),Blocks.DIRT.defaultBlockState(),3);
        level.setBlock(startPos.offset(11, 10, 2),Blocks.DIRT.defaultBlockState(),3);
        level.setBlock(startPos.offset(11, 10, 3),Blocks.COBBLESTONE.defaultBlockState(),3);
        level.setBlock(startPos.offset(11, 10, 6),Blocks.COBBLESTONE.defaultBlockState(),3);
        level.setBlock(startPos.offset(11, 10, 12),Blocks.MOSSY_COBBLESTONE.defaultBlockState(),3);
        level.setBlock(startPos.offset(11, 10, 15),Blocks.MOSSY_COBBLESTONE.defaultBlockState(),3);
        level.setBlock(startPos.offset(11, 10, 16),Blocks.DIRT.defaultBlockState(),3);
        level.setBlock(startPos.offset(11, 10, 17),Blocks.DIRT.defaultBlockState(),3);
        level.setBlock(startPos.offset(11, 11, 1),Blocks.GRASS.defaultBlockState(),3);
        level.setBlock(startPos.offset(11, 11, 2),Blocks.GRASS.defaultBlockState(),3);
        level.setBlock(startPos.offset(11, 11, 3),Blocks.MOSSY_COBBLESTONE.defaultBlockState(),3);
        level.setBlock(startPos.offset(11, 11, 5),stoneStair6,3);
        level.setBlock(startPos.offset(11, 11, 6),Blocks.COBBLESTONE.defaultBlockState(),3);
        level.setBlock(startPos.offset(11, 11, 7),stoneStair7,3);
        level.setBlock(startPos.offset(11, 11, 11),stoneStair6,3);
        level.setBlock(startPos.offset(11, 11, 12),Blocks.COBBLESTONE.defaultBlockState(),3);
        level.setBlock(startPos.offset(11, 11, 13),stoneStair7,3);
        level.setBlock(startPos.offset(11, 11, 15),Blocks.COBBLESTONE.defaultBlockState(),3);
        level.setBlock(startPos.offset(11, 11, 16),Blocks.GRASS.defaultBlockState(),3);
        level.setBlock(startPos.offset(11, 11, 17),Blocks.GRASS.defaultBlockState(),3);
        level.setBlock(startPos.offset(11, 12, 3),Blocks.GRASS.defaultBlockState(),3);
        level.setBlock(startPos.offset(11, 12, 4),Blocks.COBBLESTONE.defaultBlockState(),3);
        level.setBlock(startPos.offset(11, 12, 5),Blocks.COBBLESTONE.defaultBlockState(),3);
        level.setBlock(startPos.offset(11, 12, 6),Blocks.COBBLESTONE.defaultBlockState(),3);
        level.setBlock(startPos.offset(11, 12, 7),Blocks.COBBLESTONE.defaultBlockState(),3);
        level.setBlock(startPos.offset(11, 12, 8),Blocks.COBBLESTONE.defaultBlockState(),3);
        level.setBlock(startPos.offset(11, 12, 9),Blocks.COBBLESTONE.defaultBlockState(),3);
        level.setBlock(startPos.offset(11, 12, 10),Blocks.COBBLESTONE.defaultBlockState(),3);
        level.setBlock(startPos.offset(11, 12, 11),Blocks.COBBLESTONE.defaultBlockState(),3);
        level.setBlock(startPos.offset(11, 12, 12),Blocks.COBBLESTONE.defaultBlockState(),3);
        level.setBlock(startPos.offset(11, 12, 13),Blocks.COBBLESTONE.defaultBlockState(),3);
        level.setBlock(startPos.offset(11, 12, 14),Blocks.COBBLESTONE.defaultBlockState(),3);
        level.setBlock(startPos.offset(11, 12, 15),Blocks.GRASS.defaultBlockState(),3);
        level.setBlock(startPos.offset(11, 13, 4),Blocks.GRASS.defaultBlockState(),3);
        level.setBlock(startPos.offset(11, 13, 5),Blocks.GRASS.defaultBlockState(),3);
        level.setBlock(startPos.offset(11, 13, 6),Blocks.DIRT.defaultBlockState(),3);
        level.setBlock(startPos.offset(11, 13, 7),Blocks.DIRT.defaultBlockState(),3);
        level.setBlock(startPos.offset(11, 13, 8),Blocks.DIRT.defaultBlockState(),3);
        level.setBlock(startPos.offset(11, 13, 9),Blocks.DIRT.defaultBlockState(),3);
        level.setBlock(startPos.offset(11, 13, 10),Blocks.DIRT.defaultBlockState(),3);
        level.setBlock(startPos.offset(11, 13, 11),Blocks.GRASS.defaultBlockState(),3);
        level.setBlock(startPos.offset(11, 13, 12),Blocks.GRASS.defaultBlockState(),3);
        level.setBlock(startPos.offset(11, 13, 13),Blocks.GRASS.defaultBlockState(),3);
        level.setBlock(startPos.offset(11, 13, 14),Blocks.GRASS.defaultBlockState(),3);
        level.setBlock(startPos.offset(11, 14, 6),Blocks.GRASS.defaultBlockState(),3);
        level.setBlock(startPos.offset(11, 14, 7),Blocks.GRASS.defaultBlockState(),3);
        level.setBlock(startPos.offset(11, 14, 8),Blocks.GRASS.defaultBlockState(),3);
        level.setBlock(startPos.offset(11, 14, 9),Blocks.GRASS.defaultBlockState(),3);
        level.setBlock(startPos.offset(11, 14, 10),Blocks.GRASS.defaultBlockState(),3);
        level.setBlock(startPos.offset(12, 0, 6),Blocks.COBBLESTONE.defaultBlockState(),3);
        level.setBlock(startPos.offset(12, 0, 7),Blocks.COBBLESTONE.defaultBlockState(),3);
        level.setBlock(startPos.offset(12, 0, 8),Blocks.COBBLESTONE.defaultBlockState(),3);
        level.setBlock(startPos.offset(12, 0, 9),Blocks.COBBLESTONE.defaultBlockState(),3);
        level.setBlock(startPos.offset(12, 0, 10),Blocks.COBBLESTONE.defaultBlockState(),3);
        level.setBlock(startPos.offset(12, 0, 11),Blocks.COBBLESTONE.defaultBlockState(),3);
        level.setBlock(startPos.offset(12, 0, 12),Blocks.COBBLESTONE.defaultBlockState(),3);
        level.setBlock(startPos.offset(12, 1, 6),Blocks.MOSSY_COBBLESTONE.defaultBlockState(),3);
        level.setBlock(startPos.offset(12, 1, 7),Blocks.COBBLESTONE.defaultBlockState(),3);
        level.setBlock(startPos.offset(12, 1, 8),Blocks.COBBLESTONE.defaultBlockState(),3);
        level.setBlock(startPos.offset(12, 1, 9),Blocks.MOSSY_COBBLESTONE.defaultBlockState(),3);
        level.setBlock(startPos.offset(12, 1, 10),Blocks.COBBLESTONE.defaultBlockState(),3);
        level.setBlock(startPos.offset(12, 1, 11),Blocks.MOSSY_COBBLESTONE.defaultBlockState(),3);
        level.setBlock(startPos.offset(12, 1, 12),Blocks.MOSSY_COBBLESTONE.defaultBlockState(),3);
        level.setBlock(startPos.offset(12, 2, 6),Blocks.COBBLESTONE.defaultBlockState(),3);
        level.setBlock(startPos.offset(12, 2, 7),Blocks.COBBLESTONE.defaultBlockState(),3);
        level.setBlock(startPos.offset(12, 2, 8),Blocks.COBBLESTONE.defaultBlockState(),3);
        level.setBlock(startPos.offset(12, 2, 9),Blocks.COBBLESTONE.defaultBlockState(),3);
        level.setBlock(startPos.offset(12, 2, 10),Blocks.COBBLESTONE.defaultBlockState(),3);
        level.setBlock(startPos.offset(12, 2, 11),Blocks.COBBLESTONE.defaultBlockState(),3);
        level.setBlock(startPos.offset(12, 2, 12),Blocks.COBBLESTONE.defaultBlockState(),3);
        level.setBlock(startPos.offset(12, 3, 6),Blocks.COBBLESTONE.defaultBlockState(),3);
        level.setBlock(startPos.offset(12, 3, 7),Blocks.COBBLESTONE.defaultBlockState(),3);
        level.setBlock(startPos.offset(12, 3, 8),Blocks.COBBLESTONE.defaultBlockState(),3);
        level.setBlock(startPos.offset(12, 3, 9),Blocks.COBBLESTONE.defaultBlockState(),3);
        level.setBlock(startPos.offset(12, 3, 10),Blocks.COBBLESTONE.defaultBlockState(),3);
        level.setBlock(startPos.offset(12, 3, 11),Blocks.COBBLESTONE.defaultBlockState(),3);
        level.setBlock(startPos.offset(12, 3, 12),Blocks.COBBLESTONE.defaultBlockState(),3);
        level.setBlock(startPos.offset(12, 4, 3),Blocks.COBBLESTONE.defaultBlockState(),3);
        level.setBlock(startPos.offset(12, 4, 4),Blocks.COBBLESTONE.defaultBlockState(),3);
        level.setBlock(startPos.offset(12, 4, 5),Blocks.COBBLESTONE.defaultBlockState(),3);
        level.setBlock(startPos.offset(12, 4, 6),Blocks.COBBLESTONE.defaultBlockState(),3);
        level.setBlock(startPos.offset(12, 4, 7),Blocks.COBBLESTONE.defaultBlockState(),3);
        level.setBlock(startPos.offset(12, 4, 8),Blocks.MOSSY_COBBLESTONE.defaultBlockState(),3);
        level.setBlock(startPos.offset(12, 4, 9),Blocks.COBBLESTONE.defaultBlockState(),3);
        level.setBlock(startPos.offset(12, 4, 10),Blocks.COBBLESTONE.defaultBlockState(),3);
        level.setBlock(startPos.offset(12, 4, 11),Blocks.COBBLESTONE.defaultBlockState(),3);
        level.setBlock(startPos.offset(12, 4, 12),Blocks.COBBLESTONE.defaultBlockState(),3);
        level.setBlock(startPos.offset(12, 4, 13),Blocks.MOSSY_COBBLESTONE.defaultBlockState(),3);
        level.setBlock(startPos.offset(12, 4, 14),Blocks.COBBLESTONE.defaultBlockState(),3);
        level.setBlock(startPos.offset(12, 4, 15),Blocks.COBBLESTONE.defaultBlockState(),3);
        level.setBlock(startPos.offset(12, 5, 3),Blocks.COBBLESTONE.defaultBlockState(),3);
        level.setBlock(startPos.offset(12, 5, 15),Blocks.COBBLESTONE.defaultBlockState(),3);
        level.setBlock(startPos.offset(12, 6, 3),Blocks.COBBLESTONE.defaultBlockState(),3);
        level.setBlock(startPos.offset(12, 6, 15),Blocks.COBBLESTONE.defaultBlockState(),3);
        level.setBlock(startPos.offset(12, 7, 3),Blocks.COBBLESTONE.defaultBlockState(),3);
        level.setBlock(startPos.offset(12, 7, 15),Blocks.COBBLESTONE.defaultBlockState(),3);
        level.setBlock(startPos.offset(12, 8, 0),Blocks.DIRT.defaultBlockState(),3);
        level.setBlock(startPos.offset(12, 8, 1),Blocks.DIRT.defaultBlockState(),3);
        level.setBlock(startPos.offset(12, 8, 2),Blocks.DIRT.defaultBlockState(),3);
        level.setBlock(startPos.offset(12, 8, 3),Blocks.COBBLESTONE.defaultBlockState(),3);
        level.setBlock(startPos.offset(12, 8, 4),Blocks.MOSSY_COBBLESTONE.defaultBlockState(),3);
